Workbook

Sheet 1
A1: 생산수량 | B1: =H97 -> 38395 | E1: 불량금액 | F1: =G97 -> 0
A2: 불량수량 | B2: =I97 -> 12 | L2: =SUBTOTAL(9,L6:L96) -> 3 | M2: =SUBTOTAL(9,M6:M96) -> 1 | N2: =SUBTOTAL(9,N6:N96) -> 0 | O2: =SUBTOTAL(9,O6:O96) -> 0 | P2: =SUBTOTAL(9,P6:P96) -> 0 | Q2: =SUBTOTAL(9,Q6:Q96) -> 0 | R2: =SUBTOTAL(9,R6:R96) -> 0 | S2: =SUBTOTAL(9,S6:S96) -> 0 | ... AK2: =SUBTOTAL(9,AK6:AK96) -> 0 | AL2: =SUBTOTAL(9,AL6:AL74) -> 12
A3: 불량율(ppm) | B3: =IF(ISERROR(B2/(B2+B1)*1000000),"",(B2/(B2+B1)*1000000)) -> 312.44304 | L3: =SUM(L6:L96) -> 3 | M3: =SUM(M6:M96) -> 1 | N3: =SUM(N6:N96) -> 0 | O3: =SUM(O6:O96) -> 0 | P3: =SUM(P6:P96) -> 0 | Q3: =SUM(Q6:Q96) -> 0 | R3: =SUM(R6:R96) -> 0 | S3: =SUM(S6:S96) -> 0 | ... AK3: =SUM(AK6:AK96) -> 0 | AL3: =SUM(AL6:AL74) -> 12
A4: =AM97 -> OK | E4: 거래선 및 불량금액 | H4: 종합 | L4: 깨짐 | M4: 찍힘 | N4: CRACK | O4: 스크래치 | P4: 녹불량 | Q4: 초기가동 | R4: 편차수정 | S4: 중량불량 | T4: 설비Error | U4: Pellet누락 | V4: 낙물 | W4: 산화 | X4: 휨 | Y4: 눌림 | Z4: 분말소착 | AA4: 역싸이징 | AB4: 이물질소착 | AC4: 기포 | AD4: 윈도우 GO | AE4: 윈도우 NO | AF4: 조립불량 | AG4: 침투불량 | AH4: 치형뜯김 | AI4: 기타 | AJ4: 폐기 | AK4: 소재불량 | AL4: 합계 | AM4: 오기 유/무
A5: TM NO. | B5: CODE (ERP) | C5: 품 명 | D5: 차종 | E5: 거래선 | F5: 단가 | G5: 불량금액 (단가x수량) | H5: 생산수량 | I5: 불량수량 | J5: 불량율 (PPM)
A6: 1360-00 | B6: 10901 | C6: MOTOR PULLEY | I6: =SUM(L6:AK6) -> 0 | AL6: =SUM(L6:AK6) -> 0 | AM6: =IF(AL6=I6,"OK","NG") -> OK
A7: 1360-01 | B7: 15922 | C7: MOTOR PULLEY | I7: =SUM(L7:AK7) -> 0 | AL7: =SUM(L7:AK7) -> 0 | AM7: =IF(AL7=I7,"OK","NG") -> OK
A8: 1361-00 | B8: 10899 | C8: BALL NUT PULLEY | I8: =SUM(L8:AK8) -> 0 | AL8: =SUM(L8:AK8) -> 0 | AM8: =IF(AL8=I8,"OK","NG") -> OK
A9: 1361-01 | B9: 10897 | C9: BALL NUT PULLEY | I9: =SUM(L9:AK9) -> 0 | AL9: =SUM(L9:AK9) -> 0 | AM9: =IF(AL9=I9,"OK","NG") -> OK
A10: 1361-02 | B10: 18523 | C10: BALL NUT PULLEY | I10: =SUM(L10:AK10) -> 0 | AL10: =SUM(L10:AK10) -> 0 | AM10: =IF(AL10=I10,"OK","NG") -> OK
A11: 1361-50 | B11: 19445 | C11: BELT GUIDE | I11: =SUM(L11:AK11) -> 0 | AL11: =SUM(L11:AK11) -> 0 | AM11: =IF(AL11=I11,"OK","NG") -> OK
A12: 1464-00 | B12: 10315 | C12: PULLEY | I12: =SUM(L12:AK12) -> 0 | AL12: =SUM(L12:AK12) -> 0 | AM12: =IF(AL12=I12,"OK","NG") -> OK
A13: 1464-01 | B13: 14961 | C13: PULLEY | I13: =SUM(L13:AK13) -> 0 | AL13: =SUM(L13:AK13) -> 0 | AM13: =IF(AL13=I13,"OK","NG") -> OK
A14: 1510-00 | B14: 10254 | C14: PULLEY LARGE | I14: =SUM(L14:AK14) -> 0 | AL14: =SUM(L14:AK14) -> 0 | AM14: =IF(AL14=I14,"OK","NG") -> OK
A15: 1510-01 | B15: 11856 | C15: PULLEY LARGE | I15: =SUM(L15:AK15) -> 0 | AL15: =SUM(L15:AK15) -> 0 | AM15: =IF(AL15=I15,"OK","NG") -> OK
A16: 1510-02 | B16: 15003 | C16: PULLEY LARGE | I16: =SUM(L16:AK16) -> 0 | AL16: =SUM(L16:AK16) -> 0 | AM16: =IF(AL16=I16,"OK","NG") -> OK
A17: 1695-00 | B17: 15173 | C17: MOTOR PULLEY | I17: =SUM(L17:AK17) -> 0 | AL17: =SUM(L17:AK17) -> 0 | AM17: =IF(AL17=I17,"OK","NG") -> OK
A18: 1781-00 | B18: 15519 | C18: PULLEY | H18: =880+2120 -> 3000 | I18: =SUM(L18:AK18) -> 0 | AL18: =SUM(L18:AK18) -> 0 | AM18: =IF(AL18=I18,"OK","NG") -> OK
A19: 1785-00 | B19: 14988 | C19: MOTOR PULLEY | H19: =600+5400+4800 -> 10800 | I19: =SUM(L19:AK19) -> 1 | L19: 1 | AL19: =SUM(L19:AK19) -> 1 | AM19: =IF(AL19=I19,"OK","NG") -> OK
A20: 1786-00 | B20: 14983 | C20: BALL NUT PULLEY | I20: =SUM(L20:AK20) -> 0 | AL20: =SUM(L20:AK20) -> 0 | AM20: =IF(AL20=I20,"OK","NG") -> OK
A21: 1883-00 | B21: 16269 | C21: SLIDE | I21: =SUM(L21:AK21) -> 0 | AL21: =SUM(L21:AK21) -> 0 | AM21: =IF(AL21=I21,"OK","NG") -> OK
A22: 1903-00 | B22: 19059 | C22: PULLEY | I22: =SUM(L22:AK22) -> 0 | AL22: =SUM(L22:AK22) -> 0 | AM22: =IF(AL22=I22,"OK","NG") -> OK
A23: 1935-00 | B23: 18827 | C23: Driven Pulley | I23: =SUM(L23:AK23) -> 0 | AL23: =SUM(L23:AK23) -> 0 | AM23: =IF(AL23=I23,"OK","NG") -> OK
A24: 5001-00 | B24: 10163 | C24: PLATE 1-2-3-4 CLU BKG | H24: =336+672+672 -> 1680 | I24: =SUM(L24:AK24) -> 2 | L24: 1 | AC24: 1 | AL24: =SUM(L24:AK24) -> 2 | AM24: =IF(AL24=I24,"OK","NG") -> OK
A25: 5002-00 | B25: 10160 | C25: PLATE 4-5-6 CLU BKG | I25: =SUM(L25:AK25) -> 0 | AL25: =SUM(L25:AK25) -> 0 | AM25: =IF(AL25=I25,"OK","NG") -> OK
A26: 5003-00 | B26: 10158 | C26: PLATE 3-5-REV CLU BKG | I26: =SUM(L26:AK26) -> 0 | AL26: =SUM(L26:AK26) -> 0 | AM26: =IF(AL26=I26,"OK","NG") -> OK
A27: 5003-01 | B27: 10155 | C27: PLATE 3-5-REV CLU BKG | I27: =SUM(L27:AK27) -> 0 | AL27: =SUM(L27:AK27) -> 0 | AM27: =IF(AL27=I27,"OK","NG") -> OK
A28: 5004-00 | B28: 10153 | C28: PLATE LOW & REV CLU BKG | H28: 2184 | I28: =SUM(L28:AK28) -> 2 | L28: 1 | Y28: 1 | AL28: =SUM(L28:AK28) -> 2 | AM28: =IF(AL28=I28,"OK","NG") -> OK
A29: 5005-00 | B29: 10151 | C29: WHEEL-A/TRANS INPUT SHF SPD SEN RELUCTOR | H29: 1980 | I29: =SUM(L29:AK29) -> 0 | AL29: =SUM(L29:AK29) -> 0 | AM29: =IF(AL29=I29,"OK","NG") -> OK
A30: 5006-00 | B30: 10149 | C30: PLATE 1-2-3-4 CLU BKG | H30: =648+342 -> 990 | I30: =SUM(L30:AK30) -> 0 | AL30: =SUM(L30:AK30) -> 0 | AM30: =IF(AL30=I30,"OK","NG") -> OK
A31: 5007-00 | B31: 10146 | C31: PLATE 4-5-6 CLU BKG | I31: =SUM(L31:AK31) -> 0 | AL31: =SUM(L31:AK31) -> 0 | AM31: =IF(AL31=I31,"OK","NG") -> OK
A32: 5008-00 | B32: 10143 | C32: PLATE 3-5-REV CLU BKG | I32: =SUM(L32:AK32) -> 0 | AL32: =SUM(L32:AK32) -> 0 | AM32: =IF(AL32=I32,"OK","NG") -> OK
A33: 5009-00 | B33: 10141 | C33: PLATE LOW & REV CLU BKG | I33: =SUM(L33:AK33) -> 0 | AL33: =SUM(L33:AK33) -> 0 | AM33: =IF(AL33=I33,"OK","NG") -> OK
A34: 5010-00 | B34: 10139 | C34: WHEEL-A/TRANS INPUT SHF SPD | H34: 660 | I34: =SUM(L34:AK34) -> 0 | AL34: =SUM(L34:AK34) -> 0 | AM34: =IF(AL34=I34,"OK","NG") -> OK
A35: 5011-00 | B35: 10137 | C35: CARRIER-REACTION | I35: =SUM(L35:AK35) -> 0 | AL35: =SUM(L35:AK35) -> 0 | AM35: =IF(AL35=I35,"OK","NG") -> OK
A36: 5012-00 | B36: 10135 | C36: CARRIER-INPUT | I36: =SUM(L36:AK36) -> 0 | AL36: =SUM(L36:AK36) -> 0 | AM36: =IF(AL36=I36,"OK","NG") -> OK
A37: 5013-00 | B37: 10133 | C37: CARRIER-REACTION | H37: 935 | I37: =SUM(L37:AK37) -> 0 | AL37: =SUM(L37:AK37) -> 0 | AM37: =IF(AL37=I37,"OK","NG") -> OK
A38: 5014-00 | B38: 10131 | C38: CARRIER-INPUT | H38: =700+1250+952 -> 2902 | I38: =SUM(L38:AK38) -> 2 | M38: 1 | AB38: 1 | AL38: =SUM(L38:AK38) -> 2 | AM38: =IF(AL38=I38,"OK","NG") -> OK
A39: 5015-00 | B39: 10129 | C39: CARRIER - REACTION | H39: =1120+150 -> 1270 | I39: =SUM(L39:AK39) -> 0 | AL39: =SUM(L39:AK39) -> 0 | AM39: =IF(AL39=I39,"OK","NG") -> OK
A40: 5016-00 | B40: 10127 | C40: CARRIER - INPUT | I40: =SUM(L40:AK40) -> 0 | AL40: =SUM(L40:AK40) -> 0 | AM40: =IF(AL40=I40,"OK","NG") -> OK
...

Sheet 2
A1: 생산수량 | B1: =H97 -> 32189 | E1: 불량금액 | F1: =G97 -> 0
A2: 불량수량 | B2: =I97 -> 11 | L2: =SUBTOTAL(9,L6:L96) -> 4 | M2: =SUBTOTAL(9,M6:M96) -> 2 | N2: =SUBTOTAL(9,N6:N96) -> 0 | O2: =SUBTOTAL(9,O6:O96) -> 0 | P2: =SUBTOTAL(9,P6:P96) -> 0 | Q2: =SUBTOTAL(9,Q6:Q96) -> 0 | R2: =SUBTOTAL(9,R6:R96) -> 0 | S2: =SUBTOTAL(9,S6:S96) -> 0 | ... AL2: =SUBTOTAL(9,AL6:AL96) -> 11
A3: 불량율(ppm) | B3: =IF(ISERROR(B2/(B2+B1)*1000000),"",(B2/(B2+B1)*1000000)) -> 341.61491 | L3: =SUM(L6:L96) -> 4 | M3: =SUM(M6:M96) -> 2 | N3: =SUM(N6:N96) -> 0 | O3: =SUM(O6:O96) -> 0 | P3: =SUM(P6:P96) -> 0 | Q3: =SUM(Q6:Q96) -> 0 | R3: =SUM(R6:R96) -> 0 | S3: =SUM(S6:S96) -> 0 | ... AL3: =SUM(AL6:AL96) -> 11
A4: =AM97 -> OK | E4: 거래선 및 불량금액 | H4: 종합 | L4: 깨짐 | M4: 찍힘 | N4: CRACK | O4: 스크래치 | P4: 녹불량 | Q4: 초기가동 | R4: 편차수정 | S4: 중량불량 | T4: 설비Error | U4: Pellet누락 | V4: 낙물 | W4: 산화 | X4: 휨 | Y4: 눌림 | Z4: 분말소착 | AA4: 역싸이징 | AB4: 이물질소착 | AC4: 기포 | AD4: 윈도우 GO | AE4: 윈도우 NO | AF4: 조립불량 | AG4: 침투불량 | AH4: 치형뜯김 | AI4: 기타 | AJ4: 폐기 | AK4: 소재불량 | AL4: 합계 | AM4: 오기 유/무
A5: TM NO. | B5: CODE (ERP) | C5: 품 명 | D5: 차종 | E5: 거래선 | F5: 단가 | G5: 불량금액 (단가x수량) | H5: 생산수량 | I5: 불량수량 | J5: 불량율 (PPM)
A6: 1360-00 | B6: 10901 | C6: MOTOR PULLEY | I6: =SUM(L6:AK6) -> 0 | AL6: =SUM(L6:AK6) -> 0 | AM6: =IF(AL6=I6,"OK","NG") -> OK
A7: 1360-01 | B7: 15922 | C7: MOTOR PULLEY | I7: =SUM(L7:AK7) -> 0 | AL7: =SUM(L7:AK7) -> 0 | AM7: =IF(AL7=I7,"OK","NG") -> OK
A8: 1361-00 | B8: 10899 | C8: BALL NUT PULLEY | I8: =SUM(L8:AK8) -> 0 | AL8: =SUM(L8:AK8) -> 0 | AM8: =IF(AL8=I8,"OK","NG") -> OK
A9: 1361-01 | B9: 10897 | C9: BALL NUT PULLEY | I9: =SUM(L9:AK9) -> 0 | AL9: =SUM(L9:AK9) -> 0 | AM9: =IF(AL9=I9,"OK","NG") -> OK
A10: 1361-02 | B10: 18523 | C10: BALL NUT PULLEY | I10: =SUM(L10:AK10) -> 0 | AL10: =SUM(L10:AK10) -> 0 | AM10: =IF(AL10=I10,"OK","NG") -> OK
A11: 1361-50 | B11: 19445 | C11: BELT GUIDE | I11: =SUM(L11:AK11) -> 0 | AL11: =SUM(L11:AK11) -> 0 | AM11: =IF(AL11=I11,"OK","NG") -> OK
A12: 1464-00 | B12: 10315 | C12: PULLEY | I12: =SUM(L12:AK12) -> 0 | AL12: =SUM(L12:AK12) -> 0 | AM12: =IF(AL12=I12,"OK","NG") -> OK
A13: 1464-01 | B13: 14961 | C13: PULLEY | I13: =SUM(L13:AK13) -> 0 | AL13: =SUM(L13:AK13) -> 0 | AM13: =IF(AL13=I13,"OK","NG") -> OK
A14: 1510-00 | B14: 10254 | C14: PULLEY LARGE | I14: =SUM(L14:AK14) -> 0 | AL14: =SUM(L14:AK14) -> 0 | AM14: =IF(AL14=I14,"OK","NG") -> OK
A15: 1510-01 | B15: 11856 | C15: PULLEY LARGE | I15: =SUM(L15:AK15) -> 0 | AL15: =SUM(L15:AK15) -> 0 | AM15: =IF(AL15=I15,"OK","NG") -> OK
A16: 1510-02 | B16: 15003 | C16: PULLEY LARGE | I16: =SUM(L16:AK16) -> 0 | AL16: =SUM(L16:AK16) -> 0 | AM16: =IF(AL16=I16,"OK","NG") -> OK
A17: 1695-00 | B17: 15173 | C17: MOTOR PULLEY | I17: =SUM(L17:AK17) -> 0 | AL17: =SUM(L17:AK17) -> 0 | AM17: =IF(AL17=I17,"OK","NG") -> OK
A18: 1781-00 | B18: 15519 | C18: PULLEY | H18: 1360 | I18: =SUM(L18:AK18) -> 0 | AL18: =SUM(L18:AK18) -> 0 | AM18: =IF(AL18=I18,"OK","NG") -> OK
A19: 1785-00 | B19: 14988 | C19: MOTOR PULLEY | H19: =1560+2040 -> 3600 | I19: =SUM(L19:AK19) -> 0 | AL19: =SUM(L19:AK19) -> 0 | AM19: =IF(AL19=I19,"OK","NG") -> OK
A20: 1786-00 | B20: 14983 | C20: BALL NUT PULLEY | I20: =SUM(L20:AK20) -> 0 | AL20: =SUM(L20:AK20) -> 0 | AM20: =IF(AL20=I20,"OK","NG") -> OK
A21: 1883-00 | B21: 16269 | C21: SLIDE | I21: =SUM(L21:AK21) -> 0 | AL21: =SUM(L21:AK21) -> 0 | AM21: =IF(AL21=I21,"OK","NG") -> OK
A22: 1903-00 | B22: 19059 | C22: PULLEY | I22: =SUM(L22:AK22) -> 0 | AL22: =SUM(L22:AK22) -> 0 | AM22: =IF(AL22=I22,"OK","NG") -> OK
A23: 1935-00 | B23: 18827 | C23: Driven Pulley | I23: =SUM(L23:AK23) -> 0 | AL23: =SUM(L23:AK23) -> 0 | AM23: =IF(AL23=I23,"OK","NG") -> OK
A24: 5001-00 | B24: 10163 | C24: PLATE 1-2-3-4 CLU BKG | H24: =672+672 -> 1344 | I24: =SUM(L24:AK24) -> 3 | AF24: 1 | AG24: 1 | AI24: 1 | AL24: =SUM(L24:AK24) -> 3 | AM24: =IF(AL24=I24,"OK","NG") -> OK
A25: 5002-00 | B25: 10160 | C25: PLATE 4-5-6 CLU BKG | I25: =SUM(L25:AK25) -> 0 | AL25: =SUM(L25:AK25) -> 0 | AM25: =IF(AL25=I25,"OK","NG") -> OK
A26: 5003-00 | B26: 10158 | C26: PLATE 3-5-REV CLU BKG | I26: =SUM(L26:AK26) -> 0 | AL26: =SUM(L26:AK26) -> 0 | AM26: =IF(AL26=I26,"OK","NG") -> OK
A27: 5003-01 | B27: 10155 | C27: PLATE 3-5-REV CLU BKG | I27: =SUM(L27:AK27) -> 0 | AL27: =SUM(L27:AK27) -> 0 | AM27: =IF(AL27=I27,"OK","NG") -> OK
A28: 5004-00 | B28: 10153 | C28: PLATE LOW & REV CLU BKG | H28: 2184 | I28: =SUM(L28:AK28) -> 4 | L28: 2 | Y28: 1 | AC28: 1 | AL28: =SUM(L28:AK28) -> 4 | AM28: =IF(AL28=I28,"OK","NG") -> OK
A29: 5005-00 | B29: 10151 | C29: WHEEL-A/TRANS INPUT SHF SPD SEN RELUCTOR | H29: 1980 | I29: =SUM(L29:AK29) -> 0 | AL29: =SUM(L29:AK29) -> 0 | AM29: =IF(AL29=I29,"OK","NG") -> OK
A30: 5006-00 | B30: 10149 | C30: PLATE 1-2-3-4 CLU BKG | H30: 1026 | I30: =SUM(L30:AK30) -> 0 | AL30: =SUM(L30:AK30) -> 0 | AM30: =IF(AL30=I30,"OK","NG") -> OK
A31: 5007-00 | B31: 10146 | C31: PLATE 4-5-6 CLU BKG | I31: =SUM(L31:AK31) -> 0 | AL31: =SUM(L31:AK31) -> 0 | AM31: =IF(AL31=I31,"OK","NG") -> OK
A32: 5008-00 | B32: 10143 | C32: PLATE 3-5-REV CLU BKG | I32: =SUM(L32:AK32) -> 0 | AL32: =SUM(L32:AK32) -> 0 | AM32: =IF(AL32=I32,"OK","NG") -> OK
A33: 5009-00 | B33: 10141 | C33: PLATE LOW & REV CLU BKG | H33: 1770 | I33: =SUM(L33:AK33) -> 0 | AL33: =SUM(L33:AK33) -> 0 | AM33: =IF(AL33=I33,"OK","NG") -> OK
A34: 5010-00 | B34: 10139 | C34: WHEEL-A/TRANS INPUT SHF SPD | H34: 550 | I34: =SUM(L34:AK34) -> 0 | AL34: =SUM(L34:AK34) -> 0 | AM34: =IF(AL34=I34,"OK","NG") -> OK
A35: 5011-00 | B35: 10137 | C35: CARRIER-REACTION | I35: =SUM(L35:AK35) -> 0 | AL35: =SUM(L35:AK35) -> 0 | AM35: =IF(AL35=I35,"OK","NG") -> OK
A36: 5012-00 | B36: 10135 | C36: CARRIER-INPUT | I36: =SUM(L36:AK36) -> 0 | AL36: =SUM(L36:AK36) -> 0 | AM36: =IF(AL36=I36,"OK","NG") -> OK
A37: 5013-00 | B37: 10133 | C37: CARRIER-REACTION | H37: =1000+1000+905+300 -> 3205 | I37: =SUM(L37:AK37) -> 0 | AL37: =SUM(L37:AK37) -> 0 | AM37: =IF(AL37=I37,"OK","NG") -> OK
A38: 5014-00 | B38: 10131 | C38: CARRIER-INPUT | H38: 700 | I38: =SUM(L38:AK38) -> 0 | AL38: =SUM(L38:AK38) -> 0 | AM38: =IF(AL38=I38,"OK","NG") -> OK
A39: 5015-00 | B39: 10129 | C39: CARRIER - REACTION | I39: =SUM(L39:AK39) -> 0 | AL39: =SUM(L39:AK39) -> 0 | AM39: =IF(AL39=I39,"OK","NG") -> OK
A40: 5016-00 | B40: 10127 | C40: CARRIER - INPUT | I40: =SUM(L40:AK40) -> 0 | AL40: =SUM(L40:AK40) -> 0 | AM40: =IF(AL40=I40,"OK","NG") -> OK
...

Sheet 3
A1: 생산수량 | B1: =H97 -> 24066 | E1: 불량금액 | F1: =G97 -> 0
A2: 불량수량 | B2: =I97 -> 8 | L2: =SUBTOTAL(9,L6:L96) -> 1 | M2: =SUBTOTAL(9,M6:M96) -> 0 | N2: =SUBTOTAL(9,N6:N96) -> 0 | O2: =SUBTOTAL(9,O6:O96) -> 0 | P2: =SUBTOTAL(9,P6:P96) -> 0 | Q2: =SUBTOTAL(9,Q6:Q96) -> 0 | R2: =SUBTOTAL(9,R6:R96) -> 0 | S2: =SUBTOTAL(9,S6:S96) -> 0 | ... AK2: =SUBTOTAL(9,AK6:AK96) -> 0 | AL2: =SUBTOTAL(9,AL6:AL74) -> 8
A3: 불량율(ppm) | B3: =IF(ISERROR(B2/(B2+B1)*1000000),"",(B2/(B2+B1)*1000000)) -> 332.30871 | L3: =SUM(L6:L96) -> 1 | M3: =SUM(M6:M96) -> 0 | N3: =SUM(N6:N96) -> 0 | O3: =SUM(O6:O96) -> 0 | P3: =SUM(P6:P96) -> 0 | Q3: =SUM(Q6:Q96) -> 0 | R3: =SUM(R6:R96) -> 0 | S3: =SUM(S6:S96) -> 0 | ... AK3: =SUM(AK6:AK96) -> 0 | AL3: =SUM(AL6:AL74) -> 8
A4: =AM97 -> OK | E4: 거래선 및 불량금액 | H4: 종합 | L4: 깨짐 | M4: 찍힘 | N4: CRACK | O4: 스크래치 | P4: 녹불량 | Q4: 초기가동 | R4: 편차수정 | S4: 중량불량 | T4: 설비Error | U4: Pellet누락 | V4: 낙물 | W4: 산화 | X4: 휨 | Y4: 눌림 | Z4: 분말소착 | AA4: 역싸이징 | AB4: 이물질소착 | AC4: 기포 | AD4: 윈도우 GO | AE4: 윈도우 NO | AF4: 조립불량 | AG4: 침투불량 | AH4: 치형뜯김 | AI4: 기타 | AJ4: 폐기 | AK4: 소재불량 | AL4: 합계 | AM4: 오기 유/무
A5: TM NO. | B5: CODE (ERP) | C5: 품 명 | D5: 차종 | E5: 거래선 | F5: 단가 | G5: 불량금액 (단가x수량) | H5: 생산수량 | I5: 불량수량 | J5: 불량율 (PPM)
A6: 1360-00 | B6: 10901 | C6: MOTOR PULLEY | I6: =SUM(L6:AK6) -> 0 | AL6: =SUM(L6:AK6) -> 0 | AM6: =IF(AL6=I6,"OK","NG") -> OK
A7: 1360-01 | B7: 15922 | C7: MOTOR PULLEY | I7: =SUM(L7:AK7) -> 0 | AL7: =SUM(L7:AK7) -> 0 | AM7: =IF(AL7=I7,"OK","NG") -> OK
A8: 1361-00 | B8: 10899 | C8: BALL NUT PULLEY | I8: =SUM(L8:AK8) -> 0 | AL8: =SUM(L8:AK8) -> 0 | AM8: =IF(AL8=I8,"OK","NG") -> OK
A9: 1361-01 | B9: 10897 | C9: BALL NUT PULLEY | H9: =240+760 -> 1000 | I9: =SUM(L9:AK9) -> 0 | AL9: =SUM(L9:AK9) -> 0 | AM9: =IF(AL9=I9,"OK","NG") -> OK
A10: 1361-02 | B10: 18523 | C10: BALL NUT PULLEY | I10: =SUM(L10:AK10) -> 0 | AL10: =SUM(L10:AK10) -> 0 | AM10: =IF(AL10=I10,"OK","NG") -> OK
A11: 1361-50 | B11: 19445 | C11: BELT GUIDE | I11: =SUM(L11:AK11) -> 0 | AL11: =SUM(L11:AK11) -> 0 | AM11: =IF(AL11=I11,"OK","NG") -> OK
A12: 1464-00 | B12: 10315 | C12: PULLEY | I12: =SUM(L12:AK12) -> 0 | AL12: =SUM(L12:AK12) -> 0 | AM12: =IF(AL12=I12,"OK","NG") -> OK
A13: 1464-01 | B13: 14961 | C13: PULLEY | I13: =SUM(L13:AK13) -> 0 | AL13: =SUM(L13:AK13) -> 0 | AM13: =IF(AL13=I13,"OK","NG") -> OK
A14: 1510-00 | B14: 10254 | C14: PULLEY LARGE | I14: =SUM(L14:AK14) -> 0 | AL14: =SUM(L14:AK14) -> 0 | AM14: =IF(AL14=I14,"OK","NG") -> OK
A15: 1510-01 | B15: 11856 | C15: PULLEY LARGE | I15: =SUM(L15:AK15) -> 0 | AL15: =SUM(L15:AK15) -> 0 | AM15: =IF(AL15=I15,"OK","NG") -> OK
A16: 1510-02 | B16: 15003 | C16: PULLEY LARGE | I16: =SUM(L16:AK16) -> 0 | AL16: =SUM(L16:AK16) -> 0 | AM16: =IF(AL16=I16,"OK","NG") -> OK
A17: 1695-00 | B17: 15173 | C17: MOTOR PULLEY | I17: =SUM(L17:AK17) -> 0 | AL17: =SUM(L17:AK17) -> 0 | AM17: =IF(AL17=I17,"OK","NG") -> OK
A18: 1781-00 | B18: 15519 | C18: PULLEY | I18: =SUM(L18:AK18) -> 0 | AL18: =SUM(L18:AK18) -> 0 | AM18: =IF(AL18=I18,"OK","NG") -> OK
A19: 1785-00 | B19: 14988 | C19: MOTOR PULLEY | H19: 840 | I19: =SUM(L19:AK19) -> 0 | AL19: =SUM(L19:AK19) -> 0 | AM19: =IF(AL19=I19,"OK","NG") -> OK
A20: 1786-00 | B20: 14983 | C20: BALL NUT PULLEY | I20: =SUM(L20:AK20) -> 0 | AL20: =SUM(L20:AK20) -> 0 | AM20: =IF(AL20=I20,"OK","NG") -> OK
A21: 1883-00 | B21: 16269 | C21: SLIDE | I21: =SUM(L21:AK21) -> 0 | AL21: =SUM(L21:AK21) -> 0 | AM21: =IF(AL21=I21,"OK","NG") -> OK
A22: 1903-00 | B22: 19059 | C22: PULLEY | I22: =SUM(L22:AK22) -> 0 | AL22: =SUM(L22:AK22) -> 0 | AM22: =IF(AL22=I22,"OK","NG") -> OK
A23: 1935-00 | B23: 18827 | C23: Driven Pulley | I23: =SUM(L23:AK23) -> 0 | AL23: =SUM(L23:AK23) -> 0 | AM23: =IF(AL23=I23,"OK","NG") -> OK
A24: 5001-00 | B24: 10163 | C24: PLATE 1-2-3-4 CLU BKG | H24: =336+336+672+672 -> 2016 | I24: =SUM(L24:AK24) -> 0 | AL24: =SUM(L24:AK24) -> 0 | AM24: =IF(AL24=I24,"OK","NG") -> OK
A25: 5002-00 | B25: 10160 | C25: PLATE 4-5-6 CLU BKG | I25: =SUM(L25:AK25) -> 0 | AL25: =SUM(L25:AK25) -> 0 | AM25: =IF(AL25=I25,"OK","NG") -> OK
A26: 5003-00 | B26: 10158 | C26: PLATE 3-5-REV CLU BKG | I26: =SUM(L26:AK26) -> 0 | AL26: =SUM(L26:AK26) -> 0 | AM26: =IF(AL26=I26,"OK","NG") -> OK
A27: 5003-01 | B27: 10155 | C27: PLATE 3-5-REV CLU BKG | I27: =SUM(L27:AK27) -> 0 | AL27: =SUM(L27:AK27) -> 0 | AM27: =IF(AL27=I27,"OK","NG") -> OK
A28: 5004-00 | B28: 10153 | C28: PLATE LOW & REV CLU BKG | H28: 1248 | I28: =SUM(L28:AK28) -> 0 | AL28: =SUM(L28:AK28) -> 0 | AM28: =IF(AL28=I28,"OK","NG") -> OK
A29: 5005-00 | B29: 10151 | C29: WHEEL-A/TRANS INPUT SHF SPD SEN RELUCTOR | H29: 1980 | I29: =SUM(L29:AK29) -> 0 | AL29: =SUM(L29:AK29) -> 0 | AM29: =IF(AL29=I29,"OK","NG") -> OK
A30: 5006-00 | B30: 10149 | C30: PLATE 1-2-3-4 CLU BKG | H30: =684+684 -> 1368 | I30: =SUM(L30:AK30) -> 0 | AL30: =SUM(L30:AK30) -> 0 | AM30: =IF(AL30=I30,"OK","NG") -> OK
A31: 5007-00 | B31: 10146 | C31: PLATE 4-5-6 CLU BKG | I31: =SUM(L31:AK31) -> 0 | AL31: =SUM(L31:AK31) -> 0 | AM31: =IF(AL31=I31,"OK","NG") -> OK
A32: 5008-00 | B32: 10143 | C32: PLATE 3-5-REV CLU BKG | I32: =SUM(L32:AK32) -> 0 | AL32: =SUM(L32:AK32) -> 0 | AM32: =IF(AL32=I32,"OK","NG") -> OK
A33: 5009-00 | B33: 10141 | C33: PLATE LOW & REV CLU BKG | I33: =SUM(L33:AK33) -> 0 | AL33: =SUM(L33:AK33) -> 0 | AM33: =IF(AL33=I33,"OK","NG") -> OK
A34: 5010-00 | B34: 10139 | C34: WHEEL-A/TRANS INPUT SHF SPD | I34: =SUM(L34:AK34) -> 0 | AL34: =SUM(L34:AK34) -> 0 | AM34: =IF(AL34=I34,"OK","NG") -> OK
A35: 5011-00 | B35: 10137 | C35: CARRIER-REACTION | I35: =SUM(L35:AK35) -> 0 | AL35: =SUM(L35:AK35) -> 0 | AM35: =IF(AL35=I35,"OK","NG") -> OK
A36: 5012-00 | B36: 10135 | C36: CARRIER-INPUT | I36: =SUM(L36:AK36) -> 0 | AL36: =SUM(L36:AK36) -> 0 | AM36: =IF(AL36=I36,"OK","NG") -> OK
A37: 5013-00 | B37: 10133 | C37: CARRIER-REACTION | H37: =300+305 -> 605 | I37: =SUM(L37:AK37) -> 0 | AL37: =SUM(L37:AK37) -> 0 | AM37: =IF(AL37=I37,"OK","NG") -> OK
A38: 5014-00 | B38: 10131 | C38: CARRIER-INPUT | H38: =740+250 -> 990 | I38: =SUM(L38:AK38) -> 0 | AL38: =SUM(L38:AK38) -> 0 | AM38: =IF(AL38=I38,"OK","NG") -> OK
A39: 5015-00 | B39: 824 | C39: CARRIER - REACTION | I39: =SUM(L39:AK39) -> 0 | AL39: =SUM(L39:AK39) -> 0 | AM39: =IF(AL39=I39,"OK","NG") -> OK
A40: 5016-00 | B40: 10127 | C40: CARRIER - INPUT | H40: =240+1200+1620 -> 3060 | I40: =SUM(L40:AK40) -> 1 | L40: 1 | AL40: =SUM(L40:AK40) -> 1 | AM40: =IF(AL40=I40,"OK","NG") -> OK
...

Sheet 4
A1: 생산수량 | B1: =H97 -> 8127 | E1: 불량금액 | F1: =G97 -> 0
A2: 불량수량 | B2: =I97 -> 5 | L2: =SUBTOTAL(9,L6:L96) -> 5 | M2: =SUBTOTAL(9,M6:M96) -> 0 | N2: =SUBTOTAL(9,N6:N96) -> 0 | O2: =SUBTOTAL(9,O6:O96) -> 0 | P2: =SUBTOTAL(9,P6:P96) -> 0 | Q2: =SUBTOTAL(9,Q6:Q96) -> 0 | R2: =SUBTOTAL(9,R6:R96) -> 0 | S2: =SUBTOTAL(9,S6:S96) -> 0 | ... AL2: =SUBTOTAL(9,AL6:AL96) -> 5
A3: 불량율(ppm) | B3: =IF(ISERROR(B2/(B2+B1)*1000000),"",(B2/(B2+B1)*1000000)) -> 614.85489 | L3: =SUM(L6:L96) -> 5 | M3: =SUM(M6:M96) -> 0 | N3: =SUM(N6:N96) -> 0 | O3: =SUM(O6:O96) -> 0 | P3: =SUM(P6:P96) -> 0 | Q3: =SUM(Q6:Q96) -> 0 | R3: =SUM(R6:R96) -> 0 | S3: =SUM(S6:S96) -> 0 | ... AL3: =SUM(AL6:AL96) -> 5
A4: =AM97 -> OK | E4: 거래선 및 불량금액 | H4: 종합 | L4: 깨짐 | M4: 찍힘 | N4: CRACK | O4: 스크래치 | P4: 녹불량 | Q4: 초기가동 | R4: 편차수정 | S4: 중량불량 | T4: 설비Error | U4: Pellet누락 | V4: 낙물 | W4: 산화 | X4: 휨 | Y4: 눌림 | Z4: 분말소착 | AA4: 역싸이징 | AB4: 이물질소착 | AC4: 기포 | AD4: 윈도우 GO | AE4: 윈도우 NO | AF4: 조립불량 | AG4: 침투불량 | AH4: 치형뜯김 | AI4: 기타 | AJ4: 폐기 | AK4: 소재불량 | AL4: 합계 | AM4: 오기 유/무
A5: TM NO. | B5: CODE (ERP) | C5: 품 명 | D5: 차종 | E5: 거래선 | F5: 단가 | G5: 불량금액 (단가x수량) | H5: 생산수량 | I5: 불량수량 | J5: 불량율 (PPM)
A6: 1360-00 | B6: 10901 | C6: MOTOR PULLEY | I6: =SUM(L6:AK6) -> 0 | AL6: =SUM(L6:AK6) -> 0 | AM6: =IF(AL6=I6,"OK","NG") -> OK
A7: 1360-01 | B7: 15922 | C7: MOTOR PULLEY | I7: =SUM(L7:AK7) -> 0 | AL7: =SUM(L7:AK7) -> 0 | AM7: =IF(AL7=I7,"OK","NG") -> OK
A8: 1361-00 | B8: 10899 | C8: BALL NUT PULLEY | I8: =SUM(L8:AK8) -> 0 | AL8: =SUM(L8:AK8) -> 0 | AM8: =IF(AL8=I8,"OK","NG") -> OK
A9: 1361-01 | B9: 10897 | C9: BALL NUT PULLEY | I9: =SUM(L9:AK9) -> 0 | AL9: =SUM(L9:AK9) -> 0 | AM9: =IF(AL9=I9,"OK","NG") -> OK
A10: 1361-02 | B10: 18523 | C10: BALL NUT PULLEY | I10: =SUM(L10:AK10) -> 0 | AL10: =SUM(L10:AK10) -> 0 | AM10: =IF(AL10=I10,"OK","NG") -> OK
A11: 1361-50 | B11: 19445 | C11: BELT GUIDE | I11: =SUM(L11:AK11) -> 0 | AL11: =SUM(L11:AK11) -> 0 | AM11: =IF(AL11=I11,"OK","NG") -> OK
A12: 1464-00 | B12: 10315 | C12: PULLEY | I12: =SUM(L12:AK12) -> 0 | AL12: =SUM(L12:AK12) -> 0 | AM12: =IF(AL12=I12,"OK","NG") -> OK
A13: 1464-01 | B13: 14961 | C13: PULLEY | I13: =SUM(L13:AK13) -> 0 | AL13: =SUM(L13:AK13) -> 0 | AM13: =IF(AL13=I13,"OK","NG") -> OK
A14: 1510-00 | B14: 10254 | C14: PULLEY LARGE | I14: =SUM(L14:AK14) -> 0 | AL14: =SUM(L14:AK14) -> 0 | AM14: =IF(AL14=I14,"OK","NG") -> OK
A15: 1510-01 | B15: 11856 | C15: PULLEY LARGE | I15: =SUM(L15:AK15) -> 0 | AL15: =SUM(L15:AK15) -> 0 | AM15: =IF(AL15=I15,"OK","NG") -> OK
A16: 1510-02 | B16: 15003 | C16: PULLEY LARGE | I16: =SUM(L16:AK16) -> 0 | AL16: =SUM(L16:AK16) -> 0 | AM16: =IF(AL16=I16,"OK","NG") -> OK
A17: 1695-00 | B17: 15173 | C17: MOTOR PULLEY | I17: =SUM(L17:AK17) -> 0 | AL17: =SUM(L17:AK17) -> 0 | AM17: =IF(AL17=I17,"OK","NG") -> OK
... A36: 5012-00 | B36: 10135 | C36: CARRIER-INPUT | I36: =SUM(L36:AK36) -> 0 | AL36: =SUM(L36:AK36) -> 0 | AM36: =IF(AL36=I36,"OK","NG") -> OK
A37: 5013-00 | B37: 10133 | C37: CARRIER-REACTION | H37: =1220+324+1000 -> 2544 | I37: =SUM(L37:AK37) -> 0 | AL37: =SUM(L37:AK37) -> 0 | AM37: =IF(AL37=I37,"OK","NG") -> OK
A38: 5014-00 | B38: 10131 | C38: CARRIER-INPUT | I38: =SUM(L38:AK38) -> 0 | AL38: =SUM(L38:AK38) -> 0 | AM38: =IF(AL38=I38,"OK","NG") -> OK
A39: 5015-00 | B39: 10129 | C39: CARRIER - REACTION | H39: 870 | I39: =SUM(L39:AK39) -> 0 | AL39: =SUM(L39:AK39) -> 0 | AM39: =IF(AL39=I39,"OK","NG") -> OK
A40: 5016-00 | B40: 10127 | C40: CARRIER - INPUT | H40: 1860 | I40: =SUM(L40:AK40) -> 5 | L40: 5 | AL40: =SUM(L40:AK40) -> 5 | AM40: =IF(AL40=I40,"OK","NG") -> OK
A41: 5017-00 | B41: 14859 | C41: CARRIER-INPUT | I41: =SUM(L41:AK41) -> 0 | AL41: =SUM(L41:AK41) -> 0 | AM41: =IF(AL41=I41,"OK","NG") -> OK
A42: 5018-00 | B42: 15095 | C42: CARRIER-INPUT | I42: =SUM(L42:AK42) -> 0 | AL42: =SUM(L42:AK42) -> 0 | AM42: =IF(AL42=I42,"OK","NG") -> OK
A43: 6001-00 | B43: 10121 | C43: CARRIER PLANET | I43: =SUM(L43:AK43) -> 0 | AL43: =SUM(L43:AK43) -> 0 | AM43: =IF(AL43=I43,"OK","NG") -> OK
A44: 6002-00 | B44: 10120 | C44: CARRIER PLANET | I44: =SUM(L44:AK44) -> 0 | AL44: =SUM(L44:AK44) -> 0 | AM44: =IF(AL44=I44,"OK","NG") -> OK
A45: 6004-00 | B45: 13467 | C45: CARRIER PLANET MID | I45: =SUM(L45:AK45) -> 0 | AL45: =SUM(L45:AK45) -> 0 | AM45: =IF(AL45=I45,"OK","NG") -> OK
A46: 6004-01 | B46: 15948 | C46: CARRIER PLANET MID | I46: =SUM(L46:AK46) -> 0 | AL46: =SUM(L46:AK46) -> 0 | AM46: =IF(AL46=I46,"OK","NG") -> OK
A47: 6007-00 | B47: 13466 | C47: CARRIER PLANET MID | I47: =SUM(L47:AK47) -> 0 | AL47: =SUM(L47:AK47) -> 0 | AM47: =IF(AL47=I47,"OK","NG") -> OK
A48: 6007-01 | B48: 16598 | C48: CARRIER PLANET MID | I48: =SUM(L48:AK48) -> 0 | AL48: =SUM(L48:AK48) -> 0 | AM48: =IF(AL48=I48,"OK","NG") -> OK
A49: 6009-01 | B49: 11815 | C49: PRESSURE PLATE | I49: =SUM(L49:AK49) -> 0 | AL49: =SUM(L49:AK49) -> 0 | AM49: =IF(AL49=I49,"OK","NG") -> OK
A50: 6009-02 | B50: 11823 | C50: PRESSURE PLATE | I50: =SUM(L50:AK50) -> 0 | AL50: =SUM(L50:AK50) -> 0 | AM50: =IF(AL50=I50,"OK","NG") -> OK
A51: 6009-03 | B51: 11824 | C51: PRESSURE PLATE | I51: =SUM(L51:AK51) -> 0 | AL51: =SUM(L51:AK51) -> 0 | AM51: =IF(AL51=I51,"OK","NG") -> OK
A52: 6009-04 | B52: 11825 | C52: PRESSURE PLATE | I52: =SUM(L52:AK52) -> 0 | AL52: =SUM(L52:AK52) -> 0 | AM52: =IF(AL52=I52,"OK","NG") -> OK
... A63: 6019-00 | B63: 17107 | C63: HOUSING GUIDE RING | I63: =SUM(L63:AK63) -> 0 | AL63: =SUM(L63:AK63) -> 0 | AM63: =IF(AL63=I63,"OK","NG") -> OK
A64: 6020-00 | B64: 19269 | C64: CARRIER PALNET | H64: =753+2100 -> 2853 | I64: =SUM(L64:AK64) -> 0 | AL64: =SUM(L64:AK64) -> 0 | AM64: =IF(AL64=I64,"OK","NG") -> OK
A65: 1917-00 | B65: 18306 | C65: BODY | I65: =SUM(L65:AK65) -> 0 | AL65: =SUM(L65:AK65) -> 0 | AM65: =IF(AL65=I65,"OK","NG") -> OK
A66: 1914-00 | B66: 19834 | C66: MOTOR PULLEY | I66: =SUM(L66:AK66) -> 0 | AL66: =SUM(L66:AK66) -> 0 | AM66: =IF(AL66=I66,"OK","NG") -> OK
A67: 1987-00J | B67: 20277 | C67: BELT PULLEY | I67: =SUM(L67:AK67) -> 0 | AL67: =SUM(L67:AK67) -> 0 | AM67: =IF(AL67=I67,"OK","NG") -> OK
A68: 1986-00J | B68: 20269 | C68: BELT PULLEY | I68: =SUM(L68:AK68) -> 0 | AL68: =SUM(L68:AK68) -> 0 | AM68: =IF(AL68=I68,"OK","NG") -> OK
...

Sheet 5
A1: 생산수량 | B1: =H97 -> 0 | E1: 불량금액 | F1: =G97 -> 0
A2: 불량수량 | B2: =I97 -> 0 | L2: =SUBTOTAL(9,L6:L96) -> 0 | M2: =SUBTOTAL(9,M6:M96) -> 0 | N2: =SUBTOTAL(9,N6:N96) -> 0 | O2: =SUBTOTAL(9,O6:O96) -> 0 | P2: =SUBTOTAL(9,P6:P96) -> 0 | Q2: =SUBTOTAL(9,Q6:Q96) -> 0 | R2: =SUBTOTAL(9,R6:R96) -> 0 | S2: =SUBTOTAL(9,S6:S96) -> 0 | ... AL2: =SUBTOTAL(9,AL6:AL96) -> 0
A3: 불량율(ppm) | B3: =IF(ISERROR(B2/(B2+B1)*1000000),"",(B2/(B2+B1)*1000000)) | L3: =SUM(L6:L96) -> 0 | M3: =SUM(M6:M96) -> 0 | N3: =SUM(N6:N96) -> 0 | O3: =SUM(O6:O96) -> 0 | P3: =SUM(P6:P96) -> 0 | Q3: =SUM(Q6:Q96) -> 0 | R3: =SUM(R6:R96) -> 0 | S3: =SUM(S6:S96) -> 0 | ... AL3: =SUM(AL6:AL96) -> 0
A4: =AM97 -> OK | E4: 거래선 및 불량금액 | H4: 종합 | L4: 깨짐 | M4: 찍힘 | N4: CRACK | O4: 스크래치 | P4: 녹불량 | Q4: 초기가동 | R4: 편차수정 | S4: 중량불량 | T4: 설비Error | U4: Pellet누락 | V4: 낙물 | W4: 산화 | X4: 휨 | Y4: 눌림 | Z4: 분말소착 | AA4: 역싸이징 | AB4: 이물질소착 | AC4: 기포 | AD4: 윈도우 GO | AE4: 윈도우 NO | AF4: 조립불량 | AG4: 침투불량 | AH4: 치형뜯김 | AI4: 기타 | AJ4: 폐기 | AK4: 소재불량 | AL4: 합계 | AM4: 오기 유/무
A5: TM NO. | B5: CODE (ERP) | C5: 품 명 | D5: 차종 | E5: 거래선 | F5: 단가 | G5: 불량금액 (단가x수량) | H5: 생산수량 | I5: 불량수량 | J5: 불량율 (PPM)
A6: 1360-00 | B6: 10901 | C6: MOTOR PULLEY | I6: =SUM(L6:AK6) -> 0 | AL6: =SUM(L6:AK6) -> 0 | AM6: =IF(AL6=I6,"OK","NG") -> OK
A7: 1360-01 | B7: 15922 | C7: MOTOR PULLEY | I7: =SUM(L7:AK7) -> 0 | AL7: =SUM(L7:AK7) -> 0 | AM7: =IF(AL7=I7,"OK","NG") -> OK
A8: 1361-00 | B8: 10899 | C8: BALL NUT PULLEY | I8: =SUM(L8:AK8) -> 0 | AL8: =SUM(L8:AK8) -> 0 | AM8: =IF(AL8=I8,"OK","NG") -> OK
A9: 1361-01 | B9: 10897 | C9: BALL NUT PULLEY | I9: =SUM(L9:AK9) -> 0 | AL9: =SUM(L9:AK9) -> 0 | AM9: =IF(AL9=I9,"OK","NG") -> OK
A10: 1361-02 | B10: 18523 | C10: BALL NUT PULLEY | I10: =SUM(L10:AK10) -> 0 | AL10: =SUM(L10:AK10) -> 0 | AM10: =IF(AL10=I10,"OK","NG") -> OK
A11: 1361-50 | B11: 19445 | C11: BELT GUIDE | I11: =SUM(L11:AK11) -> 0 | AL11: =SUM(L11:AK11) -> 0 | AM11: =IF(AL11=I11,"OK","NG") -> OK
A12: 1464-00 | B12: 10315 | C12: PULLEY | I12: =SUM(L12:AK12) -> 0 | AL12: =SUM(L12:AK12) -> 0 | AM12: =IF(AL12=I12,"OK","NG") -> OK
A13: 1464-01 | B13: 14961 | C13: PULLEY | I13: =SUM(L13:AK13) -> 0 | AL13: =SUM(L13:AK13) -> 0 | AM13: =IF(AL13=I13,"OK","NG") -> OK
A14: 1510-00 | B14: 10254 | C14: PULLEY LARGE | I14: =SUM(L14:AK14) -> 0 | AL14: =SUM(L14:AK14) -> 0 | AM14: =IF(AL14=I14,"OK","NG") -> OK
A15: 1510-01 | B15: 11856 | C15: PULLEY LARGE | I15: =SUM(L15:AK15) -> 0 | AL15: =SUM(L15:AK15) -> 0 | AM15: =IF(AL15=I15,"OK","NG") -> OK
A16: 1510-02 | B16: 15003 | C16: PULLEY LARGE | I16: =SUM(L16:AK16) -> 0 | AL16: =SUM(L16:AK16) -> 0 | AM16: =IF(AL16=I16,"OK","NG") -> OK
A17: 1695-00 | B17: 15173 | C17: MOTOR PULLEY | I17: =SUM(L17:AK17) -> 0 | AL17: =SUM(L17:AK17) -> 0 | AM17: =IF(AL17=I17,"OK","NG") -> OK
... A77: 1630-00 | B77: 13007 | C77: 성형-REB,RETAINER | I77: =SUM(L77:AK77) -> 0 | AL77: =SUM(L77:AK77) -> 0 | AM77: =IF(AL77=I77,"OK","NG") -> OK
I78: =SUM(L78:AK78) -> 0 | AL78: =SUM(L78:AK78) -> 0 | AM78: =IF(AL78=I78,"OK","NG") -> OK
I79: =SUM(L79:AK79) -> 0 | AL79: =SUM(L79:AK79) -> 0 | AM79: =IF(AL79=I79,"OK","NG") -> OK
I80: =SUM(L80:AK80) -> 0 | AL80: =SUM(L80:AK80) -> 0 | AM80: =IF(AL80=I80,"OK","NG") -> OK
I81: =SUM(L81:AK81) -> 0 | AL81: =SUM(L81:AK81) -> 0 | AM81: =IF(AL81=I81,"OK","NG") -> OK
I82: =SUM(L82:AK82) -> 0 | AL82: =SUM(L82:AK82) -> 0 | AM82: =IF(AL82=I82,"OK","NG") -> OK
I83: =SUM(L83:AK83) -> 0 | AL83: =SUM(L83:AK83) -> 0 | AM83: =IF(AL83=I83,"OK","NG") -> OK
I84: =SUM(L84:AK84) -> 0 | AL84: =SUM(L84:AK84) -> 0 | AM84: =IF(AL84=I84,"OK","NG") -> OK
I85: =SUM(L85:AK85) -> 0 | AL85: =SUM(L85:AK85) -> 0 | AM85: =IF(AL85=I85,"OK","NG") -> OK
I86: =SUM(L86:AK86) -> 0 | AL86: =SUM(L86:AK86) -> 0 | AM86: =IF(AL86=I86,"OK","NG") -> OK
I87: =SUM(L87:AK87) -> 0 | AL87: =SUM(L87:AK87) -> 0 | AM87: =IF(AL87=I87,"OK","NG") -> OK
I88: =SUM(L88:AK88) -> 0 | AL88: =SUM(L88:AK88) -> 0 | AM88: =IF(AL88=I88,"OK","NG") -> OK
I89: =SUM(L89:AK89) -> 0 | AL89: =SUM(L89:AK89) -> 0 | AM89: =IF(AL89=I89,"OK","NG") -> OK
... I96: =SUM(L96:AK96) -> 0 | AL96: =SUM(L96:AK96) -> 0 | AM96: =IF(AL96=I96,"OK","NG") -> OK
C97: 소계 SUBTOTAL(가로) | G97: =SUM(G6:G74) -> 0 | H97: =SUM(H6:H96) -> 0 | I97: =SUM(I6:I96) -> 0 | J97: =SUM(J6:J74) -> 0 | L97: =SUM(L6:L96) -> 0 | M97: =SUM(M6:M96) -> 0 | N97: =SUM(N6:N96) -> 0 | O97: =SUM(O6:O96) -> 0 | P97: =SUM(P6:P96) -> 0 | Q97: =SUM(Q6:Q96) -> 0 | R97: =SUM(R6:R96) -> 0 | S97: =SUM(S6:S96) -> 0 | ... AL97: =SUM(AL6:AL96) -> 0 | AM97: =IF(AL97=SUM(I97),"OK","NG") -> OK

Sheet 6
A1: 생산수량 | B1: =H97 -> 38138 | E1: 불량금액 | F1: =G97 -> 0
A2: 불량수량 | B2: =I97 -> 20 | L2: =SUBTOTAL(9,L6:L96) -> 7 | M2: =SUBTOTAL(9,M6:M96) -> 0 | N2: =SUBTOTAL(9,N6:N96) -> 0 | O2: =SUBTOTAL(9,O6:O96) -> 0 | P2: =SUBTOTAL(9,P6:P96) -> 0 | Q2: =SUBTOTAL(9,Q6:Q96) -> 0 | R2: =SUBTOTAL(9,R6:R96) -> 0 | S2: =SUBTOTAL(9,S6:S96) -> 0 | ... AL2: =SUBTOTAL(9,AL6:AL96) -> 20
A3: 불량율(ppm) | B3: =IF(ISERROR(B2/(B2+B1)*1000000),"",(B2/(B2+B1)*1000000)) -> 524.13649 | L3: =SUM(L6:L96) -> 7 | M3: =SUM(M6:M96) -> 0 | N3: =SUM(N6:N96) -> 0 | O3: =SUM(O6:O96) -> 0 | P3: =SUM(P6:P96) -> 0 | Q3: =SUM(Q6:Q96) -> 0 | R3: =SUM(R6:R96) -> 0 | S3: =SUM(S6:S96) -> 0 | ... AL3: =SUM(AL6:AL96) -> 20
A4: =AM97 -> OK | E4: 거래선 및 불량금액 | H4: 종합 | L4: 깨짐 | M4: 찍힘 | N4: CRACK | O4: 스크래치 | P4: 녹불량 | Q4: 초기가동 | R4: 편차수정 | S4: 중량불량 | T4: 설비Error | U4: Pellet누락 | V4: 낙물 | W4: 산화 | X4: 휨 | Y4: 눌림 | Z4: 분말소착 | AA4: 역싸이징 | AB4: 이물질소착 | AC4: 기포 | AD4: 윈도우 GO | AE4: 윈도우 NO | AF4: 조립불량 | AG4: 침투불량 | AH4: 치형뜯김 | AI4: 기타 | AJ4: 폐기 | AK4: 소재불량 | AL4: 합계 | AM4: 오기 유/무
A5: TM NO. | B5: CODE (ERP) | C5: 품 명 | D5: 차종 | E5: 거래선 | F5: 단가 | G5: 불량금액 (단가x수량) | H5: 생산수량 | I5: 불량수량 | J5: 불량율 (PPM)
A6: 1360-00 | B6: 10901 | C6: MOTOR PULLEY | H6: 3600 | I6: =SUM(L6:AK6) -> 0 | AL6: =SUM(L6:AK6) -> 0 | AM6: =IF(AL6=I6,"OK","NG") -> OK
A7: 1360-01 | B7: 15922 | C7: MOTOR PULLEY | I7: =SUM(L7:AK7) -> 0 | AL7: =SUM(L7:AK7) -> 0 | AM7: =IF(AL7=I7,"OK","NG") -> OK
A8: 1361-00 | B8: 10899 | C8: BALL NUT PULLEY | I8: =SUM(L8:AK8) -> 0 | AL8: =SUM(L8:AK8) -> 0 | AM8: =IF(AL8=I8,"OK","NG") -> OK
A9: 1361-01 | B9: 10897 | C9: BALL NUT PULLEY | I9: =SUM(L9:AK9) -> 0 | AL9: =SUM(L9:AK9) -> 0 | AM9: =IF(AL9=I9,"OK","NG") -> OK
A10: 1361-02 | B10: 18523 | C10: BALL NUT PULLEY | I10: =SUM(L10:AK10) -> 0 | AL10: =SUM(L10:AK10) -> 0 | AM10: =IF(AL10=I10,"OK","NG") -> OK
A11: 1361-50 | B11: 19445 | C11: BELT GUIDE | I11: =SUM(L11:AK11) -> 0 | AL11: =SUM(L11:AK11) -> 0 | AM11: =IF(AL11=I11,"OK","NG") -> OK
A12: 1464-00 | B12: 10315 | C12: PULLEY | I12: =SUM(L12:AK12) -> 0 | AL12: =SUM(L12:AK12) -> 0 | AM12: =IF(AL12=I12,"OK","NG") -> OK
A13: 1464-01 | B13: 14961 | C13: PULLEY | I13: =SUM(L13:AK13) -> 0 | AL13: =SUM(L13:AK13) -> 0 | AM13: =IF(AL13=I13,"OK","NG") -> OK
A14: 1510-00 | B14: 10254 | C14: PULLEY LARGE | H14: =1560+1200 -> 2760 | I14: =SUM(L14:AK14) -> 2 | L14: 1 | Y14: 1 | AL14: =SUM(L14:AK14) -> 2 | AM14: =IF(AL14=I14,"OK","NG") -> OK
A15: 1510-01 | B15: 11856 | C15: PULLEY LARGE | H15: 240 | I15: =SUM(L15:AK15) -> 0 | AL15: =SUM(L15:AK15) -> 0 | AM15: =IF(AL15=I15,"OK","NG") -> OK
A16: 1510-02 | B16: 15003 | C16: PULLEY LARGE | I16: =SUM(L16:AK16) -> 0 | AL16: =SUM(L16:AK16) -> 0 | AM16: =IF(AL16=I16,"OK","NG") -> OK
A17: 1695-00 | B17: 15173 | C17: MOTOR PULLEY | I17: =SUM(L17:AK17) -> 0 | AL17: =SUM(L17:AK17) -> 0 | AM17: =IF(AL17=I17,"OK","NG") -> OK
A18: 1781-00 | B18: 15519 | C18: PULLEY | I18: =SUM(L18:AK18) -> 0 | AL18: =SUM(L18:AK18) -> 0 | AM18: =IF(AL18=I18,"OK","NG") -> OK
A19: 1785-00 | B19: 14988 | C19: MOTOR PULLEY | I19: =SUM(L19:AK19) -> 0 | AL19: =SUM(L19:AK19) -> 0 | AM19: =IF(AL19=I19,"OK","NG") -> OK
A20: 1786-00 | B20: 14983 | C20: BALL NUT PULLEY | I20: =SUM(L20:AK20) -> 0 | AL20: =SUM(L20:AK20) -> 0 | AM20: =IF(AL20=I20,"OK","NG") -> OK
A21: 1883-00 | B21: 16269 | C21: SLIDE | I21: =SUM(L21:AK21) -> 0 | AL21: =SUM(L21:AK21) -> 0 | AM21: =IF(AL21=I21,"OK","NG") -> OK
A22: 1903-00 | B22: 19059 | C22: PULLEY | I22: =SUM(L22:AK22) -> 0 | AL22: =SUM(L22:AK22) -> 0 | AM22: =IF(AL22=I22,"OK","NG") -> OK
A23: 1935-00 | B23: 18827 | C23: Driven Pulley | I23: =SUM(L23:AK23) -> 0 | AL23: =SUM(L23:AK23) -> 0 | AM23: =IF(AL23=I23,"OK","NG") -> OK
A24: 5001-00 | B24: 10163 | C24: PLATE 1-2-3-4 CLU BKG | H24: 1344 | I24: =SUM(L24:AK24) -> 4 | L24: 3 | AC24: 1 | AL24: =SUM(L24:AK24) -> 4 | AM24: =IF(AL24=I24,"OK","NG") -> OK
A25: 5002-00 | B25: 10160 | C25: PLATE 4-5-6 CLU BKG | I25: =SUM(L25:AK25) -> 0 | AL25: =SUM(L25:AK25) -> 0 | AM25: =IF(AL25=I25,"OK","NG") -> OK
A26: 5003-00 | B26: 10158 | C26: PLATE 3-5-REV CLU BKG | I26: =SUM(L26:AK26) -> 0 | AL26: =SUM(L26:AK26) -> 0 | AM26: =IF(AL26=I26,"OK","NG") -> OK
A27: 5003-01 | B27: 10155 | C27: PLATE 3-5-REV CLU BKG | I27: =SUM(L27:AK27) -> 0 | AL27: =SUM(L27:AK27) -> 0 | AM27: =IF(AL27=I27,"OK","NG") -> OK
A28: 5004-00 | B28: 10153 | C28: PLATE LOW & REV CLU BKG | H28: 624 | I28: =SUM(L28:AK28) -> 0 | AL28: =SUM(L28:AK28) -> 0 | AM28: =IF(AL28=I28,"OK","NG") -> OK
A29: 5005-00 | B29: 10151 | C29: WHEEL-A/TRANS INPUT SHF SPD SEN RELUCTOR | H29: =264+440 -> 704 | I29: =SUM(L29:AK29) -> 0 | AL29: =SUM(L29:AK29) -> 0 | AM29: =IF(AL29=I29,"OK","NG") -> OK
A30: 5006-00 | B30: 10149 | C30: PLATE 1-2-3-4 CLU BKG | H30: 1296 | I30: =SUM(L30:AK30) -> 5 | AI30: 5 | AL30: =SUM(L30:AK30) -> 5 | AM30: =IF(AL30=I30,"OK","NG") -> OK
A31: 5007-00 | B31: 10146 | C31: PLATE 4-5-6 CLU BKG | I31: =SUM(L31:AK31) -> 0 | AL31: =SUM(L31:AK31) -> 0 | AM31: =IF(AL31=I31,"OK","NG") -> OK
A32: 5008-00 | B32: 10143 | C32: PLATE 3-5-REV CLU BKG | I32: =SUM(L32:AK32) -> 0 | AL32: =SUM(L32:AK32) -> 0 | AM32: =IF(AL32=I32,"OK","NG") -> OK
A33: 5009-00 | B33: 10141 | C33: PLATE LOW & REV CLU BKG | H33: 1416 | I33: =SUM(L33:AK33) -> 1 | L33: 1 | AL33: =SUM(L33:AK33) -> 1 | AM33: =IF(AL33=I33,"OK","NG") -> OK
A34: 5010-00 | B34: 10139 | C34: WHEEL-A/TRANS INPUT SHF SPD | H34: =660+660+660 -> 1980 | I34: =SUM(L34:AK34) -> 2 | Y34: 2 | AL34: =SUM(L34:AK34) -> 2 | AM34: =IF(AL34=I34,"OK","NG") -> OK
A35: 5011-00 | B35: 10137 | C35: CARRIER-REACTION | I35: =SUM(L35:AK35) -> 0 | AL35: =SUM(L35:AK35) -> 0 | AM35: =IF(AL35=I35,"OK","NG") -> OK
A36: 5012-00 | B36: 10135 | C36: CARRIER-INPUT | I36: =SUM(L36:AK36) -> 0 | AL36: =SUM(L36:AK36) -> 0 | AM36: =IF(AL36=I36,"OK","NG") -> OK
A37: 5013-00 | B37: 10133 | C37: CARRIER-REACTION | I37: =SUM(L37:AK37) -> 0 | AL37: =SUM(L37:AK37) -> 0 | AM37: =IF(AL37=I37,"OK","NG") -> OK
A38: 5014-00 | B38: 10131 | C38: CARRIER-INPUT | H38: =400+600 -> 1000 | I38: =SUM(L38:AK38) -> 2 | L38: 1 | AC38: 1 | AL38: =SUM(L38:AK38) -> 2 | AM38: =IF(AL38=I38,"OK","NG") -> OK
A39: 5015-00 | B39: 10129 | C39: CARRIER - REACTION | H39: 750 | I39: =SUM(L39:AK39) -> 0 | AL39: =SUM(L39:AK39) -> 0 | AM39: =IF(AL39=I39,"OK","NG") -> OK
A40: 5016-00 | B40: 10127 | C40: CARRIER - INPUT | H40: =700+984+177+1400 -> 3261 | I40: =SUM(L40:AK40) -> 1 | L40: 1 | AL40: =SUM(L40:AK40) -> 1 | AM40: =IF(AL40=I40,"OK","NG") -> OK
...

Sheet 7
A1: 생산수량 | B1: =H97 -> 28185 | E1: 불량금액 | F1: =G97 -> 0
A2: 불량수량 | B2: =I97 -> 24 | L2: =SUBTOTAL(9,L6:L96) -> 0 | M2: =SUBTOTAL(9,M6:M96) -> 9 | N2: =SUBTOTAL(9,N6:N96) -> 0 | O2: =SUBTOTAL(9,O6:O96) -> 0 | P2: =SUBTOTAL(9,P6:P96) -> 0 | Q2: =SUBTOTAL(9,Q6:Q96) -> 0 | R2: =SUBTOTAL(9,R6:R96) -> 0 | S2: =SUBTOTAL(9,S6:S96) -> 0 | ... AL2: =SUBTOTAL(9,AL6:AL96) -> 24
A3: 불량율(ppm) | B3: =IF(ISERROR(B2/(B2+B1)*1000000),"",(B2/(B2+B1)*1000000)) -> 850.7923 | L3: =SUM(L6:L96) -> 0 | M3: =SUM(M6:M96) -> 9 | N3: =SUM(N6:N96) -> 0 | O3: =SUM(O6:O96) -> 0 | P3: =SUM(P6:P96) -> 0 | Q3: =SUM(Q6:Q96) -> 0 | R3: =SUM(R6:R96) -> 0 | S3: =SUM(S6:S96) -> 0 | ... AL3: =SUM(AL6:AL96) -> 24
A4: =AM97 -> OK | E4: 거래선 및 불량금액 | H4: 종합 | L4: 깨짐 | M4: 찍힘 | N4: CRACK | O4: 스크래치 | P4: 녹불량 | Q4: 초기가동 | R4: 편차수정 | S4: 중량불량 | T4: 설비Error | U4: Pellet누락 | V4: 낙물 | W4: 산화 | X4: 휨 | Y4: 눌림 | Z4: 분말소착 | AA4: 역싸이징 | AB4: 이물질소착 | AC4: 기포 | AD4: 윈도우 GO | AE4: 윈도우 NO | AF4: 조립불량 | AG4: 침투불량 | AH4: 치형뜯김 | AI4: 기타 | AJ4: 폐기 | AK4: 소재불량 | AL4: 합계 | AM4: 오기 유/무
A5: TM NO. | B5: CODE (ERP) | C5: 품 명 | D5: 차종 | E5: 거래선 | F5: 단가 | G5: 불량금액 (단가x수량) | H5: 생산수량 | I5: 불량수량 | J5: 불량율 (PPM)
A6: 1360-00 | B6: 10901 | C6: MOTOR PULLEY | H6: =900+800+422+200+2190 -> 4512 | I6: =SUM(L6:AK6) -> 13 | M6: 8 | Y6: 3 | AC6: 2 | AL6: =SUM(L6:AK6) -> 13 | AM6: =IF(AL6=I6,"OK","NG") -> OK
A7: 1360-01 | B7: 15922 | C7: MOTOR PULLEY | I7: =SUM(L7:AK7) -> 0 | AL7: =SUM(L7:AK7) -> 0 | AM7: =IF(AL7=I7,"OK","NG") -> OK
A8: 1361-00 | B8: 10899 | C8: BALL NUT PULLEY | I8: =SUM(L8:AK8) -> 0 | AL8: =SUM(L8:AK8) -> 0 | AM8: =IF(AL8=I8,"OK","NG") -> OK
A9: 1361-01 | B9: 10897 | C9: BALL NUT PULLEY | H9: 100 | I9: =SUM(L9:AK9) -> 0 | AL9: =SUM(L9:AK9) -> 0 | AM9: =IF(AL9=I9,"OK","NG") -> OK
A10: 1361-02 | B10: 18523 | C10: BALL NUT PULLEY | I10: =SUM(L10:AK10) -> 0 | AL10: =SUM(L10:AK10) -> 0 | AM10: =IF(AL10=I10,"OK","NG") -> OK
A11: 1361-50 | B11: 19445 | C11: BELT GUIDE | I11: =SUM(L11:AK11) -> 0 | AL11: =SUM(L11:AK11) -> 0 | AM11: =IF(AL11=I11,"OK","NG") -> OK
A12: 1464-00 | B12: 10315 | C12: PULLEY | I12: =SUM(L12:AK12) -> 0 | AL12: =SUM(L12:AK12) -> 0 | AM12: =IF(AL12=I12,"OK","NG") -> OK
A13: 1464-01 | B13: 14961 | C13: PULLEY | I13: =SUM(L13:AK13) -> 0 | AL13: =SUM(L13:AK13) -> 0 | AM13: =IF(AL13=I13,"OK","NG") -> OK
A14: 1510-00 | B14: 10254 | C14: PULLEY LARGE | H14: 320 | I14: =SUM(L14:AK14) -> 0 | AL14: =SUM(L14:AK14) -> 0 | AM14: =IF(AL14=I14,"OK","NG") -> OK
A15: 1510-01 | B15: 11856 | C15: PULLEY LARGE | H15: 720 | I15: =SUM(L15:AK15) -> 0 | AL15: =SUM(L15:AK15) -> 0 | AM15: =IF(AL15=I15,"OK","NG") -> OK
A16: 1510-02 | B16: 15003 | C16: PULLEY LARGE | I16: =SUM(L16:AK16) -> 0 | AL16: =SUM(L16:AK16) -> 0 | AM16: =IF(AL16=I16,"OK","NG") -> OK
A17: 1695-00 | B17: 15173 | C17: MOTOR PULLEY | I17: =SUM(L17:AK17) -> 0 | AL17: =SUM(L17:AK17) -> 0 | AM17: =IF(AL17=I17,"OK","NG") -> OK
A18: 1781-00 | B18: 15519 | C18: PULLEY | I18: =SUM(L18:AK18) -> 0 | AL18: =SUM(L18:AK18) -> 0 | AM18: =IF(AL18=I18,"OK","NG") -> OK
A19: 1785-00 | B19: 14988 | C19: MOTOR PULLEY | H19: =1560+1680+1560 -> 4800 | I19: =SUM(L19:AK19) -> 0 | AL19: =SUM(L19:AK19) -> 0 | AM19: =IF(AL19=I19,"OK","NG") -> OK
A20: 1786-00 | B20: 14983 | C20: BALL NUT PULLEY | I20: =SUM(L20:AK20) -> 0 | AL20: =SUM(L20:AK20) -> 0 | AM20: =IF(AL20=I20,"OK","NG") -> OK
A21: 1883-00 | B21: 16269 | C21: SLIDE | I21: =SUM(L21:AK21) -> 0 | AL21: =SUM(L21:AK21) -> 0 | AM21: =IF(AL21=I21,"OK","NG") -> OK
A22: 1903-00 | B22: 19059 | C22: PULLEY | I22: =SUM(L22:AK22) -> 0 | AL22: =SUM(L22:AK22) -> 0 | AM22: =IF(AL22=I22,"OK","NG") -> OK
A23: 1935-00 | B23: 18827 | C23: Driven Pulley | I23: =SUM(L23:AK23) -> 0 | AL23: =SUM(L23:AK23) -> 0 | AM23: =IF(AL23=I23,"OK","NG") -> OK
A24: 5001-00 | B24: 10163 | C24: PLATE 1-2-3-4 CLU BKG | H24: 1344 | I24: =SUM(L24:AK24) -> 0 | AL24: =SUM(L24:AK24) -> 0 | AM24: =IF(AL24=I24,"OK","NG") -> OK
A25: 5002-00 | B25: 10160 | C25: PLATE 4-5-6 CLU BKG | I25: =SUM(L25:AK25) -> 0 | AL25: =SUM(L25:AK25) -> 0 | AM25: =IF(AL25=I25,"OK","NG") -> OK
A26: 5003-00 | B26: 10158 | C26: PLATE 3-5-REV CLU BKG | I26: =SUM(L26:AK26) -> 0 | AL26: =SUM(L26:AK26) -> 0 | AM26: =IF(AL26=I26,"OK","NG") -> OK
A27: 5003-01 | B27: 10155 | C27: PLATE 3-5-REV CLU BKG | I27: =SUM(L27:AK27) -> 0 | AL27: =SUM(L27:AK27) -> 0 | AM27: =IF(AL27=I27,"OK","NG") -> OK
A28: 5004-00 | B28: 10153 | C28: PLATE LOW & REV CLU BKG | H28: =624+624+312 -> 1560 | I28: =SUM(L28:AK28) -> 4 | M28: 1 | Z28: 3 | AL28: =SUM(L28:AK28) -> 4 | AM28: =IF(AL28=I28,"OK","NG") -> OK
A29: 5005-00 | B29: 10151 | C29: WHEEL-A/TRANS INPUT SHF SPD SEN RELUCTOR | H29: =924+418 -> 1342 | I29: =SUM(L29:AK29) -> 6 | AC29: 6 | AL29: =SUM(L29:AK29) -> 6 | AM29: =IF(AL29=I29,"OK","NG") -> OK
A30: 5006-00 | B30: 10149 | C30: PLATE 1-2-3-4 CLU BKG | H30: 1296 | I30: =SUM(L30:AK30) -> 0 | AL30: =SUM(L30:AK30) -> 0 | AM30: =IF(AL30=I30,"OK","NG") -> OK
A31: 5007-00 | B31: 10146 | C31: PLATE 4-5-6 CLU BKG | I31: =SUM(L31:AK31) -> 0 | AL31: =SUM(L31:AK31) -> 0 | AM31: =IF(AL31=I31,"OK","NG") -> OK
A32: 5008-00 | B32: 10143 | C32: PLATE 3-5-REV CLU BKG | I32: =SUM(L32:AK32) -> 0 | AL32: =SUM(L32:AK32) -> 0 | AM32: =IF(AL32=I32,"OK","NG") -> OK
A33: 5009-00 | B33: 10141 | C33: PLATE LOW & REV CLU BKG | I33: =SUM(L33:AK33) -> 0 | AL33: =SUM(L33:AK33) -> 0 | AM33: =IF(AL33=I33,"OK","NG") -> OK
A34: 5010-00 | B34: 10139 | C34: WHEEL-A/TRANS INPUT SHF SPD | H34: 1320 | I34: =SUM(L34:AK34) -> 0 | AL34: =SUM(L34:AK34) -> 0 | AM34: =IF(AL34=I34,"OK","NG") -> OK
A35: 5011-00 | B35: 10137 | C35: CARRIER-REACTION | I35: =SUM(L35:AK35) -> 0 | AL35: =SUM(L35:AK35) -> 0 | AM35: =IF(AL35=I35,"OK","NG") -> OK
A36: 5012-00 | B36: 10135 | C36: CARRIER-INPUT | I36: =SUM(L36:AK36) -> 0 | AL36: =SUM(L36:AK36) -> 0 | AM36: =IF(AL36=I36,"OK","NG") -> OK
A37: 5013-00 | B37: 10133 | C37: CARRIER-REACTION | I37: =SUM(L37:AK37) -> 0 | AL37: =SUM(L37:AK37) -> 0 | AM37: =IF(AL37=I37,"OK","NG") -> OK
A38: 5014-00 | B38: 10131 | C38: CARRIER-INPUT | I38: =SUM(L38:AK38) -> 0 | AL38: =SUM(L38:AK38) -> 0 | AM38: =IF(AL38=I38,"OK","NG") -> OK
A39: 5015-00 | B39: 10129 | C39: CARRIER - REACTION | I39: =SUM(L39:AK39) -> 0 | AL39: =SUM(L39:AK39) -> 0 | AM39: =IF(AL39=I39,"OK","NG") -> OK
A40: 5016-00 | B40: 10127 | C40: CARRIER - INPUT | H40: 1350 | I40: =SUM(L40:AK40) -> 0 | AL40: =SUM(L40:AK40) -> 0 | AM40: =IF(AL40=I40,"OK","NG") -> OK
...

Sheet 8
A1: 생산수량 | B1: =H97 -> 34294 | E1: 불량금액 | F1: =G97 -> 0
A2: 불량수량 | B2: =I97 -> 33 | L2: =SUBTOTAL(9,L6:L96) -> 7 | M2: =SUBTOTAL(9,M6:M96) -> 5 | N2: =SUBTOTAL(9,N6:N96) -> 0 | O2: =SUBTOTAL(9,O6:O96) -> 0 | P2: =SUBTOTAL(9,P6:P96) -> 1 | Q2: =SUBTOTAL(9,Q6:Q96) -> 0 | R2: =SUBTOTAL(9,R6:R96) -> 0 | S2: =SUBTOTAL(9,S6:S96) -> 0 | ... AL2: =SUBTOTAL(9,AL6:AL96) -> 33
A3: 불량율(ppm) | B3: =IF(ISERROR(B2/(B2+B1)*1000000),"",(B2/(B2+B1)*1000000)) -> 961.34238 | L3: =SUM(L6:L96) -> 7 | M3: =SUM(M6:M96) -> 5 | N3: =SUM(N6:N96) -> 0 | O3: =SUM(O6:O96) -> 0 | P3: =SUM(P6:P96) -> 1 | Q3: =SUM(Q6:Q96) -> 0 | R3: =SUM(R6:R96) -> 0 | S3: =SUM(S6:S96) -> 0 | ... AL3: =SUM(AL6:AL96) -> 33
A4: =AM97 -> OK | E4: 거래선 및 불량금액 | H4: 종합 | L4: 깨짐 | M4: 찍힘 | N4: CRACK | O4: 스크래치 | P4: 녹불량 | Q4: 초기가동 | R4: 편차수정 | S4: 중량불량 | T4: 설비Error | U4: Pellet누락 | V4: 낙물 | W4: 산화 | X4: 휨 | Y4: 눌림 | Z4: 분말소착 | AA4: 역싸이징 | AB4: 이물질소착 | AC4: 기포 | AD4: 윈도우 GO | AE4: 윈도우 NO | AF4: 조립불량 | AG4: 침투불량 | AH4: 치형뜯김 | AI4: 기타 | AJ4: 폐기 | AK4: 소재불량 | AL4: 합계 | AM4: 오기 유/무
A5: TM NO. | B5: CODE (ERP) | C5: 품 명 | D5: 차종 | E5: 거래선 | F5: 단가 | G5: 불량금액 (단가x수량) | H5: 생산수량 | I5: 불량수량 | J5: 불량율 (PPM)
A6: 1360-00 | B6: 10901 | C6: MOTOR PULLEY | H6: 1440 | I6: =SUM(L6:AK6) -> 7 | L6: 1 | M6: 1 | AC6: 5 | AL6: =SUM(L6:AK6) -> 7 | AM6: =IF(AL6=I6,"OK","NG") -> OK
A7: 1360-01 | B7: 15922 | C7: MOTOR PULLEY | I7: =SUM(L7:AK7) -> 0 | AL7: =SUM(L7:AK7) -> 0 | AM7: =IF(AL7=I7,"OK","NG") -> OK
A8: 1361-00 | B8: 10899 | C8: BALL NUT PULLEY | I8: =SUM(L8:AK8) -> 0 | AL8: =SUM(L8:AK8) -> 0 | AM8: =IF(AL8=I8,"OK","NG") -> OK
A9: 1361-01 | B9: 10897 | C9: BALL NUT PULLEY | H9: 900 | I9: =SUM(L9:AK9) -> 0 | AL9: =SUM(L9:AK9) -> 0 | AM9: =IF(AL9=I9,"OK","NG") -> OK
A10: 1361-02 | B10: 18523 | C10: BALL NUT PULLEY | I10: =SUM(L10:AK10) -> 0 | AL10: =SUM(L10:AK10) -> 0 | AM10: =IF(AL10=I10,"OK","NG") -> OK
A11: 1361-50 | B11: 19445 | C11: BELT GUIDE | I11: =SUM(L11:AK11) -> 0 | AL11: =SUM(L11:AK11) -> 0 | AM11: =IF(AL11=I11,"OK","NG") -> OK
A12: 1464-00 | B12: 10315 | C12: PULLEY | I12: =SUM(L12:AK12) -> 0 | AL12: =SUM(L12:AK12) -> 0 | AM12: =IF(AL12=I12,"OK","NG") -> OK
A13: 1464-01 | B13: 14961 | C13: PULLEY | I13: =SUM(L13:AK13) -> 0 | AL13: =SUM(L13:AK13) -> 0 | AM13: =IF(AL13=I13,"OK","NG") -> OK
A14: 1510-00 | B14: 10254 | C14: PULLEY LARGE | I14: =SUM(L14:AK14) -> 0 | AL14: =SUM(L14:AK14) -> 0 | AM14: =IF(AL14=I14,"OK","NG") -> OK
A15: 1510-01 | B15: 11856 | C15: PULLEY LARGE | I15: =SUM(L15:AK15) -> 0 | AL15: =SUM(L15:AK15) -> 0 | AM15: =IF(AL15=I15,"OK","NG") -> OK
A16: 1510-02 | B16: 15003 | C16: PULLEY LARGE | I16: =SUM(L16:AK16) -> 0 | AL16: =SUM(L16:AK16) -> 0 | AM16: =IF(AL16=I16,"OK","NG") -> OK
A17: 1695-00 | B17: 15173 | C17: MOTOR PULLEY | I17: =SUM(L17:AK17) -> 0 | AL17: =SUM(L17:AK17) -> 0 | AM17: =IF(AL17=I17,"OK","NG") -> OK
A18: 1781-00 | B18: 15519 | C18: PULLEY | H18: =2160+470+637 -> 3267 | I18: =SUM(L18:AK18) -> 0 | AL18: =SUM(L18:AK18) -> 0 | AM18: =IF(AL18=I18,"OK","NG") -> OK
A19: 1785-00 | B19: 14988 | C19: MOTOR PULLEY | H19: 2520 | I19: =SUM(L19:AK19) -> 0 | AL19: =SUM(L19:AK19) -> 0 | AM19: =IF(AL19=I19,"OK","NG") -> OK
A20: 1786-00 | B20: 14983 | C20: BALL NUT PULLEY | I20: =SUM(L20:AK20) -> 0 | AL20: =SUM(L20:AK20) -> 0 | AM20: =IF(AL20=I20,"OK","NG") -> OK
A21: 1883-00 | B21: 16269 | C21: SLIDE | I21: =SUM(L21:AK21) -> 0 | AL21: =SUM(L21:AK21) -> 0 | AM21: =IF(AL21=I21,"OK","NG") -> OK
A22: 1903-00 | B22: 19059 | C22: PULLEY | I22: =SUM(L22:AK22) -> 0 | AL22: =SUM(L22:AK22) -> 0 | AM22: =IF(AL22=I22,"OK","NG") -> OK
A23: 1935-00 | B23: 18827 | C23: Driven Pulley | I23: =SUM(L23:AK23) -> 0 | AL23: =SUM(L23:AK23) -> 0 | AM23: =IF(AL23=I23,"OK","NG") -> OK
A24: 5001-00 | B24: 10163 | C24: PLATE 1-2-3-4 CLU BKG | H24: 1344 | I24: =SUM(L24:AK24) -> 0 | AL24: =SUM(L24:AK24) -> 0 | AM24: =IF(AL24=I24,"OK","NG") -> OK
A25: 5002-00 | B25: 10160 | C25: PLATE 4-5-6 CLU BKG | I25: =SUM(L25:AK25) -> 0 | AL25: =SUM(L25:AK25) -> 0 | AM25: =IF(AL25=I25,"OK","NG") -> OK
A26: 5003-00 | B26: 10158 | C26: PLATE 3-5-REV CLU BKG | I26: =SUM(L26:AK26) -> 0 | AL26: =SUM(L26:AK26) -> 0 | AM26: =IF(AL26=I26,"OK","NG") -> OK
A27: 5003-01 | B27: 10155 | C27: PLATE 3-5-REV CLU BKG | I27: =SUM(L27:AK27) -> 0 | AL27: =SUM(L27:AK27) -> 0 | AM27: =IF(AL27=I27,"OK","NG") -> OK
A28: 5004-00 | B28: 10153 | C28: PLATE LOW & REV CLU BKG | H28: 2184 | I28: =SUM(L28:AK28) -> 1 | AC28: 1 | AL28: =SUM(L28:AK28) -> 1 | AM28: =IF(AL28=I28,"OK","NG") -> OK
A29: 5005-00 | B29: 10151 | C29: WHEEL-A/TRANS INPUT SHF SPD SEN RELUCTOR | H29: 1320 | I29: =SUM(L29:AK29) -> 1 | L29: 1 | AL29: =SUM(L29:AK29) -> 1 | AM29: =IF(AL29=I29,"OK","NG") -> OK
A30: 5006-00 | B30: 10149 | C30: PLATE 1-2-3-4 CLU BKG | H30: =648+684 -> 1332 | I30: =SUM(L30:AK30) -> 3 | L30: 2 | AI30: 1 | AL30: =SUM(L30:AK30) -> 3 | AM30: =IF(AL30=I30,"OK","NG") -> OK
A31: 5007-00 | B31: 10146 | C31: PLATE 4-5-6 CLU BKG | I31: =SUM(L31:AK31) -> 0 | AL31: =SUM(L31:AK31) -> 0 | AM31: =IF(AL31=I31,"OK","NG") -> OK
A32: 5008-00 | B32: 10143 | C32: PLATE 3-5-REV CLU BKG | I32: =SUM(L32:AK32) -> 0 | AL32: =SUM(L32:AK32) -> 0 | AM32: =IF(AL32=I32,"OK","NG") -> OK
A33: 5009-00 | B33: 10141 | C33: PLATE LOW & REV CLU BKG | H33: 1296 | I33: =SUM(L33:AK33) -> 4 | L33: 2 | P33: 1 | Y33: 1 | AL33: =SUM(L33:AK33) -> 4 | AM33: =IF(AL33=I33,"OK","NG") -> OK
A34: 5010-00 | B34: 10139 | C34: WHEEL-A/TRANS INPUT SHF SPD | H34: 1320 | I34: =SUM(L34:AK34) -> 2 | L34: 1 | AC34: 1 | AL34: =SUM(L34:AK34) -> 2 | AM34: =IF(AL34=I34,"OK","NG") -> OK
A35: 5011-00 | B35: 10137 | C35: CARRIER-REACTION | I35: =SUM(L35:AK35) -> 0 | AL35: =SUM(L35:AK35) -> 0 | AM35: =IF(AL35=I35,"OK","NG") -> OK
A36: 5012-00 | B36: 10135 | C36: CARRIER-INPUT | I36: =SUM(L36:AK36) -> 0 | AL36: =SUM(L36:AK36) -> 0 | AM36: =IF(AL36=I36,"OK","NG") -> OK
A37: 5013-00 | B37: 10133 | C37: CARRIER-REACTION | H37: =850+554+550 -> 1954 | I37: =SUM(L37:AK37) -> 1 | AC37: 1 | AL37: =SUM(L37:AK37) -> 1 | AM37: =IF(AL37=I37,"OK","NG") -> OK
A38: 5014-00 | B38: 10131 | C38: CARRIER-INPUT | H38: 1350 | I38: =SUM(L38:AK38) -> 0 | AL38: =SUM(L38:AK38) -> 0 | AM38: =IF(AL38=I38,"OK","NG") -> OK
A39: 5015-00 | B39: 10129 | C39: CARRIER - REACTION | H39: 100 | I39: =SUM(L39:AK39) -> 0 | AL39: =SUM(L39:AK39) -> 0 | AM39: =IF(AL39=I39,"OK","NG") -> OK
A40: 5016-00 | B40: 10127 | C40: CARRIER - INPUT | H40: 250 | I40: =SUM(L40:AK40) -> 0 | AL40: =SUM(L40:AK40) -> 0 | AM40: =IF(AL40=I40,"OK","NG") -> OK
...

Sheet 9
A1: 생산수량 | B1: =H97 -> 38644 | E1: 불량금액 | F1: =G97 -> 0
A2: 불량수량 | B2: =I97 -> 21 | M2: =SUBTOTAL(9,M6:M96) -> 3 | N2: =SUBTOTAL(9,N6:N96) -> 0 | O2: =SUBTOTAL(9,O6:O96) -> 0 | P2: =SUBTOTAL(9,P6:P96) -> 0 | Q2: =SUBTOTAL(9,Q6:Q96) -> 0 | R2: =SUBTOTAL(9,R6:R96) -> 0 | S2: =SUBTOTAL(9,S6:S96) -> 0 | T2: =SUBTOTAL(9,T6:T96) -> 0 | ... AL2: =SUBTOTAL(9,AL6:AL96) -> 21
A3: 불량율(ppm) | B3: =IF(ISERROR(B2/(B2+B1)*1000000),"",(B2/(B2+B1)*1000000)) -> 543.12686 | L3: =SUM(L6:L96) -> 10 | M3: =SUM(M6:M96) -> 3 | N3: =SUM(N6:N96) -> 0 | O3: =SUM(O6:O96) -> 0 | P3: =SUM(P6:P96) -> 0 | Q3: =SUM(Q6:Q96) -> 0 | R3: =SUM(R6:R96) -> 0 | S3: =SUM(S6:S96) -> 0 | ... AL3: =SUM(AL6:AL96) -> 21
A4: =AM97 -> OK | E4: 거래선 및 불량금액 | H4: 종합 | L4: 깨짐 | M4: 찍힘 | N4: CRACK | O4: 스크래치 | P4: 녹불량 | Q4: 초기가동 | R4: 편차수정 | S4: 중량불량 | T4: 설비Error | U4: Pellet누락 | V4: 낙물 | W4: 산화 | X4: 휨 | Y4: 눌림 | Z4: 분말소착 | AA4: 역싸이징 | AB4: 이물질소착 | AC4: 기포 | AD4: 윈도우 GO | AE4: 윈도우 NO | AF4: 조립불량 | AG4: 침투불량 | AH4: 치형뜯김 | AI4: 기타 | AJ4: 폐기 | AK4: 소재불량 | AL4: 합계 | AM4: 오기 유/무
A5: TM NO. | B5: CODE (ERP) | C5: 품 명 | D5: 차종 | E5: 거래선 | F5: 단가 | G5: 불량금액 (단가x수량) | H5: 생산수량 | I5: 불량수량 | J5: 불량율 (PPM)
A6: 1360-00 | B6: 10901 | C6: MOTOR PULLEY | H6: 2520 | I6: =SUM(L6:AK6) -> 2 | M6: 2 | AL6: =SUM(L6:AK6) -> 2 | AM6: =IF(AL6=I6,"OK","NG") -> OK
A7: 1360-01 | B7: 15922 | C7: MOTOR PULLEY | I7: =SUM(L7:AK7) -> 0 | AL7: =SUM(L7:AK7) -> 0 | AM7: =IF(AL7=I7,"OK","NG") -> OK
A8: 1361-00 | B8: 10899 | C8: BALL NUT PULLEY | I8: =SUM(L8:AK8) -> 0 | AL8: =SUM(L8:AK8) -> 0 | AM8: =IF(AL8=I8,"OK","NG") -> OK
A9: 1361-01 | B9: 10897 | C9: BALL NUT PULLEY | I9: =SUM(L9:AK9) -> 0 | AL9: =SUM(L9:AK9) -> 0 | AM9: =IF(AL9=I9,"OK","NG") -> OK
A10: 1361-02 | B10: 18523 | C10: BALL NUT PULLEY | I10: =SUM(L10:AK10) -> 0 | AL10: =SUM(L10:AK10) -> 0 | AM10: =IF(AL10=I10,"OK","NG") -> OK
A11: 1361-50 | B11: 19445 | C11: BELT GUIDE | I11: =SUM(L11:AK11) -> 0 | AL11: =SUM(L11:AK11) -> 0 | AM11: =IF(AL11=I11,"OK","NG") -> OK
A12: 1464-00 | B12: 10315 | C12: PULLEY | I12: =SUM(L12:AK12) -> 0 | AL12: =SUM(L12:AK12) -> 0 | AM12: =IF(AL12=I12,"OK","NG") -> OK
A13: 1464-01 | B13: 14961 | C13: PULLEY | I13: =SUM(L13:AK13) -> 0 | AL13: =SUM(L13:AK13) -> 0 | AM13: =IF(AL13=I13,"OK","NG") -> OK
A14: 1510-00 | B14: 10254 | C14: PULLEY LARGE | I14: =SUM(L14:AK14) -> 0 | AL14: =SUM(L14:AK14) -> 0 | AM14: =IF(AL14=I14,"OK","NG") -> OK
A15: 1510-01 | B15: 11856 | C15: PULLEY LARGE | I15: =SUM(L15:AK15) -> 0 | AL15: =SUM(L15:AK15) -> 0 | AM15: =IF(AL15=I15,"OK","NG") -> OK
A16: 1510-02 | B16: 15003 | C16: PULLEY LARGE | I16: =SUM(L16:AK16) -> 0 | AL16: =SUM(L16:AK16) -> 0 | AM16: =IF(AL16=I16,"OK","NG") -> OK
A17: 1695-00 | B17: 15173 | C17: MOTOR PULLEY | I17: =SUM(L17:AK17) -> 0 | AL17: =SUM(L17:AK17) -> 0 | AM17: =IF(AL17=I17,"OK","NG") -> OK
A18: 1781-00 | B18: 15519 | C18: PULLEY | I18: =SUM(L18:AK18) -> 0 | AL18: =SUM(L18:AK18) -> 0 | AM18: =IF(AL18=I18,"OK","NG") -> OK
A19: 1785-00 | B19: 14988 | C19: MOTOR PULLEY | H19: =1920+720+4440+3840 -> 10920 | I19: =SUM(L19:AK19) -> 0 | AL19: =SUM(L19:AK19) -> 0 | AM19: =IF(AL19=I19,"OK","NG") -> OK
A20: 1786-00 | B20: 14983 | C20: BALL NUT PULLEY | I20: =SUM(L20:AK20) -> 0 | AL20: =SUM(L20:AK20) -> 0 | AM20: =IF(AL20=I20,"OK","NG") -> OK
A21: 1883-00 | B21: 16269 | C21: SLIDE | I21: =SUM(L21:AK21) -> 0 | AL21: =SUM(L21:AK21) -> 0 | AM21: =IF(AL21=I21,"OK","NG") -> OK
A22: 1903-00 | B22: 19059 | C22: PULLEY | I22: =SUM(L22:AK22) -> 0 | AL22: =SUM(L22:AK22) -> 0 | AM22: =IF(AL22=I22,"OK","NG") -> OK
A23: 1935-00 | B23: 18827 | C23: Driven Pulley | I23: =SUM(L23:AK23) -> 0 | AL23: =SUM(L23:AK23) -> 0 | AM23: =IF(AL23=I23,"OK","NG") -> OK
A24: 5001-00 | B24: 10163 | C24: PLATE 1-2-3-4 CLU BKG | H24: 1344 | I24: =SUM(L24:AK24) -> 0 | AL24: =SUM(L24:AK24) -> 0 | AM24: =IF(AL24=I24,"OK","NG") -> OK
A25: 5002-00 | B25: 10160 | C25: PLATE 4-5-6 CLU BKG | I25: =SUM(L25:AK25) -> 0 | AL25: =SUM(L25:AK25) -> 0 | AM25: =IF(AL25=I25,"OK","NG") -> OK
A26: 5003-00 | B26: 10158 | C26: PLATE 3-5-REV CLU BKG | I26: =SUM(L26:AK26) -> 0 | AL26: =SUM(L26:AK26) -> 0 | AM26: =IF(AL26=I26,"OK","NG") -> OK
A27: 5003-01 | B27: 10155 | C27: PLATE 3-5-REV CLU BKG | I27: =SUM(L27:AK27) -> 0 | AL27: =SUM(L27:AK27) -> 0 | AM27: =IF(AL27=I27,"OK","NG") -> OK
A28: 5004-00 | B28: 10153 | C28: PLATE LOW & REV CLU BKG | H28: =624+208 -> 832 | I28: =SUM(L28:AK28) -> 1 | Y28: 1 | AL28: =SUM(L28:AK28) -> 1 | AM28: =IF(AL28=I28,"OK","NG") -> OK
A29: 5005-00 | B29: 10151 | C29: WHEEL-A/TRANS INPUT SHF SPD SEN RELUCTOR | H29: 1320 | I29: =SUM(L29:AK29) -> 3 | L29: 2 | AC29: 1 | AL29: =SUM(L29:AK29) -> 3 | AM29: =IF(AL29=I29,"OK","NG") -> OK
A30: 5006-00 | B30: 10149 | C30: PLATE 1-2-3-4 CLU BKG | H30: 1368 | I30: =SUM(L30:AK30) -> 0 | AL30: =SUM(L30:AK30) -> 0 | AM30: =IF(AL30=I30,"OK","NG") -> OK
A31: 5007-00 | B31: 10146 | C31: PLATE 4-5-6 CLU BKG | I31: =SUM(L31:AK31) -> 0 | AL31: =SUM(L31:AK31) -> 0 | AM31: =IF(AL31=I31,"OK","NG") -> OK
A32: 5008-00 | B32: 10143 | C32: PLATE 3-5-REV CLU BKG | I32: =SUM(L32:AK32) -> 0 | AL32: =SUM(L32:AK32) -> 0 | AM32: =IF(AL32=I32,"OK","NG") -> OK
A33: 5009-00 | B33: 10141 | C33: PLATE LOW & REV CLU BKG | H33: =1300+648+1770 -> 3718 | I33: =SUM(L33:AK33) -> 1 | M33: 1 | AL33: =SUM(L33:AK33) -> 1 | AM33: =IF(AL33=I33,"OK","NG") -> OK
A34: 5010-00 | B34: 10139 | C34: WHEEL-A/TRANS INPUT SHF SPD | H34: 1100 | I34: =SUM(L34:AK34) -> 12 | L34: 7 | AC34: 5 | AL34: =SUM(L34:AK34) -> 12 | AM34: =IF(AL34=I34,"OK","NG") -> OK
A35: 5011-00 | B35: 10137 | C35: CARRIER-REACTION | I35: =SUM(L35:AK35) -> 0 | AL35: =SUM(L35:AK35) -> 0 | AM35: =IF(AL35=I35,"OK","NG") -> OK
A36: 5012-00 | B36: 10135 | C36: CARRIER-INPUT | I36: =SUM(L36:AK36) -> 0 | AL36: =SUM(L36:AK36) -> 0 | AM36: =IF(AL36=I36,"OK","NG") -> OK
A37: 5013-00 | B37: 10133 | C37: CARRIER-REACTION | I37: =SUM(L37:AK37) -> 0 | AL37: =SUM(L37:AK37) -> 0 | AM37: =IF(AL37=I37,"OK","NG") -> OK
A38: 5014-00 | B38: 10131 | C38: CARRIER-INPUT | I38: =SUM(L38:AK38) -> 0 | AL38: =SUM(L38:AK38) -> 0 | AM38: =IF(AL38=I38,"OK","NG") -> OK
A39: 5015-00 | B39: 10129 | C39: CARRIER - REACTION | H39: =1400+290+1150 -> 2840 | I39: =SUM(L39:AK39) -> 1 | L39: 1 | AL39: =SUM(L39:AK39) -> 1 | AM39: =IF(AL39=I39,"OK","NG") -> OK
A40: 5016-00 | B40: 10127 | C40: CARRIER - INPUT | I40: =SUM(L40:AK40) -> 0 | AL40: =SUM(L40:AK40) -> 0 | AM40: =IF(AL40=I40,"OK","NG") -> OK
...

Sheet 10
A1: 생산수량 | B1: =H97 -> 25203 | E1: 불량금액 | F1: =G97 -> 0
A2: 불량수량 | B2: =I97 -> 15 | L2: =SUBTOTAL(9,L6:L96) -> 9 | M2: =SUBTOTAL(9,M6:M96) -> 0 | N2: =SUBTOTAL(9,N6:N96) -> 0 | O2: =SUBTOTAL(9,O6:O96) -> 0 | P2: =SUBTOTAL(9,P6:P96) -> 0 | Q2: =SUBTOTAL(9,Q6:Q96) -> 0 | R2: =SUBTOTAL(9,R6:R96) -> 0 | S2: =SUBTOTAL(9,S6:S96) -> 0 | ... AL2: =SUBTOTAL(9,AL6:AL96) -> 15
A3: 불량율(ppm) | B3: =IF(ISERROR(B2/(B2+B1)*1000000),"",(B2/(B2+B1)*1000000)) -> 594.81323 | L3: =SUM(L6:L96) -> 9 | M3: =SUM(M6:M96) -> 0 | N3: =SUM(N6:N96) -> 0 | O3: =SUM(O6:O96) -> 0 | P3: =SUM(P6:P96) -> 0 | Q3: =SUM(Q6:Q96) -> 0 | R3: =SUM(R6:R96) -> 0 | S3: =SUM(S6:S96) -> 0 | ... AL3: =SUM(AL6:AL96) -> 15
A4: =AM97 -> OK | E4: 거래선 및 불량금액 | H4: 종합 | L4: 깨짐 | M4: 찍힘 | N4: CRACK | O4: 스크래치 | P4: 녹불량 | Q4: 초기가동 | R4: 편차수정 | S4: 중량불량 | T4: 설비Error | U4: Pellet누락 | V4: 낙물 | W4: 산화 | X4: 휨 | Y4: 눌림 | Z4: 분말소착 | AA4: 역싸이징 | AB4: 이물질소착 | AC4: 기포 | AD4: 윈도우 GO | AE4: 윈도우 NO | AF4: 조립불량 | AG4: 침투불량 | AH4: 치형뜯김 | AI4: 기타 | AJ4: 폐기 | AK4: 소재불량 | AL4: 합계 | AM4: 오기 유/무
A5: TM NO. | B5: CODE (ERP) | C5: 품 명 | D5: 차종 | E5: 거래선 | F5: 단가 | G5: 불량금액 (단가x수량) | H5: 생산수량 | I5: 불량수량 | J5: 불량율 (PPM)
A6: 1360-00 | B6: 10901 | C6: MOTOR PULLEY | H6: 2280 | I6: =SUM(L6:AK6) -> 0 | AL6: =SUM(L6:AK6) -> 0 | AM6: =IF(AL6=I6,"OK","NG") -> OK
A7: 1360-01 | B7: 15922 | C7: MOTOR PULLEY | I7: =SUM(L7:AK7) -> 0 | AL7: =SUM(L7:AK7) -> 0 | AM7: =IF(AL7=I7,"OK","NG") -> OK
A8: 1361-00 | B8: 10899 | C8: BALL NUT PULLEY | I8: =SUM(L8:AK8) -> 0 | AL8: =SUM(L8:AK8) -> 0 | AM8: =IF(AL8=I8,"OK","NG") -> OK
A9: 1361-01 | B9: 10897 | C9: BALL NUT PULLEY | I9: =SUM(L9:AK9) -> 0 | AL9: =SUM(L9:AK9) -> 0 | AM9: =IF(AL9=I9,"OK","NG") -> OK
A10: 1361-02 | B10: 18523 | C10: BALL NUT PULLEY | I10: =SUM(L10:AK10) -> 0 | AL10: =SUM(L10:AK10) -> 0 | AM10: =IF(AL10=I10,"OK","NG") -> OK
A11: 1361-50 | B11: 19445 | C11: BELT GUIDE | I11: =SUM(L11:AK11) -> 0 | AL11: =SUM(L11:AK11) -> 0 | AM11: =IF(AL11=I11,"OK","NG") -> OK
A12: 1464-00 | B12: 10315 | C12: PULLEY | I12: =SUM(L12:AK12) -> 0 | AL12: =SUM(L12:AK12) -> 0 | AM12: =IF(AL12=I12,"OK","NG") -> OK
A13: 1464-01 | B13: 14961 | C13: PULLEY | I13: =SUM(L13:AK13) -> 0 | AL13: =SUM(L13:AK13) -> 0 | AM13: =IF(AL13=I13,"OK","NG") -> OK
A14: 1510-00 | B14: 10254 | C14: PULLEY LARGE | I14: =SUM(L14:AK14) -> 0 | AL14: =SUM(L14:AK14) -> 0 | AM14: =IF(AL14=I14,"OK","NG") -> OK
A15: 1510-01 | B15: 11856 | C15: PULLEY LARGE | I15: =SUM(L15:AK15) -> 0 | AL15: =SUM(L15:AK15) -> 0 | AM15: =IF(AL15=I15,"OK","NG") -> OK
A16: 1510-02 | B16: 15003 | C16: PULLEY LARGE | I16: =SUM(L16:AK16) -> 0 | AL16: =SUM(L16:AK16) -> 0 | AM16: =IF(AL16=I16,"OK","NG") -> OK
A17: 1695-00 | B17: 15173 | C17: MOTOR PULLEY | I17: =SUM(L17:AK17) -> 0 | AL17: =SUM(L17:AK17) -> 0 | AM17: =IF(AL17=I17,"OK","NG") -> OK
A18: 1781-00 | B18: 15519 | C18: PULLEY | I18: =SUM(L18:AK18) -> 0 | AL18: =SUM(L18:AK18) -> 0 | AM18: =IF(AL18=I18,"OK","NG") -> OK
... A21: 1883-00 | B21: 16269 | C21: SLIDE | I21: =SUM(L21:AK21) -> 0 | AL21: =SUM(L21:AK21) -> 0 | AM21: =IF(AL21=I21,"OK","NG") -> OK
A22: 1903-00 | B22: 19059 | C22: PULLEY | H22: 3750 | I22: =SUM(L22:AK22) -> 0 | AL22: =SUM(L22:AK22) -> 0 | AM22: =IF(AL22=I22,"OK","NG") -> OK
A23: 1935-00 | B23: 18827 | C23: Driven Pulley | I23: =SUM(L23:AK23) -> 0 | AL23: =SUM(L23:AK23) -> 0 | AM23: =IF(AL23=I23,"OK","NG") -> OK
A24: 5001-00 | B24: 10163 | C24: PLATE 1-2-3-4 CLU BKG | H24: =672+672 -> 1344 | I24: =SUM(L24:AK24) -> 0 | AL24: =SUM(L24:AK24) -> 0 | AM24: =IF(AL24=I24,"OK","NG") -> OK
A25: 5002-00 | B25: 10160 | C25: PLATE 4-5-6 CLU BKG | I25: =SUM(L25:AK25) -> 0 | AL25: =SUM(L25:AK25) -> 0 | AM25: =IF(AL25=I25,"OK","NG") -> OK
A26: 5003-00 | B26: 10158 | C26: PLATE 3-5-REV CLU BKG | I26: =SUM(L26:AK26) -> 0 | AL26: =SUM(L26:AK26) -> 0 | AM26: =IF(AL26=I26,"OK","NG") -> OK
A27: 5003-01 | B27: 10155 | C27: PLATE 3-5-REV CLU BKG | I27: =SUM(L27:AK27) -> 0 | AL27: =SUM(L27:AK27) -> 0 | AM27: =IF(AL27=I27,"OK","NG") -> OK
A28: 5004-00 | B28: 10153 | C28: PLATE LOW & REV CLU BKG | H28: 2184 | I28: =SUM(L28:AK28) -> 0 | AL28: =SUM(L28:AK28) -> 0 | AM28: =IF(AL28=I28,"OK","NG") -> OK
A29: 5005-00 | B29: 10151 | C29: WHEEL-A/TRANS INPUT SHF SPD SEN RELUCTOR | H29: =660+1320 -> 1980 | I29: =SUM(L29:AK29) -> 0 | AL29: =SUM(L29:AK29) -> 0 | AM29: =IF(AL29=I29,"OK","NG") -> OK
A30: 5006-00 | B30: 10149 | C30: PLATE 1-2-3-4 CLU BKG | H30: 1368 | I30: =SUM(L30:AK30) -> 0 | AL30: =SUM(L30:AK30) -> 0 | AM30: =IF(AL30=I30,"OK","NG") -> OK
