Workbook

Sheet 1
A1: 생산수량 | B1: =H81 -> 0 | E1: 불량금액 | F1: =G69 -> 0
A2: 불량수량 | B2: =I81 -> 8 | L2: =SUBTOTAL(9,L6:L80) -> 0 | M2: =SUBTOTAL(9,M6:M80) -> 8 | N2: =SUBTOTAL(9,N6:N80) -> 0 | O2: =SUBTOTAL(9,O6:O80) -> 0 | P2: =SUBTOTAL(9,P6:P80) -> 0 | Q2: =SUBTOTAL(9,Q6:Q80) -> 0 | R2: =SUBTOTAL(9,R6:R80) -> 0 | S2: =SUBTOTAL(9,S6:S80) -> 0 | ... U2: =SUBTOTAL(9,U6:U80) -> 8
A3: 불량율(ppm) | B3: =IF(ISERROR(B2/(B2+B1)*1000000),"",(B2/(B2+B1)*1000000)) -> 1000000 | L3: =SUM(L6:L80) -> 0 | M3: =SUM(M6:M80) -> 8 | N3: =SUM(N6:N80) -> 0 | O3: =SUM(O6:O80) -> 0 | P3: =SUM(P6:P80) -> 0 | Q3: =SUM(Q6:Q80) -> 0 | R3: =SUM(R6:R80) -> 0 | S3: =SUM(S6:S80) -> 0 | ... U3: =SUM(U6:U80) -> 8
A4: =V81 -> OK | E4: 거래선 및 불량금액 | H4: 종합 | L4: 형상 | M4: 시험성형 | N4: 밀도수정 | O4: CRACK 수정 | P4: 발란스 | Q4: 자동화 셋팅 | R4: 셋팅 | S4: 기타 | T4: 폐기 | U4: 합계 | V4: 오기 유/무
A5: TM NO. | B5: CODE - 성형 (ERP) | C5: 품 명 | D5: 차종 | E5: 거래선 | F5: 단가 | G5: 불량금액 (단가x수량) | H5: 생산수량 | I5: 불량수량 | J5: 불량율 (PPM)
A6: 1360-00 | B6: 8092 | C6: 성형-MOTOR PULLEY | I6: =SUM(L6:T6) -> 0 | U6: =SUM(L6:T6) -> 0 | V6: =IF(U6=I6,"OK","NG") -> OK
A7: 1361-00J | B7: 8088 | C7: 성형-BALL NUT PULLEY | I7: =SUM(L7:T7) -> 0 | U7: =SUM(L7:T7) -> 0 | V7: =IF(U7=I7,"OK","NG") -> OK
A8: 1361-01J | B8: 8081 | C8: 성형-BALL NUT PULLEY | I8: =SUM(L8:T8) -> 3 | M8: 3 | U8: =SUM(L8:T8) -> 3 | V8: =IF(U8=I8,"OK","NG") -> OK
A9: 1361-02J | B9: 18524 | C9: 성형-BALL NUT PULLEY | I9: =SUM(L9:T9) -> 0 | U9: =SUM(L9:T9) -> 0 | V9: =IF(U9=I9,"OK","NG") -> OK
A10: 1464-00 | B10: 6234 | C10: 성형-PULLEY | I10: =SUM(L10:T10) -> 0 | U10: =SUM(L10:T10) -> 0 | V10: =IF(U10=I10,"OK","NG") -> OK
A11: 1464-01 | B11: 14830 | C11: 성형-PULLEY | I11: =SUM(L11:T11) -> 0 | U11: =SUM(L11:T11) -> 0 | V11: =IF(U11=I11,"OK","NG") -> OK
A12: 1510-00 | B12: 6004 | C12: 성형-PULLEY LARGE | I12: =SUM(L12:T12) -> 0 | U12: =SUM(L12:T12) -> 0 | V12: =IF(U12=I12,"OK","NG") -> OK
A13: 1510-01 | B13: 11857 | C13: 성형-PULLEY LARGE | I13: =SUM(L13:T13) -> 0 | U13: =SUM(L13:T13) -> 0 | V13: =IF(U13=I13,"OK","NG") -> OK
A14: 1510-02 | B14: 15004 | C14: 성형-PULLEY LARGE | I14: =SUM(L14:T14) -> 0 | U14: =SUM(L14:T14) -> 0 | V14: =IF(U14=I14,"OK","NG") -> OK
A15: 1695-00 | B15: 15174 | C15: 성형-MOTOR PULLEY | I15: =SUM(L15:T15) -> 0 | U15: =SUM(L15:T15) -> 0 | V15: =IF(U15=I15,"OK","NG") -> OK
A16: 1781-00 | B16: 15520 | C16: 성형-PULLEY | I16: =SUM(L16:T16) -> 0 | U16: =SUM(L16:T16) -> 0 | V16: =IF(U16=I16,"OK","NG") -> OK
A17: 1785-00 | B17: 14989 | C17: 성형-MOTOR PULLEY | I17: =SUM(L17:T17) -> 0 | U17: =SUM(L17:T17) -> 0 | V17: =IF(U17=I17,"OK","NG") -> OK
A18: 1786-00 | B18: 14984 | C18: 성형-BALL NUT PULLEY | I18: =SUM(L18:T18) -> 0 | U18: =SUM(L18:T18) -> 0 | V18: =IF(U18=I18,"OK","NG") -> OK
A19: 1883-00 | B19: 16270 | C19: 성형-SLIDE | I19: =SUM(L19:T19) -> 0 | U19: =SUM(L19:T19) -> 0 | V19: =IF(U19=I19,"OK","NG") -> OK
A20: 1903-00 | B20: 19060 | C20: 성형-PULLEY | I20: =SUM(L20:T20) -> 0 | U20: =SUM(L20:T20) -> 0 | V20: =IF(U20=I20,"OK","NG") -> OK
... A50: 6002-20 | B50: 11352 | C50: 성형-CARRIER PLANET | I50: =SUM(L50:T50) -> 0 | U50: =SUM(L50:T50) -> 0 | V50: =IF(U50=I50,"OK","NG") -> OK
A51: 6004-10 | B51: 13515 | C51: 성형-CARRIER PLANET MID | I51: =SUM(L51:T51) -> 5 | M51: 5 | U51: =SUM(L51:T51) -> 5 | V51: =IF(U51=I51,"OK","NG") -> OK
A52: 6004-20 | B52: 13516 | C52: 성형-CARRIER PLANET MID | I52: =SUM(L52:T52) -> 0 | U52: =SUM(L52:T52) -> 0 | V52: =IF(U52=I52,"OK","NG") -> OK
A53: 6007-10 | B53: 13468 | C53: 성형-CARRIER PLANET MID | I53: =SUM(L53:T53) -> 0 | U53: =SUM(L53:T53) -> 0 | V53: =IF(U53=I53,"OK","NG") -> OK
A54: 6007-20 | B54: 13469 | C54: 성형-CARRIER PLANET MID | I54: =SUM(L54:T54) -> 0 | U54: =SUM(L54:T54) -> 0 | V54: =IF(U54=I54,"OK","NG") -> OK
A55: 6009-00 | B55: 11820 | C55: 성형-PRESSURE PLATE | I55: =SUM(L55:T55) -> 0 | U55: =SUM(L55:T55) -> 0 | V55: =IF(U55=I55,"OK","NG") -> OK
A56: 6009-01 | B56: 11816 | C56: 성형-PRESSURE PLATE | I56: =SUM(L56:T56) -> 0 | U56: =SUM(L56:T56) -> 0 | V56: =IF(U56=I56,"OK","NG") -> OK
A57: 6011-10 | B57: 11381 | C57: 성형-CARRIER PALNET | I57: =SUM(L57:T57) -> 0 | U57: =SUM(L57:T57) -> 0 | V57: =IF(U57=I57,"OK","NG") -> OK
A58: 6011-20 | B58: 11382 | C58: 성형-CARRIER PALNET | I58: =SUM(L58:T58) -> 0 | U58: =SUM(L58:T58) -> 0 | V58: =IF(U58=I58,"OK","NG") -> OK
A59: 6017-10 | B59: 16586 | C59: 성형-CARRIER PLANET MID | I59: =SUM(L59:T59) -> 0 | U59: =SUM(L59:T59) -> 0 | V59: =IF(U59=I59,"OK","NG") -> OK
A60: 6017-20 | B60: 16587 | C60: 성형-CARRIER PLANET MID | I60: =SUM(L60:T60) -> 0 | U60: =SUM(L60:T60) -> 0 | V60: =IF(U60=I60,"OK","NG") -> OK
A61: 6019-00 | B61: 17121 | C61: 성형-HOUSING GUIDE RING | I61: =SUM(L61:T61) -> 0 | U61: =SUM(L61:T61) -> 0 | V61: =IF(U61=I61,"OK","NG") -> OK
A62: 6020-10 | B62: 19270 | C62: 성형-CARRIER PALNET | I62: =SUM(L62:T62) -> 0 | U62: =SUM(L62:T62) -> 0 | V62: =IF(U62=I62,"OK","NG") -> OK
A63: 6020-20 | B63: 19276 | C63: 성형-CARRIER PALNET | I63: =SUM(L63:T63) -> 0 | U63: =SUM(L63:T63) -> 0 | V63: =IF(U63=I63,"OK","NG") -> OK
... A74: 1948-00 | B74: 19279 | C74: 성형-Flange | I74: =SUM(L74:T74) -> 0 | U74: =SUM(L74:T74) -> 0 | V74: =IF(U74=I74,"OK","NG") -> OK
A75: 6026-10 | B75: 22724 | C75: 성형-SUB ASSY-CARRIER PLANET, MID&RR | I75: =SUM(L75:T75) -> 0 | U75: =SUM(L75:T75) -> 0 | V75: OK
A76: 6027-20 | B76: 22705 | C76: 성형-SUB ASSY-CARRIER PLANET, MID&RR | I76: =SUM(L76:T76) -> 0 | U76: =SUM(L76:T76) -> 0 | V76: =IF(U76=I76,"OK","NG") -> OK
A77: 5010-00 | B77: 5655 | C77: 성형-WHEEL-A/TRANS INPUT SHF SPD | I77: =SUM(L77:T77) -> 0 | U77: =SUM(L77:T77) -> 0 | V77: =IF(U77=I77,"OK","NG") -> OK
A78: 6027-30 | B78: 22704 | C78: 성형-SUB ASSY-CARRIER PLANET, MID&RR | I78: =SUM(L78:T78) -> 0 | U78: =SUM(L78:T78) -> 0 | V78: =IF(U78=I78,"OK","NG") -> OK
A79: 6026-30 | B79: 22722 | C79: 성형-SUB ASSY-CARRIER PLANET, MID&RR | I79: =SUM(L79:T79) -> 0 | U79: =SUM(L79:T79) -> 0
...

Sheet 2
A1: 생산수량 | B1: =H69 -> 0 | E1: 불량금액 | F1: =G69 -> 0
A2: 불량수량 | B2: =I81 -> 30 | L2: =SUBTOTAL(9,L6:L80) -> 0 | M2: =SUBTOTAL(9,M6:M80) -> 30 | N2: =SUBTOTAL(9,N6:N80) -> 0 | O2: =SUBTOTAL(9,O6:O80) -> 0 | P2: =SUBTOTAL(9,P6:P80) -> 0 | Q2: =SUBTOTAL(9,Q6:Q80) -> 0 | R2: =SUBTOTAL(9,R6:R80) -> 0 | S2: =SUBTOTAL(9,S6:S80) -> 0 | ... U2: =SUBTOTAL(9,U6:U80) -> 30
A3: 불량율(ppm) | B3: =IF(ISERROR(B2/(B2+B1)*1000000),"",(B2/(B2+B1)*1000000)) -> 1000000 | L3: =SUM(L6:L80) -> 0 | M3: =SUM(M6:M80) -> 30 | N3: =SUM(N6:N80) -> 0 | O3: =SUM(O6:O80) -> 0 | P3: =SUM(P6:P80) -> 0 | Q3: =SUM(Q6:Q80) -> 0 | R3: =SUM(R6:R80) -> 0 | S3: =SUM(S6:S80) -> 0 | ... U3: =SUM(U6:U80) -> 30
A4: =V81 -> OK | E4: 거래선 및 불량금액 | H4: 종합 | L4: 형상 | M4: 시험성형 | N4: 밀도수정 | O4: CRACK 수정 | P4: 발란스 | Q4: 자동화 셋팅 | R4: 셋팅 | S4: 기타 | T4: 폐기 | U4: 합계 | V4: 오기 유/무
A5: TM NO. | B5: CODE - 성형 (ERP) | C5: 품 명 | D5: 차종 | E5: 거래선 | F5: 단가 | G5: 불량금액 (단가x수량) | H5: 생산수량 | I5: 불량수량 | J5: 불량율 (PPM)
A6: 1360-00 | B6: 8092 | C6: 성형-MOTOR PULLEY | I6: =SUM(L6:T6) -> 0 | U6: =SUM(L6:T6) -> 0 | V6: =IF(U6=I6,"OK","NG") -> OK
A7: 1361-00J | B7: 8088 | C7: 성형-BALL NUT PULLEY | I7: =SUM(L7:T7) -> 0 | U7: =SUM(L7:T7) -> 0 | V7: =IF(U7=I7,"OK","NG") -> OK
A8: 1361-01J | B8: 8081 | C8: 성형-BALL NUT PULLEY | I8: =SUM(L8:T8) -> 0 | U8: =SUM(L8:T8) -> 0 | V8: =IF(U8=I8,"OK","NG") -> OK
A9: 1361-02J | B9: 18524 | C9: 성형-BALL NUT PULLEY | I9: =SUM(L9:T9) -> 0 | U9: =SUM(L9:T9) -> 0 | V9: =IF(U9=I9,"OK","NG") -> OK
A10: 1464-00 | B10: 6234 | C10: 성형-PULLEY | I10: =SUM(L10:T10) -> 0 | U10: =SUM(L10:T10) -> 0 | V10: =IF(U10=I10,"OK","NG") -> OK
A11: 1464-01 | B11: 14830 | C11: 성형-PULLEY | I11: =SUM(L11:T11) -> 0 | U11: =SUM(L11:T11) -> 0 | V11: =IF(U11=I11,"OK","NG") -> OK
A12: 1510-00 | B12: 6004 | C12: 성형-PULLEY LARGE | I12: =SUM(L12:T12) -> 0 | U12: =SUM(L12:T12) -> 0 | V12: =IF(U12=I12,"OK","NG") -> OK
A13: 1510-01 | B13: 11857 | C13: 성형-PULLEY LARGE | I13: =SUM(L13:T13) -> 0 | U13: =SUM(L13:T13) -> 0 | V13: =IF(U13=I13,"OK","NG") -> OK
A14: 1510-02 | B14: 15004 | C14: 성형-PULLEY LARGE | I14: =SUM(L14:T14) -> 0 | U14: =SUM(L14:T14) -> 0 | V14: =IF(U14=I14,"OK","NG") -> OK
A15: 1695-00 | B15: 15174 | C15: 성형-MOTOR PULLEY | I15: =SUM(L15:T15) -> 0 | U15: =SUM(L15:T15) -> 0 | V15: =IF(U15=I15,"OK","NG") -> OK
A16: 1781-00 | B16: 15520 | C16: 성형-PULLEY | I16: =SUM(L16:T16) -> 0 | U16: =SUM(L16:T16) -> 0 | V16: =IF(U16=I16,"OK","NG") -> OK
A17: 1785-00 | B17: 14989 | C17: 성형-MOTOR PULLEY | I17: =SUM(L17:T17) -> 5 | M17: 5 | U17: =SUM(L17:T17) -> 5 | V17: =IF(U17=I17,"OK","NG") -> OK
A18: 1786-00 | B18: 14984 | C18: 성형-BALL NUT PULLEY | I18: =SUM(L18:T18) -> 0 | U18: =SUM(L18:T18) -> 0 | V18: =IF(U18=I18,"OK","NG") -> OK
A19: 1883-00 | B19: 16270 | C19: 성형-SLIDE | I19: =SUM(L19:T19) -> 0 | U19: =SUM(L19:T19) -> 0 | V19: =IF(U19=I19,"OK","NG") -> OK
A20: 1903-00 | B20: 19060 | C20: 성형-PULLEY | I20: =SUM(L20:T20) -> 0 | U20: =SUM(L20:T20) -> 0 | V20: =IF(U20=I20,"OK","NG") -> OK
A21: 1935-00 | B21: 18828 | C21: 성형-Driven Pulley | I21: =SUM(L21:T21) -> 0 | U21: =SUM(L21:T21) -> 0 | V21: =IF(U21=I21,"OK","NG") -> OK
A22: 5001-00 | B22: 5695 | C22: 성형-PLATE 1-2-3-4 CLU BKG | I22: =SUM(L22:T22) -> 0 | U22: =SUM(L22:T22) -> 0 | V22: =IF(U22=I22,"OK","NG") -> OK
A23: 5002-00 | B23: 5691 | C23: 성형-PLATE 4-5-6 CLU BKG | I23: =SUM(L23:T23) -> 0 | U23: =SUM(L23:T23) -> 0 | V23: =IF(U23=I23,"OK","NG") -> OK
A24: 5003-00 | B24: 5687 | C24: 성형-PLATE 3-5-REV CLU BKG | I24: =SUM(L24:T24) -> 0 | U24: =SUM(L24:T24) -> 0 | V24: =IF(U24=I24,"OK","NG") -> OK
A25: 5003-01 | B25: 5683 | C25: 성형-PLATE 3-5-REV CLU BKG | I25: =SUM(L25:T25) -> 0 | U25: =SUM(L25:T25) -> 0 | V25: =IF(U25=I25,"OK","NG") -> OK
A26: 5004-00 | B26: 5679 | C26: 성형-PLATE LOW & REV CLU BKG | I26: =SUM(L26:T26) -> 0 | U26: =SUM(L26:T26) -> 0 | V26: =IF(U26=I26,"OK","NG") -> OK
A27: 5005-00 | B27: 5675 | C27: 성형-WHEEL-A/TRANS INPUT SHF SPD SEN RELUCTOR | I27: =SUM(L27:T27) -> 4 | M27: 4 | U27: =SUM(L27:T27) -> 4 | V27: =IF(U27=I27,"OK","NG") -> OK
A28: 5006-00 | B28: 5671 | C28: 성형-PLATE 1-2-3-4 CLU BKG | I28: =SUM(L28:T28) -> 0 | U28: =SUM(L28:T28) -> 0 | V28: =IF(U28=I28,"OK","NG") -> OK
A29: 5007-00 | B29: 5667 | C29: 성형-PLATE 4-5-6 CLU BKG | I29: =SUM(L29:T29) -> 0 | U29: =SUM(L29:T29) -> 0 | V29: =IF(U29=I29,"OK","NG") -> OK
A30: 5008-00 | B30: 5663 | C30: 성형-PLATE 3-5-REV CLU BKG | I30: =SUM(L30:T30) -> 0 | U30: =SUM(L30:T30) -> 0 | V30: =IF(U30=I30,"OK","NG") -> OK
A31: 5009-00 | B31: 5659 | C31: 성형-PLATE LOW & REV CLU BKG | I31: =SUM(L31:T31) -> 0 | U31: =SUM(L31:T31) -> 0 | V31: =IF(U31=I31,"OK","NG") -> OK
A32: 5010-00 | B32: 5655 | C32: 성형-WHEEL-A/TRANS INPUT SHF SPD | I32: =SUM(L32:T32) -> 0 | U32: =SUM(L32:T32) -> 0 | V32: =IF(U32=I32,"OK","NG") -> OK
A33: 5011-10 | B33: 5651 | C33: 성형-CARRIER-REACTION | I33: =SUM(L33:T33) -> 0 | U33: =SUM(L33:T33) -> 0 | V33: =IF(U33=I33,"OK","NG") -> OK
A34: 5012-10 | B34: 5643 | C34: 성형-CARRIER-INPUT | I34: =SUM(L34:T34) -> 0 | U34: =SUM(L34:T34) -> 0 | V34: =IF(U34=I34,"OK","NG") -> OK
A35: 5012-20 | B35: 11350 | C35: 성형-CARRIER-INPUT | I35: =SUM(L35:T35) -> 0 | U35: =SUM(L35:T35) -> 0 | V35: =IF(U35=I35,"OK","NG") -> OK
A36: 5013-10 | B36: 5635 | C36: 성형-CARRIER-REACTION | I36: =SUM(L36:T36) -> 0 | U36: =SUM(L36:T36) -> 0 | V36: =IF(U36=I36,"OK","NG") -> OK
A37: 5013-20 | B37: 11349 | C37: 성형-CARRIER-REACTION | I37: =SUM(L37:T37) -> 0 | U37: =SUM(L37:T37) -> 0 | V37: =IF(U37=I37,"OK","NG") -> OK
A38: 5014-10 | B38: 5627 | C38: 성형-CARRIER-INPUT | I38: =SUM(L38:T38) -> 0 | U38: =SUM(L38:T38) -> 0 | V38: =IF(U38=I38,"OK","NG") -> OK
A39: 5014-20 | B39: 11348 | C39: 성형-CARRIER-INPUT | I39: =SUM(L39:T39) -> 0 | U39: =SUM(L39:T39) -> 0 | V39: =IF(U39=I39,"OK","NG") -> OK
... A41: 5015-20 | B41: 11347 | C41: 성형-CARRIER - REACTION | I41: =SUM(L41:T41) -> 0 | U41: =SUM(L41:T41) -> 0 | V41: =IF(U41=I41,"OK","NG") -> OK
...

Sheet 3
A1: 생산수량 | B1: =H69 -> 0 | E1: 불량금액 | F1: =G69 -> 0
A2: 불량수량 | B2: =I81 -> 12 | L2: =SUBTOTAL(9,L6:L80) -> 0 | M2: =SUBTOTAL(9,M6:M80) -> 12 | N2: =SUBTOTAL(9,N6:N80) -> 0 | O2: =SUBTOTAL(9,O6:O80) -> 0 | P2: =SUBTOTAL(9,P6:P80) -> 0 | Q2: =SUBTOTAL(9,Q6:Q80) -> 0 | R2: =SUBTOTAL(9,R6:R80) -> 0 | S2: =SUBTOTAL(9,S6:S80) -> 0 | ... U2: =SUBTOTAL(9,U6:U80) -> 12
A3: 불량율(ppm) | B3: =IF(ISERROR(B2/(B2+B1)*1000000),"",(B2/(B2+B1)*1000000)) -> 1000000 | L3: =SUM(L6:L80) -> 0 | M3: =SUM(M6:M80) -> 12 | N3: =SUM(N6:N80) -> 0 | O3: =SUM(O6:O80) -> 0 | P3: =SUM(P6:P80) -> 0 | Q3: =SUM(Q6:Q80) -> 0 | R3: =SUM(R6:R80) -> 0 | S3: =SUM(S6:S80) -> 0 | ... U3: =SUM(U6:U80) -> 12
A4: =V81 -> OK | E4: 거래선 및 불량금액 | H4: 종합 | L4: 형상 | M4: 시험성형 | N4: 밀도수정 | O4: CRACK 수정 | P4: 발란스 | Q4: 자동화 셋팅 | R4: 셋팅 | S4: 기타 | T4: 폐기 | U4: 합계 | V4: 오기 유/무
A5: TM NO. | B5: CODE - 성형 (ERP) | C5: 품 명 | D5: 차종 | E5: 거래선 | F5: 단가 | G5: 불량금액 (단가x수량) | H5: 생산수량 | I5: 불량수량 | J5: 불량율 (PPM)
A6: 1360-00 | B6: 8092 | C6: 성형-MOTOR PULLEY | I6: =SUM(L6:T6) -> 0 | U6: =SUM(L6:T6) -> 0 | V6: =IF(U6=I6,"OK","NG") -> OK
A7: 1361-00J | B7: 8088 | C7: 성형-BALL NUT PULLEY | I7: =SUM(L7:T7) -> 0 | U7: =SUM(L7:T7) -> 0 | V7: =IF(U7=I7,"OK","NG") -> OK
A8: 1361-01J | B8: 8081 | C8: 성형-BALL NUT PULLEY | I8: =SUM(L8:T8) -> 2 | M8: 2 | U8: =SUM(L8:T8) -> 2 | V8: =IF(U8=I8,"OK","NG") -> OK
A9: 1361-02J | B9: 18524 | C9: 성형-BALL NUT PULLEY | I9: =SUM(L9:T9) -> 0 | U9: =SUM(L9:T9) -> 0 | V9: =IF(U9=I9,"OK","NG") -> OK
A10: 1464-00 | B10: 6234 | C10: 성형-PULLEY | I10: =SUM(L10:T10) -> 0 | U10: =SUM(L10:T10) -> 0 | V10: =IF(U10=I10,"OK","NG") -> OK
A11: 1464-01 | B11: 14830 | C11: 성형-PULLEY | I11: =SUM(L11:T11) -> 0 | U11: =SUM(L11:T11) -> 0 | V11: =IF(U11=I11,"OK","NG") -> OK
A12: 1510-00 | B12: 6004 | C12: 성형-PULLEY LARGE | I12: =SUM(L12:T12) -> 0 | U12: =SUM(L12:T12) -> 0 | V12: =IF(U12=I12,"OK","NG") -> OK
A13: 1510-01 | B13: 11857 | C13: 성형-PULLEY LARGE | I13: =SUM(L13:T13) -> 0 | U13: =SUM(L13:T13) -> 0 | V13: =IF(U13=I13,"OK","NG") -> OK
A14: 1510-02 | B14: 15004 | C14: 성형-PULLEY LARGE | I14: =SUM(L14:T14) -> 0 | U14: =SUM(L14:T14) -> 0 | V14: =IF(U14=I14,"OK","NG") -> OK
A15: 1695-00 | B15: 15174 | C15: 성형-MOTOR PULLEY | I15: =SUM(L15:T15) -> 0 | U15: =SUM(L15:T15) -> 0 | V15: =IF(U15=I15,"OK","NG") -> OK
A16: 1781-00 | B16: 15520 | C16: 성형-PULLEY | I16: =SUM(L16:T16) -> 0 | U16: =SUM(L16:T16) -> 0 | V16: =IF(U16=I16,"OK","NG") -> OK
A17: 1785-00 | B17: 14989 | C17: 성형-MOTOR PULLEY | I17: =SUM(L17:T17) -> 0 | U17: =SUM(L17:T17) -> 0 | V17: =IF(U17=I17,"OK","NG") -> OK
A18: 1786-00 | B18: 14984 | C18: 성형-BALL NUT PULLEY | I18: =SUM(L18:T18) -> 0 | U18: =SUM(L18:T18) -> 0 | V18: =IF(U18=I18,"OK","NG") -> OK
A19: 1883-00 | B19: 16270 | C19: 성형-SLIDE | I19: =SUM(L19:T19) -> 0 | U19: =SUM(L19:T19) -> 0 | V19: =IF(U19=I19,"OK","NG") -> OK
A20: 1903-00 | B20: 19060 | C20: 성형-PULLEY | I20: =SUM(L20:T20) -> 0 | U20: =SUM(L20:T20) -> 0 | V20: =IF(U20=I20,"OK","NG") -> OK
... A56: 6009-01 | B56: 11816 | C56: 성형-PRESSURE PLATE | I56: =SUM(L56:T56) -> 0 | U56: =SUM(L56:T56) -> 0 | V56: =IF(U56=I56,"OK","NG") -> OK
A57: 6011-10 | B57: 11381 | C57: 성형-CARRIER PALNET | I57: =SUM(L57:T57) -> 4 | M57: 4 | U57: =SUM(L57:T57) -> 4 | V57: =IF(U57=I57,"OK","NG") -> OK
A58: 6011-20 | B58: 11382 | C58: 성형-CARRIER PALNET | I58: =SUM(L58:T58) -> 6 | M58: 6 | U58: =SUM(L58:T58) -> 6 | V58: =IF(U58=I58,"OK","NG") -> OK
A59: 6017-10 | B59: 16586 | C59: 성형-CARRIER PLANET MID | I59: =SUM(L59:T59) -> 0 | U59: =SUM(L59:T59) -> 0 | V59: =IF(U59=I59,"OK","NG") -> OK
A60: 6017-20 | B60: 16587 | C60: 성형-CARRIER PLANET MID | I60: =SUM(L60:T60) -> 0 | U60: =SUM(L60:T60) -> 0 | V60: =IF(U60=I60,"OK","NG") -> OK
A61: 6019-00 | B61: 17121 | C61: 성형-HOUSING GUIDE RING | I61: =SUM(L61:T61) -> 0 | U61: =SUM(L61:T61) -> 0 | V61: =IF(U61=I61,"OK","NG") -> OK
A62: 6020-10 | B62: 19270 | C62: 성형-CARRIER PALNET | I62: =SUM(L62:T62) -> 0 | U62: =SUM(L62:T62) -> 0 | V62: =IF(U62=I62,"OK","NG") -> OK
A63: 6020-20 | B63: 19276 | C63: 성형-CARRIER PALNET | I63: =SUM(L63:T63) -> 0 | U63: =SUM(L63:T63) -> 0 | V63: =IF(U63=I63,"OK","NG") -> OK
A64: 1914-00 | B64: 19836 | C64: 성형-MOTOR PULLEY | I64: =SUM(L64:T64) -> 0 | U64: =SUM(L64:T64) -> 0 | V64: =IF(U64=I64,"OK","NG") -> OK
A65: 1987-00J | B65: 20278 | C65: 성형-BELT PULLEY | I65: =SUM(L65:T65) -> 0 | U65: =SUM(L65:T65) -> 0 | V65: =IF(U65=I65,"OK","NG") -> OK
A66: 1986-00 | B66: 20272 | C66: 성형-BELT PULLEY | I66: =SUM(L66:T66) -> 0 | U66: =SUM(L66:T66) -> 0 | V66: =IF(U66=I66,"OK","NG") -> OK
A67: 2059-00 | B67: 20956 | C67: 성형-BELT PULLEY | I67: =SUM(L67:T67) -> 0 | U67: =SUM(L67:T67) -> 0 | V67: =IF(U67=I67,"OK","NG") -> OK
A68: 6023-10 | B68: 21299 | C68: 성형-CARRIER PLANET MID | I68: =SUM(L68:T68) -> 0 | U68: =SUM(L68:T68) -> 0 | V68: =IF(U68=I68,"OK","NG") -> OK
A69: 2140-00 | B69: 22115 | C69: 성형-CAM PLATE | I69: =SUM(L69:T69) -> 0 | U69: =SUM(L69:T69) -> 0 | V69: =IF(U69=I69,"OK","NG") -> OK
A70: 6027-10 | B70: 22706 | C70: 성형-SUB ASSY-CARRIER PLANET, MID&RR | I70: =SUM(L70:T70) -> 0 | U70: =SUM(L70:T70) -> 0 | V70: =IF(U70=I70,"OK","NG") -> OK
... A74: 1948-00 | B74: 19279 | C74: 성형-Flange | I74: =SUM(L74:T74) -> 0 | U74: =SUM(L74:T74) -> 0 | V74: =IF(U74=I74,"OK","NG") -> OK
A75: 6026-10 | B75: 22724 | C75: 성형-SUB ASSY-CARRIER PLANET, MID&RR | I75: 0 | U75: 0 | V75: OK
A76: 6027-20 | B76: 22705 | C76: 성형-SUB ASSY-CARRIER PLANET, MID&RR | I76: =SUM(L76:T76) -> 0 | U76: =SUM(L76:T76) -> 0 | V76: =IF(U76=I76,"OK","NG") -> OK
A77: 5010-00 | B77: 5655 | C77: 성형-WHEEL-A/TRANS INPUT SHF SPD | I77: =SUM(L77:T77) -> 0 | U77: =SUM(L77:T77) -> 0 | V77: =IF(U77=I77,"OK","NG") -> OK
A78: 6027-30 | B78: 22704 | C78: 성형-SUB ASSY-CARRIER PLANET, MID&RR | I78: =SUM(L78:T78) -> 0 | U78: =SUM(L78:T78) -> 0 | V78: =IF(U78=I78,"OK","NG") -> OK
...

Sheet 4
A1: 생산수량 | B1: =H69 -> 0 | E1: 불량금액 | F1: =G69 -> 0
A2: 불량수량 | B2: =I81 -> 34 | L2: =SUBTOTAL(9,L6:L80) -> 0 | M2: =SUBTOTAL(9,M6:M80) -> 14 | N2: =SUBTOTAL(9,N6:N80) -> 0 | O2: =SUBTOTAL(9,O6:O80) -> 0 | P2: =SUBTOTAL(9,P6:P80) -> 0 | Q2: =SUBTOTAL(9,Q6:Q80) -> 0 | R2: =SUBTOTAL(9,R6:R80) -> 0 | S2: =SUBTOTAL(9,S6:S80) -> 20 | ... U2: =SUBTOTAL(9,U6:U80) -> 34
A3: 불량율(ppm) | B3: =IF(ISERROR(B2/(B2+B1)*1000000),"",(B2/(B2+B1)*1000000)) -> 1000000 | L3: =SUM(L6:L80) -> 0 | M3: =SUM(M6:M80) -> 14 | N3: =SUM(N6:N80) -> 0 | O3: =SUM(O6:O80) -> 0 | P3: =SUM(P6:P80) -> 0 | Q3: =SUM(Q6:Q80) -> 0 | R3: =SUM(R6:R80) -> 0 | S3: =SUM(S6:S80) -> 20 | ... U3: =SUM(U6:U80) -> 34
A4: =V81 -> OK | E4: 거래선 및 불량금액 | H4: 종합 | L4: 형상 | M4: 시험성형 | N4: 밀도수정 | O4: CRACK 수정 | P4: 발란스 | Q4: 자동화 셋팅 | R4: 셋팅 | S4: 기타 | T4: 폐기 | U4: 합계 | V4: 오기 유/무
A5: TM NO. | B5: CODE - 성형 (ERP) | C5: 품 명 | D5: 차종 | E5: 거래선 | F5: 단가 | G5: 불량금액 (단가x수량) | H5: 생산수량 | I5: 불량수량 | J5: 불량율 (PPM)
A6: 1360-00 | B6: 8092 | C6: 성형-MOTOR PULLEY | I6: =SUM(L6:T6) -> 0 | U6: =SUM(L6:T6) -> 0 | V6: =IF(U6=I6,"OK","NG") -> OK
A7: 1361-00J | B7: 8088 | C7: 성형-BALL NUT PULLEY | I7: =SUM(L7:T7) -> 0 | U7: =SUM(L7:T7) -> 0 | V7: =IF(U7=I7,"OK","NG") -> OK
A8: 1361-01J | B8: 8081 | C8: 성형-BALL NUT PULLEY | I8: =SUM(L8:T8) -> 0 | U8: =SUM(L8:T8) -> 0 | V8: =IF(U8=I8,"OK","NG") -> OK
A9: 1361-02J | B9: 18524 | C9: 4 | I9: =SUM(L9:T9) -> 0 | U9: =SUM(L9:T9) -> 0 | V9: =IF(U9=I9,"OK","NG") -> OK
A10: 1464-00 | B10: 6234 | C10: 성형-PULLEY | I10: =SUM(L10:T10) -> 0 | U10: =SUM(L10:T10) -> 0 | V10: =IF(U10=I10,"OK","NG") -> OK
A11: 1464-01 | B11: 14830 | C11: 성형-PULLEY | I11: =SUM(L11:T11) -> 0 | U11: =SUM(L11:T11) -> 0 | V11: =IF(U11=I11,"OK","NG") -> OK
A12: 1510-00 | B12: 6004 | C12: 성형-PULLEY LARGE | I12: =SUM(L12:T12) -> 0 | U12: =SUM(L12:T12) -> 0 | V12: =IF(U12=I12,"OK","NG") -> OK
A13: 1510-01 | B13: 11857 | C13: 성형-PULLEY LARGE | I13: =SUM(L13:T13) -> 0 | U13: =SUM(L13:T13) -> 0 | V13: =IF(U13=I13,"OK","NG") -> OK
A14: 1510-02 | B14: 15004 | C14: 성형-PULLEY LARGE | I14: =SUM(L14:T14) -> 0 | U14: =SUM(L14:T14) -> 0 | V14: =IF(U14=I14,"OK","NG") -> OK
A15: 1695-00 | B15: 15174 | C15: 성형-MOTOR PULLEY | I15: =SUM(L15:T15) -> 0 | U15: =SUM(L15:T15) -> 0 | V15: =IF(U15=I15,"OK","NG") -> OK
A16: 1781-00 | B16: 15520 | C16: 성형-PULLEY | I16: =SUM(L16:T16) -> 0 | U16: =SUM(L16:T16) -> 0 | V16: =IF(U16=I16,"OK","NG") -> OK
A17: 1785-00 | B17: 14989 | C17: 성형-MOTOR PULLEY | I17: =SUM(L17:T17) -> 0 | U17: =SUM(L17:T17) -> 0 | V17: =IF(U17=I17,"OK","NG") -> OK
A18: 1786-00 | B18: 14984 | C18: 성형-BALL NUT PULLEY | I18: =SUM(L18:T18) -> 0 | U18: =SUM(L18:T18) -> 0 | V18: =IF(U18=I18,"OK","NG") -> OK
A19: 1883-00 | B19: 16270 | C19: 성형-SLIDE | I19: =SUM(L19:T19) -> 0 | U19: =SUM(L19:T19) -> 0 | V19: =IF(U19=I19,"OK","NG") -> OK
A20: 1903-00 | B20: 19060 | C20: 성형-PULLEY | I20: =SUM(L20:T20) -> 0 | U20: =SUM(L20:T20) -> 0 | V20: =IF(U20=I20,"OK","NG") -> OK
A21: 1935-00 | B21: 18828 | C21: 성형-Driven Pulley | I21: =SUM(L21:T21) -> 0 | U21: =SUM(L21:T21) -> 0 | V21: =IF(U21=I21,"OK","NG") -> OK
... A57: 6011-10 | B57: 11381 | C57: 성형-CARRIER PALNET | I57: =SUM(L57:T57) -> 0 | U57: =SUM(L57:T57) -> 0 | V57: =IF(U57=I57,"OK","NG") -> OK
A58: 6011-20 | B58: 11382 | C58: 성형-CARRIER PALNET | I58: =SUM(L58:T58) -> 27 | M58: 7 | S58: 20 | U58: =SUM(L58:T58) -> 27 | V58: =IF(U58=I58,"OK","NG") -> OK
A59: 6017-10 | B59: 16586 | C59: 성형-CARRIER PLANET MID | I59: =SUM(L59:T59) -> 0 | U59: =SUM(L59:T59) -> 0 | V59: =IF(U59=I59,"OK","NG") -> OK
A60: 6017-20 | B60: 16587 | C60: 성형-CARRIER PLANET MID | I60: =SUM(L60:T60) -> 0 | U60: =SUM(L60:T60) -> 0 | V60: =IF(U60=I60,"OK","NG") -> OK
A61: 6019-00 | B61: 17121 | C61: 성형-HOUSING GUIDE RING | I61: =SUM(L61:T61) -> 0 | U61: =SUM(L61:T61) -> 0 | V61: =IF(U61=I61,"OK","NG") -> OK
A62: 6020-10 | B62: 19270 | C62: 성형-CARRIER PALNET | I62: =SUM(L62:T62) -> 0 | U62: =SUM(L62:T62) -> 0 | V62: =IF(U62=I62,"OK","NG") -> OK
A63: 6020-20 | B63: 19276 | C63: 성형-CARRIER PALNET | I63: =SUM(L63:T63) -> 0 | U63: =SUM(L63:T63) -> 0 | V63: =IF(U63=I63,"OK","NG") -> OK
A64: 1914-00 | B64: 19836 | C64: 성형-MOTOR PULLEY | I64: =SUM(L64:T64) -> 0 | U64: =SUM(L64:T64) -> 0 | V64: =IF(U64=I64,"OK","NG") -> OK
A65: 1987-00J | B65: 20278 | C65: 성형-BELT PULLEY | I65: =SUM(L65:T65) -> 0 | U65: =SUM(L65:T65) -> 0 | V65: =IF(U65=I65,"OK","NG") -> OK
A66: 1986-00 | B66: 20272 | C66: 성형-BELT PULLEY | I66: =SUM(L66:T66) -> 0 | U66: =SUM(L66:T66) -> 0 | V66: =IF(U66=I66,"OK","NG") -> OK
A67: 2059-00 | B67: 20956 | C67: 성형-BELT PULLEY | I67: =SUM(L67:T67) -> 0 | U67: =SUM(L67:T67) -> 0 | V67: =IF(U67=I67,"OK","NG") -> OK
A68: 6023-10 | B68: 21299 | C68: 성형-CARRIER PLANET MID | I68: =SUM(L68:T68) -> 0 | U68: =SUM(L68:T68) -> 0 | V68: =IF(U68=I68,"OK","NG") -> OK
A69: 2140-00 | B69: 22115 | C69: 성형-CAM PLATE | I69: =SUM(L69:T69) -> 0 | U69: =SUM(L69:T69) -> 0 | V69: =IF(U69=I69,"OK","NG") -> OK
A70: 6027-10 | B70: 22706 | C70: 성형-SUB ASSY-CARRIER PLANET, MID&RR | I70: =SUM(L70:T70) -> 0 | U70: =SUM(L70:T70) -> 0 | V70: =IF(U70=I70,"OK","NG") -> OK
... A74: 1948-00 | B74: 19279 | C74: 성형-Flange | I74: =SUM(L74:T74) -> 0 | U74: =SUM(L74:T74) -> 0 | V74: =IF(U74=I74,"OK","NG") -> OK
A75: 6026-10 | B75: 22724 | C75: 성형-SUB ASSY-CARRIER PLANET, MID&RR | I75: 0 | U75: 0 | V75: OK
A76: 6027-20 | B76: 22705 | C76: 성형-SUB ASSY-CARRIER PLANET, MID&RR | I76: =SUM(L76:T76) -> 0 | U76: =SUM(L76:T76) -> 0 | V76: =IF(U76=I76,"OK","NG") -> OK
A77: 5010-00 | B77: 5655 | C77: 성형-WHEEL-A/TRANS INPUT SHF SPD | I77: =SUM(L77:T77) -> 0 | U77: =SUM(L77:T77) -> 0 | V77: =IF(U77=I77,"OK","NG") -> OK
A78: 6027-30 | B78: 22704 | C78: 성형-SUB ASSY-CARRIER PLANET, MID&RR | I78: =SUM(L78:T78) -> 0 | U78: =SUM(L78:T78) -> 0 | V78: =IF(U78=I78,"OK","NG") -> OK
...

Sheet 5
A1: 생산수량 | B1: =H69 -> 0 | E1: 불량금액 | F1: =G69 -> 0
A2: 불량수량 | B2: =I81 -> 0 | L2: =SUBTOTAL(9,L6:L80) -> 0 | M2: =SUBTOTAL(9,M6:M80) -> 0 | N2: =SUBTOTAL(9,N6:N80) -> 0 | O2: =SUBTOTAL(9,O6:O80) -> 0 | P2: =SUBTOTAL(9,P6:P80) -> 0 | Q2: =SUBTOTAL(9,Q6:Q80) -> 0 | R2: =SUBTOTAL(9,R6:R80) -> 0 | S2: =SUBTOTAL(9,S6:S80) -> 0 | ... U2: =SUBTOTAL(9,U6:U80) -> 0
A3: 불량율(ppm) | B3: =IF(ISERROR(B2/(B2+B1)*1000000),"",(B2/(B2+B1)*1000000)) | L3: =SUM(L6:L80) -> 0 | M3: =SUM(M6:M80) -> 0 | N3: =SUM(N6:N80) -> 0 | O3: =SUM(O6:O80) -> 0 | P3: =SUM(P6:P80) -> 0 | Q3: =SUM(Q6:Q80) -> 0 | R3: =SUM(R6:R80) -> 0 | S3: =SUM(S6:S80) -> 0 | ... U3: =SUM(U6:U80) -> 0
A4: =V81 -> OK | E4: 거래선 및 불량금액 | H4: 종합 | L4: 형상 | M4: 시험성형 | N4: 밀도수정 | O4: CRACK 수정 | P4: 발란스 | Q4: 자동화 셋팅 | R4: 셋팅 | S4: 기타 | T4: 폐기 | U4: 합계 | V4: 오기 유/무
A5: TM NO. | B5: CODE - 성형 (ERP) | C5: 품 명 | D5: 차종 | E5: 거래선 | F5: 단가 | G5: 불량금액 (단가x수량) | H5: 생산수량 | I5: 불량수량 | J5: 불량율 (PPM)
A6: 1360-00 | B6: 8092 | C6: 성형-MOTOR PULLEY | I6: =SUM(L6:T6) -> 0 | U6: =SUM(L6:T6) -> 0 | V6: =IF(U6=I6,"OK","NG") -> OK
A7: 1361-00J | B7: 8088 | C7: 성형-BALL NUT PULLEY | I7: =SUM(L7:T7) -> 0 | U7: =SUM(L7:T7) -> 0 | V7: =IF(U7=I7,"OK","NG") -> OK
A8: 1361-01J | B8: 8081 | C8: 성형-BALL NUT PULLEY | I8: =SUM(L8:T8) -> 0 | U8: =SUM(L8:T8) -> 0 | V8: =IF(U8=I8,"OK","NG") -> OK
A9: 1361-02J | B9: 18524 | C9: 성형-BALL NUT PULLEY | I9: =SUM(L9:T9) -> 0 | U9: =SUM(L9:T9) -> 0 | V9: =IF(U9=I9,"OK","NG") -> OK
A10: 1464-00 | B10: 6234 | C10: 성형-PULLEY | I10: =SUM(L10:T10) -> 0 | U10: =SUM(L10:T10) -> 0 | V10: =IF(U10=I10,"OK","NG") -> OK
A11: 1464-01 | B11: 14830 | C11: 성형-PULLEY | I11: =SUM(L11:T11) -> 0 | U11: =SUM(L11:T11) -> 0 | V11: =IF(U11=I11,"OK","NG") -> OK
A12: 1510-00 | B12: 6004 | C12: 성형-PULLEY LARGE | I12: =SUM(L12:T12) -> 0 | U12: =SUM(L12:T12) -> 0 | V12: =IF(U12=I12,"OK","NG") -> OK
A13: 1510-01 | B13: 11857 | C13: 성형-PULLEY LARGE | I13: =SUM(L13:T13) -> 0 | U13: =SUM(L13:T13) -> 0 | V13: =IF(U13=I13,"OK","NG") -> OK
A14: 1510-02 | B14: 15004 | C14: 성형-PULLEY LARGE | I14: =SUM(L14:T14) -> 0 | U14: =SUM(L14:T14) -> 0 | V14: =IF(U14=I14,"OK","NG") -> OK
A15: 1695-00 | B15: 15174 | C15: 성형-MOTOR PULLEY | I15: =SUM(L15:T15) -> 0 | U15: =SUM(L15:T15) -> 0 | V15: =IF(U15=I15,"OK","NG") -> OK
A16: 1781-00 | B16: 15520 | C16: 성형-PULLEY | I16: =SUM(L16:T16) -> 0 | U16: =SUM(L16:T16) -> 0 | V16: =IF(U16=I16,"OK","NG") -> OK
A17: 1785-00 | B17: 14989 | C17: 성형-MOTOR PULLEY | I17: =SUM(L17:T17) -> 0 | U17: =SUM(L17:T17) -> 0 | V17: =IF(U17=I17,"OK","NG") -> OK
... A74: 1948-00 | B74: 19279 | C74: 성형-Flange | I74: =SUM(L74:T74) -> 0 | U74: =SUM(L74:T74) -> 0 | V74: =IF(U74=I74,"OK","NG") -> OK
A75: 6026-10 | B75: 22724 | C75: 성형-SUB ASSY-CARRIER PLANET, MID&RR | I75: 0 | U75: 0 | V75: OK
A76: 6027-20 | B76: 22705 | C76: 성형-SUB ASSY-CARRIER PLANET, MID&RR | I76: =SUM(L76:T76) -> 0 | U76: =SUM(L76:T76) -> 0 | V76: =IF(U76=I76,"OK","NG") -> OK
A77: 5010-00 | B77: 5655 | C77: 성형-WHEEL-A/TRANS INPUT SHF SPD | I77: =SUM(L77:T77) -> 0 | U77: =SUM(L77:T77) -> 0 | V77: =IF(U77=I77,"OK","NG") -> OK
A78: 6027-30 | B78: 22704 | C78: 성형-SUB ASSY-CARRIER PLANET, MID&RR | I78: =SUM(L78:T78) -> 0 | U78: =SUM(L78:T78) -> 0 | V78: =IF(U78=I78,"OK","NG") -> OK
A79: 6026-30 | B79: 22722 | C79: 성형-SUB ASSY-CARRIER PLANET, MID&RR | I79: =SUM(L79:T79) -> 0 | U79: =SUM(L79:T79) -> 0 | V79: =IF(U79=I79,"OK","NG") -> OK
A80: 6026-20 | B80: 22723 | C80: 성형-SUB ASSY-CARRIER PLANET, MID&RR | I80: =SUM(L80:T80) -> 0 | U80: =SUM(L80:T80) -> 0 | V80: =IF(U80=I80,"OK","NG") -> OK
C81: 소계 SUBTOTAL(가로) | G81: =SUM(G6:G49) -> 0 | H81: =SUM(H6:H49) -> 0 | I81: =SUM(I6:I80) -> 0 | J81: =SUM(J6:J49) -> 0 | K81: =SUM(K6:K51) -> 0 | L81: =SUM(L6:L80) -> 0 | M81: =SUM(M6:M80) -> 0 | N81: =SUM(N6:N80) -> 0 | O81: =SUM(O6:O80) -> 0 | P81: =SUM(P6:P80) -> 0 | Q81: =SUM(Q6:Q80) -> 0 | R81: =SUM(R6:R80) -> 0 | S81: =SUM(S6:S80) -> 0 | ... U81: =SUM(U6:U80) -> 0 | V81: =IF(U81=SUM(I81),"OK","NG") -> OK

Sheet 6
A1: 생산수량 | B1: =H69 -> 0 | E1: 불량금액 | F1: =G69 -> 0
A2: 불량수량 | B2: =I81 -> 33 | L2: =SUBTOTAL(9,L6:L80) -> 0 | M2: =SUBTOTAL(9,M6:M80) -> 33 | N2: =SUBTOTAL(9,N6:N80) -> 0 | O2: =SUBTOTAL(9,O6:O80) -> 0 | P2: =SUBTOTAL(9,P6:P80) -> 0 | Q2: =SUBTOTAL(9,Q6:Q80) -> 0 | R2: =SUBTOTAL(9,R6:R80) -> 0 | S2: =SUBTOTAL(9,S6:S80) -> 0 | ... U2: =SUBTOTAL(9,U6:U80) -> 33
A3: 불량율(ppm) | B3: =IF(ISERROR(B2/(B2+B1)*1000000),"",(B2/(B2+B1)*1000000)) -> 1000000 | L3: =SUM(L6:L80) -> 0 | M3: =SUM(M6:M80) -> 33 | N3: =SUM(N6:N80) -> 0 | O3: =SUM(O6:O80) -> 0 | P3: =SUM(P6:P80) -> 0 | Q3: =SUM(Q6:Q80) -> 0 | R3: =SUM(R6:R80) -> 0 | S3: =SUM(S6:S80) -> 0 | ... U3: =SUM(U6:U80) -> 33
A4: =V81 -> OK | E4: 거래선 및 불량금액 | H4: 종합 | L4: 형상 | M4: 시험성형 | N4: 밀도수정 | O4: CRACK 수정 | P4: 발란스 | Q4: 자동화 셋팅 | R4: 셋팅 | S4: 기타 | T4: 폐기 | U4: 합계 | V4: 오기 유/무
A5: TM NO. | B5: CODE - 성형 (ERP) | C5: 품 명 | D5: 차종 | E5: 거래선 | F5: 단가 | G5: 불량금액 (단가x수량) | H5: 생산수량 | I5: 불량수량 | J5: 불량율 (PPM)
A6: 1360-00 | B6: 8092 | C6: 성형-MOTOR PULLEY | I6: =SUM(L6:T6) -> 0 | U6: =SUM(L6:T6) -> 0 | V6: =IF(U6=I6,"OK","NG") -> OK
A7: 1361-00J | B7: 8088 | C7: 성형-BALL NUT PULLEY | I7: =SUM(L7:T7) -> 0 | U7: =SUM(L7:T7) -> 0 | V7: =IF(U7=I7,"OK","NG") -> OK
A8: 1361-01J | B8: 8081 | C8: 성형-BALL NUT PULLEY | I8: =SUM(L8:T8) -> 0 | U8: =SUM(L8:T8) -> 0 | V8: =IF(U8=I8,"OK","NG") -> OK
A9: 1361-02J | B9: 18524 | C9: 성형-BALL NUT PULLEY | I9: =SUM(L9:T9) -> 0 | U9: =SUM(L9:T9) -> 0 | V9: =IF(U9=I9,"OK","NG") -> OK
A10: 1464-00 | B10: 6234 | C10: 성형-PULLEY | I10: =SUM(L10:T10) -> 0 | U10: =SUM(L10:T10) -> 0 | V10: =IF(U10=I10,"OK","NG") -> OK
A11: 1464-01 | B11: 14830 | C11: 성형-PULLEY | I11: =SUM(L11:T11) -> 0 | U11: =SUM(L11:T11) -> 0 | V11: =IF(U11=I11,"OK","NG") -> OK
A12: 1510-00 | B12: 6004 | C12: 성형-PULLEY LARGE | I12: =SUM(L12:T12) -> 0 | U12: =SUM(L12:T12) -> 0 | V12: =IF(U12=I12,"OK","NG") -> OK
A13: 1510-01 | B13: 11857 | C13: 성형-PULLEY LARGE | I13: =SUM(L13:T13) -> 0 | U13: =SUM(L13:T13) -> 0 | V13: =IF(U13=I13,"OK","NG") -> OK
A14: 1510-02 | B14: 15004 | C14: 성형-PULLEY LARGE | I14: =SUM(L14:T14) -> 0 | U14: =SUM(L14:T14) -> 0 | V14: =IF(U14=I14,"OK","NG") -> OK
A15: 1695-00 | B15: 15174 | C15: 성형-MOTOR PULLEY | I15: =SUM(L15:T15) -> 0 | U15: =SUM(L15:T15) -> 0 | V15: =IF(U15=I15,"OK","NG") -> OK
A16: 1781-00 | B16: 15520 | C16: 성형-PULLEY | I16: =SUM(L16:T16) -> 0 | U16: =SUM(L16:T16) -> 0 | V16: =IF(U16=I16,"OK","NG") -> OK
A17: 1785-00 | B17: 14989 | C17: 성형-MOTOR PULLEY | I17: =SUM(L17:T17) -> 0 | U17: =SUM(L17:T17) -> 0 | V17: =IF(U17=I17,"OK","NG") -> OK
... A21: 1935-00 | B21: 18828 | C21: 성형-Driven Pulley | I21: =SUM(L21:T21) -> 0 | U21: =SUM(L21:T21) -> 0 | V21: =IF(U21=I21,"OK","NG") -> OK
A22: 5001-00 | B22: 5695 | C22: 성형-PLATE 1-2-3-4 CLU BKG | I22: =SUM(L22:T22) -> 7 | M22: 7 | U22: =SUM(L22:T22) -> 7 | V22: =IF(U22=I22,"OK","NG") -> OK
A23: 5002-00 | B23: 5691 | C23: 성형-PLATE 4-5-6 CLU BKG | I23: =SUM(L23:T23) -> 0 | U23: =SUM(L23:T23) -> 0 | V23: =IF(U23=I23,"OK","NG") -> OK
A24: 5003-00 | B24: 5687 | C24: 성형-PLATE 3-5-REV CLU BKG | I24: =SUM(L24:T24) -> 0 | U24: =SUM(L24:T24) -> 0 | V24: =IF(U24=I24,"OK","NG") -> OK
A25: 5003-01 | B25: 5683 | C25: 성형-PLATE 3-5-REV CLU BKG | I25: =SUM(L25:T25) -> 0 | U25: =SUM(L25:T25) -> 0 | V25: =IF(U25=I25,"OK","NG") -> OK
A26: 5004-00 | B26: 5679 | C26: 성형-PLATE LOW & REV CLU BKG | I26: =SUM(L26:T26) -> 0 | U26: =SUM(L26:T26) -> 0 | V26: =IF(U26=I26,"OK","NG") -> OK
A27: 5005-00 | B27: 5675 | C27: 성형-WHEEL-A/TRANS INPUT SHF SPD SEN RELUCTOR | I27: =SUM(L27:T27) -> 0 | U27: =SUM(L27:T27) -> 0 | V27: =IF(U27=I27,"OK","NG") -> OK
A28: 5006-00 | B28: 5671 | C28: 성형-PLATE 1-2-3-4 CLU BKG | I28: =SUM(L28:T28) -> 0 | U28: =SUM(L28:T28) -> 0 | V28: =IF(U28=I28,"OK","NG") -> OK
A29: 5007-00 | B29: 5667 | C29: 성형-PLATE 4-5-6 CLU BKG | I29: =SUM(L29:T29) -> 0 | U29: =SUM(L29:T29) -> 0 | V29: =IF(U29=I29,"OK","NG") -> OK
A30: 5008-00 | B30: 5663 | C30: 성형-PLATE 3-5-REV CLU BKG | I30: =SUM(L30:T30) -> 0 | U30: =SUM(L30:T30) -> 0 | V30: =IF(U30=I30,"OK","NG") -> OK
A31: 5009-00 | B31: 5659 | C31: 성형-PLATE LOW & REV CLU BKG | I31: =SUM(L31:T31) -> 0 | U31: =SUM(L31:T31) -> 0 | V31: =IF(U31=I31,"OK","NG") -> OK
A32: 5010-00 | B32: 5655 | C32: 성형-WHEEL-A/TRANS INPUT SHF SPD | I32: =SUM(L32:T32) -> 0 | U32: =SUM(L32:T32) -> 0 | V32: =IF(U32=I32,"OK","NG") -> OK
A33: 5011-10 | B33: 5651 | C33: 성형-CARRIER-REACTION | I33: =SUM(L33:T33) -> 0 | U33: =SUM(L33:T33) -> 0 | V33: =IF(U33=I33,"OK","NG") -> OK
A34: 5012-10 | B34: 5643 | C34: 성형-CARRIER-INPUT | I34: =SUM(L34:T34) -> 0 | U34: =SUM(L34:T34) -> 0 | V34: =IF(U34=I34,"OK","NG") -> OK
... A38: 5014-10 | B38: 5627 | C38: 성형-CARRIER-INPUT | I38: =SUM(L38:T38) -> 0 | U38: =SUM(L38:T38) -> 0 | V38: =IF(U38=I38,"OK","NG") -> OK
A39: 5014-20 | B39: 11348 | C39: 성형-CARRIER-INPUT | I39: =SUM(L39:T39) -> 7 | M39: 7 | U39: =SUM(L39:T39) -> 7 | V39: =IF(U39=I39,"OK","NG") -> OK
A40: 5015-10 | B40: 5619 | C40: 성형-CARRIER - REACTION | I40: =SUM(L40:T40) -> 0 | U40: =SUM(L40:T40) -> 0 | V40: =IF(U40=I40,"OK","NG") -> OK
A41: 5015-20 | B41: 11347 | C41: 성형-CARRIER - REACTION | I41: =SUM(L41:T41) -> 0 | U41: =SUM(L41:T41) -> 0 | V41: =IF(U41=I41,"OK","NG") -> OK
A42: 5016-10 | B42: 5611 | C42: 성형-CARRIER - INPUT | I42: =SUM(L42:T42) -> 0 | U42: =SUM(L42:T42) -> 0 | V42: =IF(U42=I42,"OK","NG") -> OK
A43: 5016-20 | B43: 11336 | C43: 성형-CARRIER - INPUT | I43: =SUM(L43:T43) -> 0 | U43: =SUM(L43:T43) -> 0 | V43: =IF(U43=I43,"OK","NG") -> OK
A44: 5017-10 | B44: 14860 | C44: 성형-CARRIER-INPUT | I44: =SUM(L44:T44) -> 0 | U44: =SUM(L44:T44) -> 0 | V44: =IF(U44=I44,"OK","NG") -> OK
A45: 5017-20 | B45: 14861 | C45: 성형-CARRIER-INPUT | I45: =SUM(L45:T45) -> 0 | U45: =SUM(L45:T45) -> 0 | V45: =IF(U45=I45,"OK","NG") -> OK
A46: 5018-10 | B46: 15096 | C46: 성형-CARRIER-INPUT | I46: =SUM(L46:T46) -> 0 | U46: =SUM(L46:T46) -> 0 | V46: =IF(U46=I46,"OK","NG") -> OK
...

Sheet 7
A1: 생산수량 | B1: =H69 -> 0 | E1: 불량금액 | F1: =G69 -> 0
A2: 불량수량 | B2: =I81 -> 66 | L2: =SUBTOTAL(9,L6:L80) -> 0 | M2: =SUBTOTAL(9,M6:M80) -> 38 | N2: =SUBTOTAL(9,N6:N80) -> 0 | O2: =SUBTOTAL(9,O6:O80) -> 15 | P2: =SUBTOTAL(9,P6:P80) -> 0 | Q2: =SUBTOTAL(9,Q6:Q80) -> 0 | R2: =SUBTOTAL(9,R6:R80) -> 0 | S2: =SUBTOTAL(9,S6:S80) -> 13 | ... U2: =SUBTOTAL(9,U6:U80) -> 66
A3: 불량율(ppm) | B3: =IF(ISERROR(B2/(B2+B1)*1000000),"",(B2/(B2+B1)*1000000)) -> 1000000 | L3: =SUM(L6:L80) -> 0 | M3: =SUM(M6:M80) -> 38 | N3: =SUM(N6:N80) -> 0 | O3: =SUM(O6:O80) -> 15 | P3: =SUM(P6:P80) -> 0 | Q3: =SUM(Q6:Q80) -> 0 | R3: =SUM(R6:R80) -> 0 | S3: =SUM(S6:S80) -> 13 | ... U3: =SUM(U6:U80) -> 66
A4: =V81 -> OK | E4: 거래선 및 불량금액 | H4: 종합 | L4: 형상 | M4: 시험성형 | N4: 밀도수정 | O4: CRACK 수정 | P4: 발란스 | Q4: 자동화 셋팅 | R4: 셋팅 | S4: 기타 | T4: 폐기 | U4: 합계 | V4: 오기 유/무
A5: TM NO. | B5: CODE - 성형 (ERP) | C5: 품 명 | D5: 차종 | E5: 거래선 | F5: 단가 | G5: 불량금액 (단가x수량) | H5: 생산수량 | I5: 불량수량 | J5: 불량율 (PPM)
A6: 1360-00 | B6: 8092 | C6: 성형-MOTOR PULLEY | I6: =SUM(L6:T6) -> 0 | U6: =SUM(L6:T6) -> 0 | V6: =IF(U6=I6,"OK","NG") -> OK
A7: 1361-00J | B7: 8088 | C7: 성형-BALL NUT PULLEY | I7: =SUM(L7:T7) -> 0 | U7: =SUM(L7:T7) -> 0 | V7: =IF(U7=I7,"OK","NG") -> OK
A8: 1361-01J | B8: 8081 | C8: 성형-BALL NUT PULLEY | I8: =SUM(L8:T8) -> 0 | U8: =SUM(L8:T8) -> 0 | V8: =IF(U8=I8,"OK","NG") -> OK
A9: 1361-02J | B9: 18524 | C9: 성형-BALL NUT PULLEY | I9: =SUM(L9:T9) -> 0 | U9: =SUM(L9:T9) -> 0 | V9: =IF(U9=I9,"OK","NG") -> OK
A10: 1464-00 | B10: 6234 | C10: 성형-PULLEY | I10: =SUM(L10:T10) -> 0 | U10: =SUM(L10:T10) -> 0 | V10: =IF(U10=I10,"OK","NG") -> OK
A11: 1464-01 | B11: 14830 | C11: 성형-PULLEY | I11: =SUM(L11:T11) -> 0 | U11: =SUM(L11:T11) -> 0 | V11: =IF(U11=I11,"OK","NG") -> OK
A12: 1510-00 | B12: 6004 | C12: 성형-PULLEY LARGE | I12: =SUM(L12:T12) -> 0 | U12: =SUM(L12:T12) -> 0 | V12: =IF(U12=I12,"OK","NG") -> OK
A13: 1510-01 | B13: 11857 | C13: 성형-PULLEY LARGE | I13: =SUM(L13:T13) -> 0 | U13: =SUM(L13:T13) -> 0 | V13: =IF(U13=I13,"OK","NG") -> OK
A14: 1510-02 | B14: 15004 | C14: 성형-PULLEY LARGE | I14: =SUM(L14:T14) -> 0 | U14: =SUM(L14:T14) -> 0 | V14: =IF(U14=I14,"OK","NG") -> OK
A15: 1695-00 | B15: 15174 | C15: 성형-MOTOR PULLEY | I15: =SUM(L15:T15) -> 0 | U15: =SUM(L15:T15) -> 0 | V15: =IF(U15=I15,"OK","NG") -> OK
A16: 1781-00 | B16: 15520 | C16: 성형-PULLEY | I16: =SUM(L16:T16) -> 0 | U16: =SUM(L16:T16) -> 0 | V16: =IF(U16=I16,"OK","NG") -> OK
A17: 1785-00 | B17: 14989 | C17: 성형-MOTOR PULLEY | I17: =SUM(L17:T17) -> 0 | U17: =SUM(L17:T17) -> 0 | V17: =IF(U17=I17,"OK","NG") -> OK
... A25: 5003-01 | B25: 5683 | C25: 성형-PLATE 3-5-REV CLU BKG | I25: =SUM(L25:T25) -> 0 | U25: =SUM(L25:T25) -> 0 | V25: =IF(U25=I25,"OK","NG") -> OK
A26: 5004-00 | B26: 5679 | C26: 성형-PLATE LOW & REV CLU BKG | I26: =SUM(L26:T26) -> 7 | M26: 7 | U26: =SUM(L26:T26) -> 7 | V26: =IF(U26=I26,"OK","NG") -> OK
A27: 5005-00 | B27: 5675 | C27: 성형-WHEEL-A/TRANS INPUT SHF SPD SEN RELUCTOR | I27: =SUM(L27:T27) -> 0 | U27: =SUM(L27:T27) -> 0 | V27: =IF(U27=I27,"OK","NG") -> OK
A28: 5006-00 | B28: 5671 | C28: 성형-PLATE 1-2-3-4 CLU BKG | I28: =SUM(L28:T28) -> 0 | U28: =SUM(L28:T28) -> 0 | V28: =IF(U28=I28,"OK","NG") -> OK
A29: 5007-00 | B29: 5667 | C29: 성형-PLATE 4-5-6 CLU BKG | I29: =SUM(L29:T29) -> 0 | U29: =SUM(L29:T29) -> 0 | V29: =IF(U29=I29,"OK","NG") -> OK
A30: 5008-00 | B30: 5663 | C30: 성형-PLATE 3-5-REV CLU BKG | I30: =SUM(L30:T30) -> 0 | U30: =SUM(L30:T30) -> 0 | V30: =IF(U30=I30,"OK","NG") -> OK
A31: 5009-00 | B31: 5659 | C31: 성형-PLATE LOW & REV CLU BKG | I31: =SUM(L31:T31) -> 0 | U31: =SUM(L31:T31) -> 0 | V31: =IF(U31=I31,"OK","NG") -> OK
A32: 5010-00 | B32: 5655 | C32: 성형-WHEEL-A/TRANS INPUT SHF SPD | I32: =SUM(L32:T32) -> 0 | U32: =SUM(L32:T32) -> 0 | V32: =IF(U32=I32,"OK","NG") -> OK
A33: 5011-10 | B33: 5651 | C33: 성형-CARRIER-REACTION | I33: =SUM(L33:T33) -> 0 | U33: =SUM(L33:T33) -> 0 | V33: =IF(U33=I33,"OK","NG") -> OK
A34: 5012-10 | B34: 5643 | C34: 성형-CARRIER-INPUT | I34: =SUM(L34:T34) -> 0 | U34: =SUM(L34:T34) -> 0 | V34: =IF(U34=I34,"OK","NG") -> OK
A35: 5012-20 | B35: 11350 | C35: 성형-CARRIER-INPUT | I35: =SUM(L35:T35) -> 0 | U35: =SUM(L35:T35) -> 0 | V35: =IF(U35=I35,"OK","NG") -> OK
A36: 5013-10 | B36: 5635 | C36: 성형-CARRIER-REACTION | I36: =SUM(L36:T36) -> 0 | U36: =SUM(L36:T36) -> 0 | V36: =IF(U36=I36,"OK","NG") -> OK
A37: 5013-20 | B37: 11349 | C37: 성형-CARRIER-REACTION | I37: =SUM(L37:T37) -> 0 | U37: =SUM(L37:T37) -> 0 | V37: =IF(U37=I37,"OK","NG") -> OK
A38: 5014-10 | B38: 5627 | C38: 성형-CARRIER-INPUT | I38: =SUM(L38:T38) -> 0 | U38: =SUM(L38:T38) -> 0 | V38: =IF(U38=I38,"OK","NG") -> OK
... A63: 6020-20 | B63: 19276 | C63: 성형-CARRIER PALNET | I63: =SUM(L63:T63) -> 0 | U63: =SUM(L63:T63) -> 0 | V63: =IF(U63=I63,"OK","NG") -> OK
A64: 1914-00 | B64: 19836 | C64: 성형-MOTOR PULLEY | I64: =SUM(L64:T64) -> 24 | M64: 11 | S64: 13 | U64: =SUM(L64:T64) -> 24 | V64: =IF(U64=I64,"OK","NG") -> OK
A65: 1987-00J | B65: 20278 | C65: 성형-BELT PULLEY | I65: =SUM(L65:T65) -> 0 | U65: =SUM(L65:T65) -> 0 | V65: =IF(U65=I65,"OK","NG") -> OK
A66: 1986-00 | B66: 20272 | C66: 성형-BELT PULLEY | I66: =SUM(L66:T66) -> 0 | U66: =SUM(L66:T66) -> 0 | V66: =IF(U66=I66,"OK","NG") -> OK
A67: 2059-00 | B67: 20956 | C67: 성형-BELT PULLEY | I67: =SUM(L67:T67) -> 25 | M67: 10 | O67: 15 | U67: =SUM(L67:T67) -> 25 | V67: =IF(U67=I67,"OK","NG") -> OK
A68: 6023-10 | B68: 21299 | C68: 성형-CARRIER PLANET MID | I68: =SUM(L68:T68) -> 0 | U68: =SUM(L68:T68) -> 0 | V68: =IF(U68=I68,"OK","NG") -> OK
A69: 2140-00 | B69: 22115 | C69: 성형-CAM PLATE | I69: =SUM(L69:T69) -> 0 | U69: =SUM(L69:T69) -> 0 | V69: =IF(U69=I69,"OK","NG") -> OK
A70: 6027-10 | B70: 22706 | C70: 성형-SUB ASSY-CARRIER PLANET, MID&RR | I70: =SUM(L70:T70) -> 0 | U70: =SUM(L70:T70) -> 0 | V70: =IF(U70=I70,"OK","NG") -> OK
A71: 2206-00 | B71: 22886 | C71: 성형-BALL NUT PULLEY | I71: =SUM(L71:T71) -> 0 | U71: =SUM(L71:T71) -> 0 | V71: =IF(U71=I71,"OK","NG") -> OK
...

Sheet 8
A1: 생산수량 | B1: =H81 -> 0 | E1: 불량금액 | F1: =G81 -> 0
A2: 불량수량 | B2: =I81 -> 38 | L2: =SUBTOTAL(9,L6:L80) -> 0 | M2: =SUBTOTAL(9,M6:M80) -> 38 | N2: =SUBTOTAL(9,N6:N80) -> 0 | O2: =SUBTOTAL(9,O6:O80) -> 0 | P2: =SUBTOTAL(9,P6:P80) -> 0 | Q2: =SUBTOTAL(9,Q6:Q80) -> 0 | R2: =SUBTOTAL(9,R6:R80) -> 0 | S2: =SUBTOTAL(9,S6:S80) -> 0 | ... U2: =SUBTOTAL(9,U6:U80) -> 38
A3: 불량율(ppm) | B3: =IF(ISERROR(B2/(B2+B1)*1000000),"",(B2/(B2+B1)*1000000)) -> 1000000 | L3: =SUM(L6:L80) -> 0 | M3: =SUM(M6:M80) -> 38 | N3: =SUM(N6:N80) -> 0 | O3: =SUM(O6:O80) -> 0 | P3: =SUM(P6:P80) -> 0 | Q3: =SUM(Q6:Q80) -> 0 | R3: =SUM(R6:R80) -> 0 | S3: =SUM(S6:S80) -> 0 | ... U3: =SUM(U6:U80) -> 38
A4: =V81 -> OK | E4: 거래선 및 불량금액 | H4: 종합 | L4: 형상 | M4: 시험성형 | N4: 밀도수정 | O4: CRACK 수정 | P4: 발란스 | Q4: 자동화 셋팅 | R4: 셋팅 | S4: 기타 | T4: 폐기 | U4: 합계 | V4: 오기 유/무
A5: TM NO. | B5: CODE - 성형 (ERP) | C5: 품 명 | D5: 차종 | E5: 거래선 | F5: 단가 | G5: 불량금액 (단가x수량) | H5: 생산수량 | I5: 불량수량 | J5: 불량율 (PPM)
A6: 1360-00 | B6: 8092 | C6: 성형-MOTOR PULLEY | I6: =SUM(L6:T6) -> 0 | U6: =SUM(L6:T6) -> 0 | V6: =IF(U6=I6,"OK","NG") -> OK
A7: 1361-00J | B7: 8088 | C7: 성형-BALL NUT PULLEY | I7: =SUM(L7:T7) -> 0 | U7: =SUM(L7:T7) -> 0 | V7: =IF(U7=I7,"OK","NG") -> OK
A8: 1361-01J | B8: 8081 | C8: 성형-BALL NUT PULLEY | I8: =SUM(L8:T8) -> 0 | U8: =SUM(L8:T8) -> 0 | V8: =IF(U8=I8,"OK","NG") -> OK
A9: 1361-02J | B9: 18524 | C9: 성형-BALL NUT PULLEY | I9: =SUM(L9:T9) -> 0 | U9: =SUM(L9:T9) -> 0 | V9: =IF(U9=I9,"OK","NG") -> OK
A10: 1464-00 | B10: 6234 | C10: 성형-PULLEY | I10: =SUM(L10:T10) -> 0 | U10: =SUM(L10:T10) -> 0 | V10: =IF(U10=I10,"OK","NG") -> OK
A11: 1464-01 | B11: 14830 | C11: 성형-PULLEY | I11: =SUM(L11:T11) -> 0 | U11: =SUM(L11:T11) -> 0 | V11: =IF(U11=I11,"OK","NG") -> OK
A12: 1510-00 | B12: 6004 | C12: 성형-PULLEY LARGE | I12: =SUM(L12:T12) -> 0 | U12: =SUM(L12:T12) -> 0 | V12: =IF(U12=I12,"OK","NG") -> OK
A13: 1510-01 | B13: 11857 | C13: 성형-PULLEY LARGE | I13: =SUM(L13:T13) -> 0 | U13: =SUM(L13:T13) -> 0 | V13: =IF(U13=I13,"OK","NG") -> OK
A14: 1510-02 | B14: 15004 | C14: 성형-PULLEY LARGE | I14: =SUM(L14:T14) -> 0 | U14: =SUM(L14:T14) -> 0 | V14: =IF(U14=I14,"OK","NG") -> OK
A15: 1695-00 | B15: 15174 | C15: 성형-MOTOR PULLEY | I15: =SUM(L15:T15) -> 0 | U15: =SUM(L15:T15) -> 0 | V15: =IF(U15=I15,"OK","NG") -> OK
A16: 1781-00 | B16: 15520 | C16: 성형-PULLEY | I16: =SUM(L16:T16) -> 0 | U16: =SUM(L16:T16) -> 0 | V16: =IF(U16=I16,"OK","NG") -> OK
A17: 1785-00 | B17: 14989 | C17: 성형-MOTOR PULLEY | I17: =SUM(L17:T17) -> 0 | U17: =SUM(L17:T17) -> 0 | V17: =IF(U17=I17,"OK","NG") -> OK
... A26: 5004-00 | B26: 5679 | C26: 성형-PLATE LOW & REV CLU BKG | I26: =SUM(L26:T26) -> 0 | U26: =SUM(L26:T26) -> 0 | V26: =IF(U26=I26,"OK","NG") -> OK
A27: 5005-00 | B27: 5675 | C27: 성형-WHEEL-A/TRANS INPUT SHF SPD SEN RELUCTOR | I27: =SUM(L27:T27) -> 5 | M27: 5 | U27: =SUM(L27:T27) -> 5 | V27: =IF(U27=I27,"OK","NG") -> OK
A28: 5006-00 | B28: 5671 | C28: 성형-PLATE 1-2-3-4 CLU BKG | I28: =SUM(L28:T28) -> 0 | U28: =SUM(L28:T28) -> 0 | V28: =IF(U28=I28,"OK","NG") -> OK
A29: 5007-00 | B29: 5667 | C29: 성형-PLATE 4-5-6 CLU BKG | I29: =SUM(L29:T29) -> 0 | U29: =SUM(L29:T29) -> 0 | V29: =IF(U29=I29,"OK","NG") -> OK
A30: 5008-00 | B30: 5663 | C30: 성형-PLATE 3-5-REV CLU BKG | I30: =SUM(L30:T30) -> 0 | U30: =SUM(L30:T30) -> 0 | V30: =IF(U30=I30,"OK","NG") -> OK
A31: 5009-00 | B31: 5659 | C31: 성형-PLATE LOW & REV CLU BKG | I31: =SUM(L31:T31) -> 0 | U31: =SUM(L31:T31) -> 0 | V31: =IF(U31=I31,"OK","NG") -> OK
A32: 5010-00 | B32: 5655 | C32: 성형-WHEEL-A/TRANS INPUT SHF SPD | I32: =SUM(L32:T32) -> 0 | U32: =SUM(L32:T32) -> 0 | V32: =IF(U32=I32,"OK","NG") -> OK
A33: 5011-10 | B33: 5651 | C33: 성형-CARRIER-REACTION | I33: =SUM(L33:T33) -> 0 | U33: =SUM(L33:T33) -> 0 | V33: =IF(U33=I33,"OK","NG") -> OK
A34: 5012-10 | B34: 5643 | C34: 성형-CARRIER-INPUT | I34: =SUM(L34:T34) -> 0 | U34: =SUM(L34:T34) -> 0 | V34: =IF(U34=I34,"OK","NG") -> OK
A35: 5012-20 | B35: 11350 | C35: 성형-CARRIER-INPUT | I35: =SUM(L35:T35) -> 0 | U35: =SUM(L35:T35) -> 0 | V35: =IF(U35=I35,"OK","NG") -> OK
A36: 5013-10 | B36: 5635 | C36: 성형-CARRIER-REACTION | I36: =SUM(L36:T36) -> 0 | U36: =SUM(L36:T36) -> 0 | V36: =IF(U36=I36,"OK","NG") -> OK
A37: 5013-20 | B37: 11349 | C37: 성형-CARRIER-REACTION | I37: =SUM(L37:T37) -> 0 | U37: =SUM(L37:T37) -> 0 | V37: =IF(U37=I37,"OK","NG") -> OK
A38: 5014-10 | B38: 5627 | C38: 성형-CARRIER-INPUT | I38: =SUM(L38:T38) -> 0 | U38: =SUM(L38:T38) -> 0 | V38: =IF(U38=I38,"OK","NG") -> OK
A39: 5014-20 | B39: 11348 | C39: 성형-CARRIER-INPUT | I39: =SUM(L39:T39) -> 0 | U39: =SUM(L39:T39) -> 0 | V39: =IF(U39=I39,"OK","NG") -> OK
... A56: 6009-01 | B56: 11816 | C56: 성형-PRESSURE PLATE | I56: =SUM(L56:T56) -> 0 | U56: =SUM(L56:T56) -> 0 | V56: =IF(U56=I56,"OK","NG") -> OK
A57: 6011-10 | B57: 11381 | C57: 성형-CARRIER PALNET | I57: =SUM(L57:T57) -> 10 | M57: 10 | U57: =SUM(L57:T57) -> 10 | V57: =IF(U57=I57,"OK","NG") -> OK
A58: 6011-20 | B58: 11382 | C58: 성형-CARRIER PALNET | I58: =SUM(L58:T58) -> 0 | U58: =SUM(L58:T58) -> 0 | V58: =IF(U58=I58,"OK","NG") -> OK
A59: 6017-10 | B59: 16586 | C59: 성형-CARRIER PLANET MID | I59: =SUM(L59:T59) -> 0 | U59: =SUM(L59:T59) -> 0 | V59: =IF(U59=I59,"OK","NG") -> OK
A60: 6017-20 | B60: 16587 | C60: 성형-CARRIER PLANET MID | I60: =SUM(L60:T60) -> 0 | U60: =SUM(L60:T60) -> 0 | V60: =IF(U60=I60,"OK","NG") -> OK
A61: 6019-00 | B61: 17121 | C61: 성형-HOUSING GUIDE RING | I61: =SUM(L61:T61) -> 0 | U61: =SUM(L61:T61) -> 0 | V61: =IF(U61=I61,"OK","NG") -> OK
A62: 6020-10 | B62: 19270 | C62: 성형-CARRIER PALNET | I62: =SUM(L62:T62) -> 0 | U62: =SUM(L62:T62) -> 0 | V62: =IF(U62=I62,"OK","NG") -> OK
A63: 6020-20 | B63: 19276 | C63: 성형-CARRIER PALNET | I63: =SUM(L63:T63) -> 0 | U63: =SUM(L63:T63) -> 0 | V63: =IF(U63=I63,"OK","NG") -> OK
A64: 1914-00 | B64: 19836 | C64: 성형-MOTOR PULLEY | I64: =SUM(L64:T64) -> 0 | U64: =SUM(L64:T64) -> 0 | V64: =IF(U64=I64,"OK","NG") -> OK
...

Sheet 9
A1: 생산수량 | B1: =H69 -> 0 | E1: 불량금액 | F1: =G69 -> 0
A2: 불량수량 | B2: =I81 -> 25 | L2: =SUBTOTAL(9,L6:L80) -> 0 | M2: =SUBTOTAL(9,M6:M80) -> 25 | N2: =SUBTOTAL(9,N6:N80) -> 0 | O2: =SUBTOTAL(9,O6:O80) -> 0 | P2: =SUBTOTAL(9,P6:P80) -> 0 | Q2: =SUBTOTAL(9,Q6:Q80) -> 0 | R2: =SUBTOTAL(9,R6:R80) -> 0 | S2: =SUBTOTAL(9,S6:S80) -> 0 | ... U2: =SUBTOTAL(9,U6:U80) -> 25
A3: 불량율(ppm) | B3: =IF(ISERROR(B2/(B2+B1)*1000000),"",(B2/(B2+B1)*1000000)) -> 1000000 | L3: =SUM(L6:L80) -> 0 | M3: =SUM(M6:M80) -> 25 | N3: =SUM(N6:N80) -> 0 | O3: =SUM(O6:O80) -> 0 | P3: =SUM(P6:P80) -> 0 | Q3: =SUM(Q6:Q80) -> 0 | R3: =SUM(R6:R80) -> 0 | S3: =SUM(S6:S80) -> 0 | ... U3: =SUM(U6:U80) -> 25
A4: =V81 -> OK | E4: 거래선 및 불량금액 | H4: 종합 | L4: 형상 | M4: 시험성형 | N4: 밀도수정 | O4: CRACK 수정 | P4: 발란스 | Q4: 자동화 셋팅 | R4: 셋팅 | S4: 기타 | T4: 폐기 | U4: 합계 | V4: 오기 유/무
A5: TM NO. | B5: CODE - 성형 (ERP) | C5: 품 명 | D5: 차종 | E5: 거래선 | F5: 단가 | G5: 불량금액 (단가x수량) | H5: 생산수량 | I5: 불량수량 | J5: 불량율 (PPM)
A6: 1360-00 | B6: 8092 | C6: 성형-MOTOR PULLEY | I6: =SUM(L6:T6) -> 0 | U6: =SUM(L6:T6) -> 0 | V6: =IF(U6=I6,"OK","NG") -> OK
A7: 1361-00J | B7: 8088 | C7: 성형-BALL NUT PULLEY | I7: =SUM(L7:T7) -> 0 | U7: =SUM(L7:T7) -> 0 | V7: =IF(U7=I7,"OK","NG") -> OK
A8: 1361-01J | B8: 8081 | C8: 성형-BALL NUT PULLEY | I8: =SUM(L8:T8) -> 0 | U8: =SUM(L8:T8) -> 0 | V8: =IF(U8=I8,"OK","NG") -> OK
A9: 1361-02J | B9: 18524 | C9: 성형-BALL NUT PULLEY | I9: =SUM(L9:T9) -> 0 | U9: =SUM(L9:T9) -> 0 | V9: =IF(U9=I9,"OK","NG") -> OK
A10: 1464-00 | B10: 6234 | C10: 성형-PULLEY | I10: =SUM(L10:T10) -> 0 | U10: =SUM(L10:T10) -> 0 | V10: =IF(U10=I10,"OK","NG") -> OK
A11: 1464-01 | B11: 14830 | C11: 성형-PULLEY | I11: =SUM(L11:T11) -> 0 | U11: =SUM(L11:T11) -> 0 | V11: =IF(U11=I11,"OK","NG") -> OK
A12: 1510-00 | B12: 6004 | C12: 성형-PULLEY LARGE | I12: =SUM(L12:T12) -> 0 | U12: =SUM(L12:T12) -> 0 | V12: =IF(U12=I12,"OK","NG") -> OK
A13: 1510-01 | B13: 11857 | C13: 성형-PULLEY LARGE | I13: =SUM(L13:T13) -> 0 | U13: =SUM(L13:T13) -> 0 | V13: =IF(U13=I13,"OK","NG") -> OK
A14: 1510-02 | B14: 15004 | C14: 성형-PULLEY LARGE | I14: =SUM(L14:T14) -> 0 | U14: =SUM(L14:T14) -> 0 | V14: =IF(U14=I14,"OK","NG") -> OK
A15: 1695-00 | B15: 15174 | C15: 성형-MOTOR PULLEY | I15: =SUM(L15:T15) -> 0 | U15: =SUM(L15:T15) -> 0 | V15: =IF(U15=I15,"OK","NG") -> OK
A16: 1781-00 | B16: 15520 | C16: 성형-PULLEY | I16: =SUM(L16:T16) -> 0 | U16: =SUM(L16:T16) -> 0 | V16: =IF(U16=I16,"OK","NG") -> OK
A17: 1785-00 | B17: 14989 | C17: 성형-MOTOR PULLEY | I17: =SUM(L17:T17) -> 5 | M17: 5 | U17: =SUM(L17:T17) -> 5 | V17: =IF(U17=I17,"OK","NG") -> OK
A18: 1786-00 | B18: 14984 | C18: 성형-BALL NUT PULLEY | I18: =SUM(L18:T18) -> 0 | U18: =SUM(L18:T18) -> 0 | V18: =IF(U18=I18,"OK","NG") -> OK
A19: 1883-00 | B19: 16270 | C19: 성형-SLIDE | I19: =SUM(L19:T19) -> 0 | U19: =SUM(L19:T19) -> 0 | V19: =IF(U19=I19,"OK","NG") -> OK
A20: 1903-00 | B20: 19060 | C20: 성형-PULLEY | I20: =SUM(L20:T20) -> 0 | U20: =SUM(L20:T20) -> 0 | V20: =IF(U20=I20,"OK","NG") -> OK
A21: 1935-00 | B21: 18828 | C21: 성형-Driven Pulley | I21: =SUM(L21:T21) -> 0 | U21: =SUM(L21:T21) -> 0 | V21: =IF(U21=I21,"OK","NG") -> OK
A22: 5001-00 | B22: 5695 | C22: 성형-PLATE 1-2-3-4 CLU BKG | I22: =SUM(L22:T22) -> 0 | U22: =SUM(L22:T22) -> 0 | V22: =IF(U22=I22,"OK","NG") -> OK
A23: 5002-00 | B23: 5691 | C23: 성형-PLATE 4-5-6 CLU BKG | I23: =SUM(L23:T23) -> 0 | U23: =SUM(L23:T23) -> 0 | V23: =IF(U23=I23,"OK","NG") -> OK
A24: 5003-00 | B24: 5687 | C24: 성형-PLATE 3-5-REV CLU BKG | I24: =SUM(L24:T24) -> 0 | U24: =SUM(L24:T24) -> 0 | V24: =IF(U24=I24,"OK","NG") -> OK
A25: 5003-01 | B25: 5683 | C25: 성형-PLATE 3-5-REV CLU BKG | I25: =SUM(L25:T25) -> 0 | U25: =SUM(L25:T25) -> 0 | V25: =IF(U25=I25,"OK","NG") -> OK
A26: 5004-00 | B26: 5679 | C26: 성형-PLATE LOW & REV CLU BKG | I26: =SUM(L26:T26) -> 0 | U26: =SUM(L26:T26) -> 0 | V26: =IF(U26=I26,"OK","NG") -> OK
A27: 5005-00 | B27: 5675 | C27: 성형-WHEEL-A/TRANS INPUT SHF SPD SEN RELUCTOR | I27: =SUM(L27:T27) -> 3 | M27: 3 | U27: =SUM(L27:T27) -> 3 | V27: =IF(U27=I27,"OK","NG") -> OK
A28: 5006-00 | B28: 5671 | C28: 성형-PLATE 1-2-3-4 CLU BKG | I28: =SUM(L28:T28) -> 0 | U28: =SUM(L28:T28) -> 0 | V28: =IF(U28=I28,"OK","NG") -> OK
A29: 5007-00 | B29: 5667 | C29: 성형-PLATE 4-5-6 CLU BKG | I29: =SUM(L29:T29) -> 0 | U29: =SUM(L29:T29) -> 0 | V29: =IF(U29=I29,"OK","NG") -> OK
A30: 5008-00 | B30: 5663 | C30: 성형-PLATE 3-5-REV CLU BKG | I30: =SUM(L30:T30) -> 0 | U30: =SUM(L30:T30) -> 0 | V30: =IF(U30=I30,"OK","NG") -> OK
A31: 5009-00 | B31: 5659 | C31: 성형-PLATE LOW & REV CLU BKG | I31: =SUM(L31:T31) -> 0 | U31: =SUM(L31:T31) -> 0 | V31: =IF(U31=I31,"OK","NG") -> OK
A32: 5010-00 | B32: 5655 | C32: 성형-WHEEL-A/TRANS INPUT SHF SPD | I32: =SUM(L32:T32) -> 0 | U32: =SUM(L32:T32) -> 0 | V32: =IF(U32=I32,"OK","NG") -> OK
A33: 5011-10 | B33: 5651 | C33: 성형-CARRIER-REACTION | I33: =SUM(L33:T33) -> 0 | U33: =SUM(L33:T33) -> 0 | V33: =IF(U33=I33,"OK","NG") -> OK
A34: 5012-10 | B34: 5643 | C34: 성형-CARRIER-INPUT | I34: =SUM(L34:T34) -> 0 | U34: =SUM(L34:T34) -> 0 | V34: =IF(U34=I34,"OK","NG") -> OK
A35: 5012-20 | B35: 11350 | C35: 성형-CARRIER-INPUT | I35: =SUM(L35:T35) -> 0 | U35: =SUM(L35:T35) -> 0 | V35: =IF(U35=I35,"OK","NG") -> OK
A36: 5013-10 | B36: 5635 | C36: 성형-CARRIER-REACTION | I36: =SUM(L36:T36) -> 0 | U36: =SUM(L36:T36) -> 0 | V36: =IF(U36=I36,"OK","NG") -> OK
A37: 5013-20 | B37: 11349 | C37: 성형-CARRIER-REACTION | I37: =SUM(L37:T37) -> 0 | U37: =SUM(L37:T37) -> 0 | V37: =IF(U37=I37,"OK","NG") -> OK
A38: 5014-10 | B38: 5627 | C38: 성형-CARRIER-INPUT | I38: =SUM(L38:T38) -> 0 | U38: =SUM(L38:T38) -> 0 | V38: =IF(U38=I38,"OK","NG") -> OK
A39: 5014-20 | B39: 11348 | C39: 성형-CARRIER-INPUT | I39: =SUM(L39:T39) -> 0 | U39: =SUM(L39:T39) -> 0 | V39: =IF(U39=I39,"OK","NG") -> OK
... A59: 6017-10 | B59: 16586 | C59: 성형-CARRIER PLANET MID | I59: =SUM(L59:T59) -> 0 | U59: =SUM(L59:T59) -> 0 | V59: =IF(U59=I59,"OK","NG") -> OK
...

Sheet 10
A1: 생산수량 | B1: =H69 -> 0 | E1: 불량금액 | F1: =G69 -> 0
A2: 불량수량 | B2: =I81 -> 10 | L2: =SUBTOTAL(9,L6:L80) -> 0 | M2: =SUBTOTAL(9,M6:M80) -> 10 | N2: =SUBTOTAL(9,N6:N80) -> 0 | O2: =SUBTOTAL(9,O6:O80) -> 0 | P2: =SUBTOTAL(9,P6:P80) -> 0 | Q2: =SUBTOTAL(9,Q6:Q80) -> 0 | R2: =SUBTOTAL(9,R6:R80) -> 0 | S2: =SUBTOTAL(9,S6:S80) -> 0 | ... U2: =SUBTOTAL(9,U6:U80) -> 10
A3: 불량율(ppm) | B3: =IF(ISERROR(B2/(B2+B1)*1000000),"",(B2/(B2+B1)*1000000)) -> 1000000 | L3: =SUM(L6:L80) -> 0 | M3: =SUM(M6:M80) -> 10 | N3: =SUM(N6:N80) -> 0 | O3: =SUM(O6:O80) -> 0 | P3: =SUM(P6:P80) -> 0 | Q3: =SUM(Q6:Q80) -> 0 | R3: =SUM(R6:R80) -> 0 | S3: =SUM(S6:S80) -> 0 | ... U3: =SUM(U6:U80) -> 10
A4: =V81 -> OK | E4: 거래선 및 불량금액 | H4: 종합 | L4: 형상 | M4: 시험성형 | N4: 밀도수정 | O4: CRACK 수정 | P4: 발란스 | Q4: 자동화 셋팅 | R4: 셋팅 | S4: 기타 | T4: 폐기 | U4: 합계 | V4: 오기 유/무
A5: TM NO. | B5: CODE - 성형 (ERP) | C5: 품 명 | D5: 차종 | E5: 거래선 | F5: 단가 | G5: 불량금액 (단가x수량) | H5: 생산수량 | I5: 불량수량 | J5: 불량율 (PPM)
A6: 1360-00 | B6: 8092 | C6: 성형-MOTOR PULLEY | I6: =SUM(L6:T6) -> 0 | U6: =SUM(L6:T6) -> 0 | V6: =IF(U6=I6,"OK","NG") -> OK
A7: 1361-00J | B7: 8088 | C7: 성형-BALL NUT PULLEY | I7: =SUM(L7:T7) -> 0 | U7: =SUM(L7:T7) -> 0 | V7: =IF(U7=I7,"OK","NG") -> OK
A8: 1361-01J | B8: 8081 | C8: 성형-BALL NUT PULLEY | I8: =SUM(L8:T8) -> 0 | U8: =SUM(L8:T8) -> 0 | V8: =IF(U8=I8,"OK","NG") -> OK
A9: 1361-02J | B9: 18524 | C9: 성형-BALL NUT PULLEY | I9: =SUM(L9:T9) -> 0 | U9: =SUM(L9:T9) -> 0 | V9: =IF(U9=I9,"OK","NG") -> OK
A10: 1464-00 | B10: 6234 | C10: 성형-PULLEY | I10: =SUM(L10:T10) -> 0 | U10: =SUM(L10:T10) -> 0 | V10: =IF(U10=I10,"OK","NG") -> OK
A11: 1464-01 | B11: 14830 | C11: 성형-PULLEY | I11: =SUM(L11:T11) -> 0 | U11: =SUM(L11:T11) -> 0 | V11: =IF(U11=I11,"OK","NG") -> OK
A12: 1510-00 | B12: 6004 | C12: 성형-PULLEY LARGE | I12: =SUM(L12:T12) -> 0 | U12: =SUM(L12:T12) -> 0 | V12: =IF(U12=I12,"OK","NG") -> OK
A13: 1510-01 | B13: 11857 | C13: 성형-PULLEY LARGE | I13: =SUM(L13:T13) -> 0 | U13: =SUM(L13:T13) -> 0 | V13: =IF(U13=I13,"OK","NG") -> OK
A14: 1510-02 | B14: 15004 | C14: 성형-PULLEY LARGE | I14: =SUM(L14:T14) -> 0 | U14: =SUM(L14:T14) -> 0 | V14: =IF(U14=I14,"OK","NG") -> OK
A15: 1695-00 | B15: 15174 | C15: 성형-MOTOR PULLEY | I15: =SUM(L15:T15) -> 0 | U15: =SUM(L15:T15) -> 0 | V15: =IF(U15=I15,"OK","NG") -> OK
A16: 1781-00 | B16: 15520 | C16: 성형-PULLEY | I16: =SUM(L16:T16) -> 0 | U16: =SUM(L16:T16) -> 0 | V16: =IF(U16=I16,"OK","NG") -> OK
A17: 1785-00 | B17: 14989 | C17: 성형-MOTOR PULLEY | I17: =SUM(L17:T17) -> 0 | U17: =SUM(L17:T17) -> 0 | V17: =IF(U17=I17,"OK","NG") -> OK
... A62: 6020-10 | B62: 19270 | C62: 성형-CARRIER PALNET | I62: =SUM(L62:T62) -> 0 | U62: =SUM(L62:T62) -> 0 | V62: =IF(U62=I62,"OK","NG") -> OK
A63: 6020-20 | B63: 19276 | C63: 성형-CARRIER PALNET | I63: =SUM(L63:T63) -> 10 | M63: 10 | U63: =SUM(L63:T63) -> 10 | V63: =IF(U63=I63,"OK","NG") -> OK
A64: 1914-00 | B64: 19836 | C64: 성형-MOTOR PULLEY | I64: =SUM(L64:T64) -> 0 | U64: =SUM(L64:T64) -> 0 | V64: =IF(U64=I64,"OK","NG") -> OK
A65: 1987-00J | B65: 20278 | C65: 성형-BELT PULLEY | I65: =SUM(L65:T65) -> 0 | U65: =SUM(L65:T65) -> 0 | V65: =IF(U65=I65,"OK","NG") -> OK
A66: 1986-00 | B66: 20272 | C66: 성형-BELT PULLEY | I66: =SUM(L66:T66) -> 0 | U66: =SUM(L66:T66) -> 0 | V66: =IF(U66=I66,"OK","NG") -> OK
A67: 2059-00 | B67: 20956 | C67: 성형-BELT PULLEY | I67: =SUM(L67:T67) -> 0 | U67: =SUM(L67:T67) -> 0 | V67: =IF(U67=I67,"OK","NG") -> OK
A68: 6023-10 | B68: 21299 | C68: 성형-CARRIER PLANET MID | I68: =SUM(L68:T68) -> 0 | U68: =SUM(L68:T68) -> 0 | V68: =IF(U68=I68,"OK","NG") -> OK
A69: 2140-00 | B69: 22115 | C69: 성형-CAM PLATE | I69: =SUM(L69:T69) -> 0 | U69: =SUM(L69:T69) -> 0 | V69: =IF(U69=I69,"OK","NG") -> OK
A70: 6027-10 | B70: 22706 | C70: 성형-SUB ASSY-CARRIER PLANET, MID&RR | I70: =SUM(L70:T70) -> 0 | U70: =SUM(L70:T70) -> 0 | V70: =IF(U70=I70,"OK","NG") -> OK
A71: 2206-00 | B71: 22886 | C71: 성형-BALL NUT PULLEY | I71: =SUM(L71:T71) -> 0 | U71: =SUM(L71:T71) -> 0 | V71: =IF(U71=I71,"OK","NG") -> OK
A72: 1676-00 | B72: 17528 | C72: 성형-CAM APPLY | I72: =SUM(L72:T72) -> 0 | U72: =SUM(L72:T72) -> 0 | V72: =IF(U72=I72,"OK","NG") -> OK
A73: 2202-00 | B73: 22380 | C73: 성형-PULLEY | I73: =SUM(L73:T73) -> 0 | U73: =SUM(L73:T73) -> 0 | V73: =IF(U73=I73,"OK","NG") -> OK
A74: 1948-00 | B74: 19279 | C74: 성형-Flange | I74: =SUM(L74:T74) -> 0 | U74: =SUM(L74:T74) -> 0 | V74: =IF(U74=I74,"OK","NG") -> OK
A75: 6026-10 | B75: 22724 | C75: 성형-SUB ASSY-CARRIER PLANET, MID&RR | I75: 0 | U75: 0 | V75: OK
A76: 6027-20 | B76: 22705 | C76: 성형-SUB ASSY-CARRIER PLANET, MID&RR | I76: =SUM(L76:T76) -> 0 | U76: =SUM(L76:T76) -> 0 | V76: =IF(U76=I76,"OK","NG") -> OK
A77: 5010-00 | B77: 5655 | C77: 성형-WHEEL-A/TRANS INPUT SHF SPD | I77: =SUM(L77:T77) -> 0 | U77: =SUM(L77:T77) -> 0 | V77: =IF(U77=I77,"OK","NG") -> OK
A78: 6027-30 | B78: 22704 | C78: 성형-SUB ASSY-CARRIER PLANET, MID&RR | I78: =SUM(L78:T78) -> 0 | U78: =SUM(L78:T78) -> 0 | V78: =IF(U78=I78,"OK","NG") -> OK
A79: 6026-30 | B79: 22722 | C79: 성형-SUB ASSY-CARRIER PLANET, MID&RR | I79: =SUM(L79:T79) -> 0 | U79: =SUM(L79:T79) -> 0 | V79: =IF(U79=I79,"OK","NG") -> OK
A80: 6026-20 | B80: 22723 | C80: 성형-SUB ASSY-CARRIER PLANET, MID&RR | I80: =SUM(L80:T80) -> 0 | U80: =SUM(L80:T80) -> 0 | V80: =IF(U80=I80,"OK","NG") -> OK
C81: 소계 SUBTOTAL(가로) | G81: =SUM(G6:G49) -> 0 | H81: =SUM(H6:H49) -> 0 | I81: =SUM(I6:I80) -> 10 | J81: =SUM(J6:J49) -> 0 | K81: =SUM(K6:K51) -> 0 | L81: =SUM(L6:L80) -> 0 | M81: =SUM(M6:M80) -> 10 | N81: =SUM(N6:N80) -> 0 | O81: =SUM(O6:O80) -> 0 | P81: =SUM(P6:P80) -> 0 | Q81: =SUM(Q6:Q80) -> 0 | R81: =SUM(R6:R80) -> 0 | S81: =SUM(S6:S80) -> 0 | ... U81: =SUM(U6:U80) -> 10 | V81: =IF(U81=SUM(I81),"OK","NG") -> OK

Sheet 11
A1: 생산수량 | B1: =H81 -> 0 | E1: 불량금액 | F1: =G81 -> 0
A2: 불량수량 | B2: =I81 -> 0 | L2: =SUBTOTAL(9,L6:L80) -> 0 | M2: =SUBTOTAL(9,M6:M80) -> 0 | N2: =SUBTOTAL(9,N6:N80) -> 0 | O2: =SUBTOTAL(9,O6:O80) -> 0 | P2: =SUBTOTAL(9,P6:P80) -> 0 | Q2: =SUBTOTAL(9,Q6:Q80) -> 0 | R2: =SUBTOTAL(9,R6:R80) -> 0 | S2: =SUBTOTAL(9,S6:S80) -> 0 | ... U2: =SUBTOTAL(9,U6:U80) -> 0
A3: 불량율(ppm) | B3: =IF(ISERROR(B2/(B2+B1)*1000000),"",(B2/(B2+B1)*1000000)) | L3: =SUM(L6:L80) -> 0 | M3: =SUM(M6:M80) -> 0 | N3: =SUM(N6:N80) -> 0 | O3: =SUM(O6:O80) -> 0 | P3: =SUM(P6:P80) -> 0 | Q3: =SUM(Q6:Q80) -> 0 | R3: =SUM(R6:R80) -> 0 | S3: =SUM(S6:S80) -> 0 | ... U3: =SUM(U6:U80) -> 0
A4: =V81 -> OK | E4: 거래선 및 불량금액 | H4: 종합 | L4: 형상 | M4: 시험성형 | N4: 밀도수정 | O4: CRACK 수정 | P4: 발란스 | Q4: 자동화 셋팅 | R4: 셋팅 | S4: 기타 | T4: 폐기 | U4: 합계 | V4: 오기 유/무
A5: TM NO. | B5: CODE - 성형 (ERP) | C5: 품 명 | D5: 차종 | E5: 거래선 | F5: 단가 | G5: 불량금액 (단가x수량) | H5: 생산수량 | I5: 불량수량 | J5: 불량율 (PPM)
A6: 1360-00 | B6: 8092 | C6: 성형-MOTOR PULLEY | I6: =SUM(L6:T6) -> 0 | U6: =SUM(L6:T6) -> 0 | V6: =IF(U6=I6,"OK","NG") -> OK
A7: 1361-00J | B7: 8088 | C7: 성형-BALL NUT PULLEY | I7: =SUM(L7:T7) -> 0 | U7: =SUM(L7:T7) -> 0 | V7: =IF(U7=I7,"OK","NG") -> OK
A8: 1361-01J | B8: 8081 | C8: 성형-BALL NUT PULLEY | I8: =SUM(L8:T8) -> 0 | U8: =SUM(L8:T8) -> 0 | V8: =IF(U8=I8,"OK","NG") -> OK
A9: 1361-02J | B9: 18524 | C9: 성형-BALL NUT PULLEY | I9: =SUM(L9:T9) -> 0 | U9: =SUM(L9:T9) -> 0 | V9: =IF(U9=I9,"OK","NG") -> OK
A10: 1464-00 | B10: 6234 | C10: 성형-PULLEY | I10: =SUM(L10:T10) -> 0 | U10: =SUM(L10:T10) -> 0 | V10: =IF(U10=I10,"OK","NG") -> OK
A11: 1464-01 | B11: 14830 | C11: 성형-PULLEY | I11: =SUM(L11:T11) -> 0 | U11: =SUM(L11:T11) -> 0 | V11: =IF(U11=I11,"OK","NG") -> OK
A12: 1510-00 | B12: 6004 | C12: 성형-PULLEY LARGE | I12: =SUM(L12:T12) -> 0 | U12: =SUM(L12:T12) -> 0 | V12: =IF(U12=I12,"OK","NG") -> OK
A13: 1510-01 | B13: 11857 | C13: 성형-PULLEY LARGE | I13: =SUM(L13:T13) -> 0 | U13: =SUM(L13:T13) -> 0 | V13: =IF(U13=I13,"OK","NG") -> OK
A14: 1510-02 | B14: 15004 | C14: 성형-PULLEY LARGE | I14: =SUM(L14:T14) -> 0 | U14: =SUM(L14:T14) -> 0 | V14: =IF(U14=I14,"OK","NG") -> OK
A15: 1695-00 | B15: 15174 | C15: 성형-MOTOR PULLEY | I15: =SUM(L15:T15) -> 0 | U15: =SUM(L15:T15) -> 0 | V15: =IF(U15=I15,"OK","NG") -> OK
A16: 1781-00 | B16: 15520 | C16: 성형-PULLEY | I16: =SUM(L16:T16) -> 0 | U16: =SUM(L16:T16) -> 0 | V16: =IF(U16=I16,"OK","NG") -> OK
A17: 1785-00 | B17: 14989 | C17: 성형-MOTOR PULLEY | I17: =SUM(L17:T17) -> 0 | U17: =SUM(L17:T17) -> 0 | V17: =IF(U17=I17,"OK","NG") -> OK
... A74: 1948-00 | B74: 19279 | C74: 성형-Flange | I74: =SUM(L74:T74) -> 0 | U74: =SUM(L74:T74) -> 0 | V74: =IF(U74=I74,"OK","NG") -> OK
A75: 6026-10 | B75: 22724 | C75: 성형-SUB ASSY-CARRIER PLANET, MID&RR | I75: 0 | U75: 0 | V75: OK
A76: 6027-20 | B76: 22705 | C76: 성형-SUB ASSY-CARRIER PLANET, MID&RR | I76: =SUM(L76:T76) -> 0 | U76: =SUM(L76:T76) -> 0 | V76: =IF(U76=I76,"OK","NG") -> OK
A77: 5010-00 | B77: 5655 | C77: 성형-WHEEL-A/TRANS INPUT SHF SPD | I77: =SUM(L77:T77) -> 0 | U77: =SUM(L77:T77) -> 0 | V77: =IF(U77=I77,"OK","NG") -> OK
A78: 6027-30 | B78: 22704 | C78: 성형-SUB ASSY-CARRIER PLANET, MID&RR | I78: =SUM(L78:T78) -> 0 | U78: =SUM(L78:T78) -> 0 | V78: =IF(U78=I78,"OK","NG") -> OK
A79: 6026-30 | B79: 22722 | C79: 성형-SUB ASSY-CARRIER PLANET, MID&RR | I79: =SUM(L79:T79) -> 0 | U79: =SUM(L79:T79) -> 0 | V79: =IF(U79=I79,"OK","NG") -> OK
A80: 6026-20 | B80: 22723 | C80: 성형-SUB ASSY-CARRIER PLANET, MID&RR | I80: =SUM(L80:T80) -> 0 | U80: =SUM(L80:T80) -> 0 | V80: =IF(U80=I80,"OK","NG") -> OK
