Workbook

Sheet Rev.History
B2: ※ 개정 이력 관리 ※
B4: No. | C4: 개정내용 | D4: 개정담당 | E4: 개정일자
B5: 1 | C5: 19년 단가정보 불량 산정 기준(지침서 : SP05-01)의거 정리본 신규제정 | D5: 박민호DR | E5: 2019.01.03
B6: 2 | C6: 신규품목 단가정보 업데이트 | D6: 박민호DR | E6: 2019.02.08
B7: 3 | C7: 신규품목 단가정보 업데이트 | D7: 박민호DR | E7: 2019.04.01
B8: 4 | C8: 신규품목 단가정보 업데이트 | D8: 박민호DR | E8: 2019.05.02
B9: 5 | C9: 신규품목 단가정보 업데이트 | D9: 박민호DR | E9: 2019.05.30
B10: 6 | C10: 신규품목 단가정보 업데이트 | D10: 박민호DR | E10: 2019.07.01
B11: 7 | C11: 신규품목 단가정보 업데이트 | D11: 박민호DR | E11: 2019.08.02
B12: 8 | C12: 신규품목 단가정보 업데이트 | D12: 박민호DR | E12: 2019.10.02
B13: 9 | C13: 신규품목 단가정보 업데이트 | D13: 박민호DR | E13: 2019.11.28
B14: 10 | C14: 신규품목 단가정보 업데이트 | D14: 박민호DR | E14: 2019.12.03
B15: 11 | C15: 정형공정 단가오류 수정 | D15: 박민호DR | E15: 2020.01.03
B16: 12 | C16: 신규품목 단가정보 업데이트 | D16: 박민호DR | E16: 2020.01.31
... B27: 23 | C27: FY24 정기개정 전체 품번별 단가 업데이트 | D27: 박민호CM | E27: 2024.04.23

Sheet 단가산출
A1: <FY25 Q-COST 산출용 공정별 단가정보> | E1: -.최초 제정 : 181231 | H1: -.최근개정 : 240604 | N1: ERP 완제품 단가정보 업데이트 CELL | R1: 정형공정 적용유무 DB | V1: O
B2: 성형품 | F2: 소결품~ | J2: 정형품~ | N2: 완제품 | R2: 정형N/A | U2: 1part 평균단가 | V2: 435 | W2: <전공정 적용
B3: TM No. | C3: 품종 | D3: 단가\ | F3: TM No. | G3: 품종 | H3: 단가\ | J3: TM No. | K3: 품종 | L3: 단가\ | N3: TM No. | O3: 품종 | P3: 단가\ | R3: TM No. | S3: 단가\ | T3: N/A여부 | U3: 2part Carrier평균 | V3: 9479 | W3: <전공정 적용
B4: =+N4 -> 614-05 | C4: =+O4 -> GAS SPRING PISTON | D4: =+IF(L4=$V$1,P4*0.6,P4*0.5) -> 9 | F4: =+N4 -> 614-05 | G4: =+O4 -> GAS SPRING PISTON | H4: =IF(T4=$V$1,P4*0.8,P4*0.6) -> 10.8 | J4: =+R4 -> 614-05 | K4: =+O4 -> GAS SPRING PISTON | L4: =T4 -> 14.4 | N4: 614-05 | O4: GAS SPRING PISTON | P4: 18 | R4: =+N4 -> 614-05 | S4: =VLOOKUP(R4,'정형공정 적용리스트'!$A:$D,3,FALSE) -> 18 | T4: =IF(S4>0,S4*0.8,"O") -> 14.4 | U4: 2part Pulley평균 | V4: 2645 | W4: <전공정 적용
B5: =+N5 -> 1262-00 | C5: =+O5 -> LATCH | D5: =+IF(L5=$V$1,P5*0.6,P5*0.5) -> 15.6 | F5: =+N5 -> 1262-00 | G5: =+O5 -> LATCH | H5: =IF(T5=$V$1,P5*0.8,P5*0.6) -> 20.8 | J5: =+R5 -> 1262-00 | K5: =+O5 -> LATCH | L5: =T5 -> O | N5: 1262-00 | O5: LATCH | P5: 26 | R5: =+N5 -> 1262-00 | S5: =VLOOKUP(R5,'정형공정 적용리스트'!$A:$D,3,FALSE) -> #N/A | T5: O
B6: =+N6 -> 433-00 | C6: =+O6 -> CHECK VALVE | D6: =+IF(L6=$V$1,P6*0.6,P6*0.5) -> 16.2 | F6: =+N6 -> 433-00 | G6: =+O6 -> CHECK VALVE | H6: =IF(T6=$V$1,P6*0.8,P6*0.6) -> 21.6 | J6: =+R6 -> 433-00 | K6: =+O6 -> CHECK VALVE | L6: =T6 -> O | N6: 433-00 | O6: CHECK VALVE | P6: 27 | R6: =+N6 -> 433-00 | S6: =VLOOKUP(R6,'정형공정 적용리스트'!$A:$D,3,FALSE) -> #N/A | T6: O
B7: =+N7 -> 369-00 | C7: =+O7 -> V/V PLATE | D7: =+IF(L7=$V$1,P7*0.6,P7*0.5) -> 20.4 | F7: =+N7 -> 369-00 | G7: =+O7 -> V/V PLATE | H7: =IF(T7=$V$1,P7*0.8,P7*0.6) -> 27.2 | J7: =+R7 -> 369-00 | K7: =+O7 -> V/V PLATE | L7: =T7 -> O | N7: 369-00 | O7: V/V PLATE | P7: 34 | R7: =+N7 -> 369-00 | S7: =VLOOKUP(R7,'정형공정 적용리스트'!$A:$D,3,FALSE) -> #N/A | T7: O
B8: =+N8 -> 014-00 | C8: =+O8 -> RETAINER GUIDE | D8: =+IF(L8=$V$1,P8*0.6,P8*0.5) -> 17.5 | F8: =+N8 -> 014-00 | G8: =+O8 -> RETAINER GUIDE | H8: =IF(T8=$V$1,P8*0.8,P8*0.6) -> 21 | J8: =+R8 -> 014-00 | K8: =+O8 -> RETAINER GUIDE | L8: =T8 -> 28 | N8: 014-00 | O8: RETAINER GUIDE | P8: 35 | R8: =+N8 -> 014-00 | S8: =VLOOKUP(R8,'정형공정 적용리스트'!$A:$D,3,FALSE) -> 35 | T8: =IF(S8>0,S8*0.8,"O") -> 28
B9: =+N9 -> 229-00 | C9: =+O9 -> RETAINER GUIDE | D9: =+IF(L9=$V$1,P9*0.6,P9*0.5) -> 19 | F9: =+N9 -> 229-00 | G9: =+O9 -> RETAINER GUIDE | H9: =IF(T9=$V$1,P9*0.8,P9*0.6) -> 22.8 | J9: =+R9 -> 229-00 | K9: =+O9 -> RETAINER GUIDE | L9: =T9 -> 30.4 | N9: 229-00 | O9: RETAINER GUIDE | P9: 38 | R9: =+N9 -> 229-00 | S9: =VLOOKUP(R9,'정형공정 적용리스트'!$A:$D,3,FALSE) -> 38 | T9: =IF(S9>0,S9*0.8,"O") -> 30.4
B10: =+N10 -> 940-00 | C10: =+O10 -> PLANE WASHER | D10: =+IF(L10=$V$1,P10*0.6,P10*0.5) -> 24.6 | F10: =+N10 -> 940-00 | G10: =+O10 -> PLANE WASHER | H10: =IF(T10=$V$1,P10*0.8,P10*0.6) -> 32.8 | J10: =+R10 -> 940-00 | K10: =+O10 -> PLANE WASHER | L10: =T10 -> O | N10: 940-00 | O10: PLANE WASHER | P10: 41 | R10: =+N10 -> 940-00 | S10: =VLOOKUP(R10,'정형공정 적용리스트'!$A:$D,3,FALSE) -> #N/A | T10: O
B11: =+N11 -> 435-00 | C11: =+O11 -> ROTARY VALVE(B) | D11: =+IF(L11=$V$1,P11*0.6,P11*0.5) -> 27 | F11: =+N11 -> 435-00 | G11: =+O11 -> ROTARY VALVE(B) | H11: =IF(T11=$V$1,P11*0.8,P11*0.6) -> 36 | J11: =+R11 -> 435-00 | K11: =+O11 -> ROTARY VALVE(B) | L11: =T11 -> O | N11: 435-00 | O11: ROTARY VALVE(B) | P11: 45 | R11: =+N11 -> 435-00 | S11: =VLOOKUP(R11,'정형공정 적용리스트'!$A:$D,3,FALSE) -> #N/A | T11: O
B12: =+N12 -> 016-00 | C12: =+O12 -> RETAINER GUIDE | D12: =+IF(L12=$V$1,P12*0.6,P12*0.5) -> 23 | F12: =+N12 -> 016-00 | G12: =+O12 -> RETAINER GUIDE | H12: =IF(T12=$V$1,P12*0.8,P12*0.6) -> 27.6 | J12: =+R12 -> 016-00 | K12: =+O12 -> RETAINER GUIDE | L12: =T12 -> 36.8 | N12: 016-00 | O12: RETAINER GUIDE | P12: 46 | R12: =+N12 -> 016-00 | S12: =VLOOKUP(R12,'정형공정 적용리스트'!$A:$D,3,FALSE) -> 46 | T12: =IF(S12>0,S12*0.8,"O") -> 36.8
B13: =+N13 -> 016-00 | C13: =+O13 -> RETAINER GUIDE | D13: =+IF(L13=$V$1,P13*0.6,P13*0.5) -> 23 | F13: =+N13 -> 016-00 | G13: =+O13 -> RETAINER GUIDE | H13: =IF(T13=$V$1,P13*0.8,P13*0.6) -> 27.6 | J13: =+R13 -> 016-00 | K13: =+O13 -> RETAINER GUIDE | L13: =T13 -> 36.8 | N13: 016-00 | O13: RETAINER GUIDE | P13: 46 | R13: =+N13 -> 016-00 | S13: =VLOOKUP(R13,'정형공정 적용리스트'!$A:$D,3,FALSE) -> 46 | T13: =IF(S13>0,S13*0.8,"O") -> 36.8
B14: =+N14 -> 242-01 | C14: =+O14 -> GAS SPRING PISTON | D14: =+IF(L14=$V$1,P14*0.6,P14*0.5) -> 23.5 | F14: =+N14 -> 242-01 | G14: =+O14 -> GAS SPRING PISTON | H14: =IF(T14=$V$1,P14*0.8,P14*0.6) -> 28.2 | J14: =+R14 -> 242-01 | K14: =+O14 -> GAS SPRING PISTON | L14: =T14 -> 37.6 | N14: 242-01 | O14: GAS SPRING PISTON | P14: 47 | R14: =+N14 -> 242-01 | S14: =VLOOKUP(R14,'정형공정 적용리스트'!$A:$D,3,FALSE) -> 47 | T14: =IF(S14>0,S14*0.8,"O") -> 37.6
B15: =+N15 -> 604-00 | C15: =+O15 -> COLLAR | D15: =+IF(L15=$V$1,P15*0.6,P15*0.5) -> 28.2 | F15: =+N15 -> 604-00 | G15: =+O15 -> COLLAR | H15: =IF(T15=$V$1,P15*0.8,P15*0.6) -> 37.6 | J15: =+R15 -> 604-00 | K15: =+O15 -> COLLAR | L15: =T15 -> O | N15: 604-00 | O15: COLLAR | P15: 47 | R15: =+N15 -> 604-00 | S15: =VLOOKUP(R15,'정형공정 적용리스트'!$A:$D,3,FALSE) -> #N/A | T15: O
B16: =+N16 -> 016-00 | C16: =+O16 -> RETAINER GUIDE | D16: =+IF(L16=$V$1,P16*0.6,P16*0.5) -> 23 | F16: =+N16 -> 016-00 | G16: =+O16 -> RETAINER GUIDE | H16: =IF(T16=$V$1,P16*0.8,P16*0.6) -> 27.6 | J16: =+R16 -> 016-00 | K16: =+O16 -> RETAINER GUIDE | L16: =T16 -> 36.8 | N16: 016-00 | O16: RETAINER GUIDE | P16: 46 | R16: =+N16 -> 016-00 | S16: =VLOOKUP(R16,'정형공정 적용리스트'!$A:$D,3,FALSE) -> 46 | T16: =IF(S16>0,S16*0.8,"O") -> 36.8
B17: =+N17 -> 316-00 | C17: =+O17 -> NUT ADJUSTER(LH) | D17: =+IF(L17=$V$1,P17*0.6,P17*0.5) -> 31.2 | F17: =+N17 -> 316-00 | G17: =+O17 -> NUT ADJUSTER(LH) | H17: =IF(T17=$V$1,P17*0.8,P17*0.6) -> 41.6 | J17: =+R17 -> 316-00 | K17: =+O17 -> NUT ADJUSTER(LH) | L17: =T17 -> O | N17: 316-00 | O17: NUT ADJUSTER(LH) | P17: 52 | R17: =+N17 -> 316-00 | S17: =VLOOKUP(R17,'정형공정 적용리스트'!$A:$D,3,FALSE) -> #N/A | T17: O
B18: =+N18 -> 317-00 | C18: =+O18 -> NUT ADJUSTER(RH) | D18: =+IF(L18=$V$1,P18*0.6,P18*0.5) -> 31.2 | F18: =+N18 -> 317-00 | G18: =+O18 -> NUT ADJUSTER(RH) | H18: =IF(T18=$V$1,P18*0.8,P18*0.6) -> 41.6 | J18: =+R18 -> 317-00 | K18: =+O18 -> NUT ADJUSTER(RH) | L18: =T18 -> O | N18: 317-00 | O18: NUT ADJUSTER(RH) | P18: 52 | R18: =+N18 -> 317-00 | S18: =VLOOKUP(R18,'정형공정 적용리스트'!$A:$D,3,FALSE) -> #N/A | T18: O
B19: =+N19 -> 426-00 | C19: =+O19 -> COMP,RETAINER | D19: =+IF(L19=$V$1,P19*0.6,P19*0.5) -> 26.5 | F19: =+N19 -> 426-00 | G19: =+O19 -> COMP,RETAINER | H19: =IF(T19=$V$1,P19*0.8,P19*0.6) -> 31.8 | J19: =+R19 -> 426-00 | K19: =+O19 -> COMP,RETAINER | L19: =T19 -> 42.4 | N19: 426-00 | O19: COMP,RETAINER | P19: 53 | R19: =+N19 -> 426-00 | S19: =VLOOKUP(R19,'정형공정 적용리스트'!$A:$D,3,FALSE) -> 53 | T19: =IF(S19>0,S19*0.8,"O") -> 42.4
B20: =+N20 -> 428-01 | C20: =+O20 -> COMP,RETAINER | D20: =+IF(L20=$V$1,P20*0.6,P20*0.5) -> 26.5 | F20: =+N20 -> 428-01 | G20: =+O20 -> COMP,RETAINER | H20: =IF(T20=$V$1,P20*0.8,P20*0.6) -> 31.8 | J20: =+R20 -> 428-01 | K20: =+O20 -> COMP,RETAINER | L20: =T20 -> 42.4 | N20: 428-01 | O20: COMP,RETAINER | P20: 53 | R20: =+N20 -> 428-01 | S20: =VLOOKUP(R20,'정형공정 적용리스트'!$A:$D,3,FALSE) -> 53 | T20: =IF(S20>0,S20*0.8,"O") -> 42.4
B21: =+N21 -> 426-00 | C21: =+O21 -> COMP,RETAINER | D21: =+IF(L21=$V$1,P21*0.6,P21*0.5) -> 26.5 | F21: =+N21 -> 426-00 | G21: =+O21 -> COMP,RETAINER | H21: =IF(T21=$V$1,P21*0.8,P21*0.6) -> 31.8 | J21: =+R21 -> 426-00 | K21: =+O21 -> COMP,RETAINER | L21: =T21 -> 42.4 | N21: 426-00 | O21: COMP,RETAINER | P21: 53 | R21: =+N21 -> 426-00 | S21: =VLOOKUP(R21,'정형공정 적용리스트'!$A:$D,3,FALSE) -> 53 | T21: =IF(S21>0,S21*0.8,"O") -> 42.4
B22: =+N22 -> 204-00 | C22: =+O22 -> BODY | D22: =+IF(L22=$V$1,P22*0.6,P22*0.5) -> 27.5 | F22: =+N22 -> 204-00 | G22: =+O22 -> BODY | H22: =IF(T22=$V$1,P22*0.8,P22*0.6) -> 33 | J22: =+R22 -> 204-00 | K22: =+O22 -> BODY | L22: =T22 -> 44 | N22: 204-00 | O22: BODY | P22: 55 | R22: =+N22 -> 204-00 | S22: =VLOOKUP(R22,'정형공정 적용리스트'!$A:$D,3,FALSE) -> 55 | T22: =IF(S22>0,S22*0.8,"O") -> 44
B23: =+N23 -> 428-01 | C23: =+O23 -> COMP,RETAINER | D23: =+IF(L23=$V$1,P23*0.6,P23*0.5) -> 26.5 | F23: =+N23 -> 428-01 | G23: =+O23 -> COMP,RETAINER | H23: =IF(T23=$V$1,P23*0.8,P23*0.6) -> 31.8 | J23: =+R23 -> 428-01 | K23: =+O23 -> COMP,RETAINER | L23: =T23 -> 42.4 | N23: 428-01 | O23: COMP,RETAINER | P23: 53 | R23: =+N23 -> 428-01 | S23: =VLOOKUP(R23,'정형공정 적용리스트'!$A:$D,3,FALSE) -> 53 | T23: =IF(S23>0,S23*0.8,"O") -> 42.4
B24: =+N24 -> 409-00 | C24: =+O24 -> REB,RETAINER | D24: =+IF(L24=$V$1,P24*0.6,P24*0.5) -> 28 | F24: =+N24 -> 409-00 | G24: =+O24 -> REB,RETAINER | H24: =IF(T24=$V$1,P24*0.8,P24*0.6) -> 33.6 | J24: =+R24 -> 409-00 | K24: =+O24 -> REB,RETAINER | L24: =T24 -> 44.8 | N24: 409-00 | O24: REB,RETAINER | P24: 56 | R24: =+N24 -> 409-00 | S24: =VLOOKUP(R24,'정형공정 적용리스트'!$A:$D,3,FALSE) -> 56 | T24: =IF(S24>0,S24*0.8,"O") -> 44.8
B25: =+N25 -> 404-00 | C25: =+O25 -> COMP,RETAINER | D25: =+IF(L25=$V$1,P25*0.6,P25*0.5) -> 28.5 | F25: =+N25 -> 404-00 | G25: =+O25 -> COMP,RETAINER | H25: =IF(T25=$V$1,P25*0.8,P25*0.6) -> 34.2 | J25: =+R25 -> 404-00 | K25: =+O25 -> COMP,RETAINER | L25: =T25 -> 45.6 | N25: 404-00 | O25: COMP,RETAINER | P25: 57 | R25: =+N25 -> 404-00 | S25: =VLOOKUP(R25,'정형공정 적용리스트'!$A:$D,3,FALSE) -> 57 | T25: =IF(S25>0,S25*0.8,"O") -> 45.6
B26: =+N26 -> 415-00 | C26: =+O26 -> COMP,RETAINER | D26: =+IF(L26=$V$1,P26*0.6,P26*0.5) -> 28.5 | F26: =+N26 -> 415-00 | G26: =+O26 -> COMP,RETAINER | H26: =IF(T26=$V$1,P26*0.8,P26*0.6) -> 34.2 | J26: =+R26 -> 415-00 | K26: =+O26 -> COMP,RETAINER | L26: =T26 -> 45.6 | N26: 415-00 | O26: COMP,RETAINER | P26: 57 | R26: =+N26 -> 415-00 | S26: =VLOOKUP(R26,'정형공정 적용리스트'!$A:$D,3,FALSE) -> 57 | T26: =IF(S26>0,S26*0.8,"O") -> 45.6
B27: =+N27 -> 415-00 | C27: =+O27 -> COMP,RETAINER | D27: =+IF(L27=$V$1,P27*0.6,P27*0.5) -> 28.5 | F27: =+N27 -> 415-00 | G27: =+O27 -> COMP,RETAINER | H27: =IF(T27=$V$1,P27*0.8,P27*0.6) -> 34.2 | J27: =+R27 -> 415-00 | K27: =+O27 -> COMP,RETAINER | L27: =T27 -> 45.6 | N27: 415-00 | O27: COMP,RETAINER | P27: 57 | R27: =+N27 -> 415-00 | S27: =VLOOKUP(R27,'정형공정 적용리스트'!$A:$D,3,FALSE) -> 57 | T27: =IF(S27>0,S27*0.8,"O") -> 45.6
B28: =+N28 -> 427-00 | C28: =+O28 -> REB,RETAINER | D28: =+IF(L28=$V$1,P28*0.6,P28*0.5) -> 28.5 | F28: =+N28 -> 427-00 | G28: =+O28 -> REB,RETAINER | H28: =IF(T28=$V$1,P28*0.8,P28*0.6) -> 34.2 | J28: =+R28 -> 427-00 | K28: =+O28 -> REB,RETAINER | L28: =T28 -> 45.6 | N28: 427-00 | O28: REB,RETAINER | P28: 57 | R28: =+N28 -> 427-00 | S28: =VLOOKUP(R28,'정형공정 적용리스트'!$A:$D,3,FALSE) -> 57 | T28: =IF(S28>0,S28*0.8,"O") -> 45.6
B29: =+N29 -> 458-00 | C29: =+O29 -> REB,RETAINER | D29: =+IF(L29=$V$1,P29*0.6,P29*0.5) -> 28.5 | F29: =+N29 -> 458-00 | G29: =+O29 -> REB,RETAINER | H29: =IF(T29=$V$1,P29*0.8,P29*0.6) -> 34.2 | J29: =+R29 -> 458-00 | K29: =+O29 -> REB,RETAINER | L29: =T29 -> 45.6 | N29: 458-00 | O29: REB,RETAINER | P29: 57 | R29: =+N29 -> 458-00 | S29: =VLOOKUP(R29,'정형공정 적용리스트'!$A:$D,3,FALSE) -> 57 | T29: =IF(S29>0,S29*0.8,"O") -> 45.6
B30: =+N30 -> 458-00 | C30: =+O30 -> REB,RETAINER | D30: =+IF(L30=$V$1,P30*0.6,P30*0.5) -> 28.5 | F30: =+N30 -> 458-00 | G30: =+O30 -> REB,RETAINER | H30: =IF(T30=$V$1,P30*0.8,P30*0.6) -> 34.2 | J30: =+R30 -> 458-00 | K30: =+O30 -> REB,RETAINER | L30: =T30 -> 45.6 | N30: 458-00 | O30: REB,RETAINER | P30: 57 | R30: =+N30 -> 458-00 | S30: =VLOOKUP(R30,'정형공정 적용리스트'!$A:$D,3,FALSE) -> 57 | T30: =IF(S30>0,S30*0.8,"O") -> 45.6
... B49: =+N49 -> 403-00 | C49: =+O49 -> COMP,RETAINER | D49: =+IF(L49=$V$1,P49*0.6,P49*0.5) -> 34 | F49: =+N49 -> 403-00 | G49: =+O49 -> COMP,RETAINER | H49: =IF(T49=$V$1,P49*0.8,P49*0.6) -> 40.8 | J49: =+R49 -> 403-00 | K49: =+O49 -> COMP,RETAINER | L49: =T49 -> 54.4 | N49: 403-00 | O49: COMP,RETAINER | P49: 68 | R49: =+N49 -> 403-00 | S49: =VLOOKUP(R49,'정형공정 적용리스트'!$A:$D,3,FALSE) -> 68 | T49: =IF(S49>0,S49*0.8,"O") -> 54.4
B50: =+N50 -> 843-00 | C50: =+O50 -> NUT ADJUSTER(LH) | D50: =+IF(L50=$V$1,P50*0.6,P50*0.5) -> 40.8 | F50: =+N50 -> 843-00 | G50: =+O50 -> NUT ADJUSTER(LH) | H50: =IF(T50=$V$1,P50*0.8,P50*0.6) -> 54.4 | J50: =+R50 -> 843-00 | K50: =+O50 -> NUT ADJUSTER(LH) | L50: =T50 -> O | N50: 843-00 | O50: NUT ADJUSTER(LH) | P50: 68 | R50: =+N50 -> 843-00 | S50: =VLOOKUP(R50,'정형공정 적용리스트'!$A:$D,3,FALSE) -> #N/A | T50: O
B51: =+N51 -> 843-00 | C51: =+O51 -> NUT ADJUSTER(LH) | D51: =+IF(L51=$V$1,P51*0.6,P51*0.5) -> 40.8 | F51: =+N51 -> 843-00 | G51: =+O51 -> NUT ADJUSTER(LH) | H51: =IF(T51=$V$1,P51*0.8,P51*0.6) -> 54.4 | J51: =+R51 -> 843-00 | K51: =+O51 -> NUT ADJUSTER(LH) | L51: =T51 -> O | N51: 843-00 | O51: NUT ADJUSTER(LH) | P51: 68 | R51: =+N51 -> 843-00 | S51: =VLOOKUP(R51,'정형공정 적용리스트'!$A:$D,3,FALSE) -> #N/A | T51: O
B52: =+N52 -> 844-00 | C52: =+O52 -> NUT ADJUSTER(RH) | D52: =+IF(L52=$V$1,P52*0.6,P52*0.5) -> 40.8 | F52: =+N52 -> 844-00 | G52: =+O52 -> NUT ADJUSTER(RH) | H52: =IF(T52=$V$1,P52*0.8,P52*0.6) -> 54.4 | J52: =+R52 -> 844-00 | K52: =+O52 -> NUT ADJUSTER(RH) | L52: =T52 -> O | N52: 844-00 | O52: NUT ADJUSTER(RH) | P52: 68 | R52: =+N52 -> 844-00 | S52: =VLOOKUP(R52,'정형공정 적용리스트'!$A:$D,3,FALSE) -> #N/A | T52: O
B53: =+N53 -> 844-00 | C53: =+O53 -> NUT ADJUSTER(RH) | D53: =+IF(L53=$V$1,P53*0.6,P53*0.5) -> 40.8 | F53: =+N53 -> 844-00 | G53: =+O53 -> NUT ADJUSTER(RH) | H53: =IF(T53=$V$1,P53*0.8,P53*0.6) -> 54.4 | J53: =+R53 -> 844-00 | K53: =+O53 -> NUT ADJUSTER(RH) | L53: =T53 -> O | N53: 844-00 | O53: NUT ADJUSTER(RH) | P53: 68 | R53: =+N53 -> 844-00 | S53: =VLOOKUP(R53,'정형공정 적용리스트'!$A:$D,3,FALSE) -> #N/A | T53: O
B54: =+N54 -> 494-01 | C54: =+O54 -> REB,RETAINER | D54: =+IF(L54=$V$1,P54*0.6,P54*0.5) -> 33 | F54: =+N54 -> 494-01 | G54: =+O54 -> REB,RETAINER | H54: =IF(T54=$V$1,P54*0.8,P54*0.6) -> 39.6 | J54: =+R54 -> 494-01 | K54: =+O54 -> REB,RETAINER | L54: =T54 -> 52.8 | N54: 494-01 | O54: REB,RETAINER | P54: 66 | R54: =+N54 -> 494-01 | S54: =VLOOKUP(R54,'정형공정 적용리스트'!$A:$D,3,FALSE) -> 66 | T54: =IF(S54>0,S54*0.8,"O") -> 52.8
B55: =+N55 -> 575-00 | C55: =+O55 -> REB,RETAINER | D55: =+IF(L55=$V$1,P55*0.6,P55*0.5) -> 34.5 | F55: =+N55 -> 575-00 | G55: =+O55 -> REB,RETAINER | H55: =IF(T55=$V$1,P55*0.8,P55*0.6) -> 41.4 | J55: =+R55 -> 575-00 | K55: =+O55 -> REB,RETAINER | L55: =T55 -> 55.2 | N55: 575-00 | O55: REB,RETAINER | P55: 69 | R55: =+N55 -> 575-00 | S55: =VLOOKUP(R55,'정형공정 적용리스트'!$A:$D,3,FALSE) -> 69 | T55: =IF(S55>0,S55*0.8,"O") -> 55.2
B56: =+N56 -> 420-00 | C56: =+O56 -> COMP,RETAINER | D56: =+IF(L56=$V$1,P56*0.6,P56*0.5) -> 35 | F56: =+N56 -> 420-00 | G56: =+O56 -> COMP,RETAINER | H56: =IF(T56=$V$1,P56*0.8,P56*0.6) -> 42 | J56: =+R56 -> 420-00 | K56: =+O56 -> COMP,RETAINER | L56: =T56 -> 56 | N56: 420-00 | O56: COMP,RETAINER | P56: 70 | R56: =+N56 -> 420-00 | S56: =VLOOKUP(R56,'정형공정 적용리스트'!$A:$D,3,FALSE) -> 70 | T56: =IF(S56>0,S56*0.8,"O") -> 56
B57: =+N57 -> 511-00 | C57: =+O57 -> BACK UP WASHER | D57: =+IF(L57=$V$1,P57*0.6,P57*0.5) -> 42.6 | F57: =+N57 -> 511-00 | G57: =+O57 -> BACK UP WASHER | H57: =IF(T57=$V$1,P57*0.8,P57*0.6) -> 56.8 | J57: =+R57 -> 511-00 | K57: =+O57 -> BACK UP WASHER | L57: =T57 -> O | N57: 511-00 | O57: BACK UP WASHER | P57: 71 | R57: =+N57 -> 511-00 | S57: =VLOOKUP(R57,'정형공정 적용리스트'!$A:$D,3,FALSE) -> #N/A | T57: O
B58: =+N58 -> 203-01 | C58: =+O58 -> PISTON | D58: =+IF(L58=$V$1,P58*0.6,P58*0.5) -> 36 | F58: =+N58 -> 203-01 | G58: =+O58 -> PISTON | H58: =IF(T58=$V$1,P58*0.8,P58*0.6) -> 43.2 | J58: =+R58 -> 203-01 | K58: =+O58 -> PISTON | L58: =T58 -> 57.6 | N58: 203-01 | O58: PISTON | P58: 72 | R58: =+N58 -> 203-01 | S58: =VLOOKUP(R58,'정형공정 적용리스트'!$A:$D,3,FALSE) -> 72 | T58: =IF(S58>0,S58*0.8,"O") -> 57.6
...

Sheet 정형공정 적용리스트
A1: 정형 MASTER | C1: 완제품단가 | D1: 정형단가 | F1: 평균단가 | H1: 정형 | I1: =+AVERAGE(C2:C2061) -> #N/A
A2: 009-03 | C2: 162 | D2: =+C2*0.8 -> 129.6
A3: 009-04 | C3: 118 | D3: =+C3*0.8 -> 94.4
A4: 017-01 | C4: 242 | D4: =+C4*0.8 -> 193.6
A5: 017-02 | C5: 380 | D5: =+C5*0.8 -> 304
A6: 051-02 | C6: 494 | D6: =+C6*0.8 -> 395.2
A7: 051-03 | C7: 619 | D7: =+C7*0.8 -> 495.2
A8: 090-02 | C8: 647 | D8: =+C8*0.8 -> 517.6
A9: 090-03 | C9: 829 | D9: =+C9*0.8 -> 663.2
A10: 1001-00 | C10: 237 | D10: =+C10*0.8 -> 189.6
A11: 1005-00 | C11: 318 | D11: =+C11*0.8 -> 254.4
A12: 1006-00 | C12: 582 | D12: =+C12*0.8 -> 465.6
A13: 1010-00 | C13: 412 | D13: =+C13*0.8 -> 329.6
... A72: 1183-01 | C72: 460 | D72: =+C72*0.8 -> 368
A73: 1184-00 | C73: =+VLOOKUP(A73,단가산출!$N:$P,3,FALSE) -> #N/A | D73: =+C73*0.8 -> #N/A
A74: 1185-00 | C74: 778 | D74: =+C74*0.8 -> 622.4
A75: 1191-02 | C75: 536 | D75: =+C75*0.8 -> 428.8
A76: 1191-03 | C76: 541 | D76: =+C76*0.8 -> 432.8
A77: 1209-01 | C77: 271 | D77: =+C77*0.8 -> 216.8
A78: 1213-00 | C78: 768 | D78: =+C78*0.8 -> 614.4
A79: 1213-02 | C79: 753 | D79: =+C79*0.8 -> 602.4
A80: 1213-03 | C80: 771 | D80: =+C80*0.8 -> 616.8
A81: 1218-02 | C81: 195 | D81: =+C81*0.8 -> 156
A82: 1218-04 | C82: 466 | D82: =+C82*0.8 -> 372.8
A83: 1218-06 | C83: 476 | D83: =+C83*0.8 -> 380.8
A84: 1218-07 | C84: 456 | D84: =+C84*0.8 -> 364.8
A85: 1218-08 | C85: 473 | D85: =+C85*0.8 -> 378.4
... A1576: 1042-02 | C1576: 769 | D1576: =+C1576*0.8 -> 615.2
A1577: 1043-00 | C1577: =+VLOOKUP(A1577,단가산출!$N:$P,3,FALSE) -> #N/A | D1577: =+C1577*0.8 -> #N/A
A1578: 1071-00 | C1578: 356 | D1578: =+C1578*0.8 -> 284.8
A1579: 1076-00 | C1579: 547 | D1579: =+C1579*0.8 -> 437.6
A1580: 1090-00 | C1580: 784 | D1580: =+C1580*0.8 -> 627.2
A1581: 1090-01 | C1581: 723 | D1581: =+C1581*0.8 -> 578.4
A1582: 1095-00 | C1582: 318 | D1582: =+C1582*0.8 -> 254.4
A1583: 1097-00 | C1583: 309 | D1583: =+C1583*0.8 -> 247.2
A1584: 1101-00 | C1584: 337 | D1584: =+C1584*0.8 -> 269.6
A1585: 1114-00 | C1585: 236 | D1585: =+C1585*0.8 -> 188.8
A1586: 1116-00 | C1586: 267 | D1586: =+C1586*0.8 -> 213.6
A1587: 1117-00 | C1587: 347 | D1587: =+C1587*0.8 -> 277.6
A1588: 1117-01 | C1588: 361 | D1588: =+C1588*0.8 -> 288.8
...

Sheet TEMP.
F4: 2파트 b/plate 평균단가 | H4: =+AVERAGE(H7:H14) -> 1974.875
F7: 5001-00 | G7: PLATE 1-2-3-4 CLU BKG | H7: 3587
F8: 5002-00 | G8: PLATE 4-5-6 CLU BKG | H8: 561
F9: 5003-01 | G9: PLATE 3-5-REV CLU BKG | H9: 1240
F10: 5004-00 | G10: PLATE LOW & REV CLU BKG | H10: 2748
F11: 5006-00 | G11: PLATE 1-2-3-4 CLU BKG | H11: 3511
F12: 5007-00 | G12: PLATE 4-5-6 CLU BKG | H12: 516
F13: 5008-00 | G13: PLATE 3-5-REV CLU BKG | H13: 1096
F14: 5009-00 | G14: PLATE LOW & REV CLU BKG | H14: 2540
